[2017-09-29 15:28:33 +0000] [18178] [DEBUG] Current configuration:
  proxy_protocol: False
  worker_connections: 1000
  statsd_host: None
  max_requests_jitter: 0
  post_fork: <function post_fork at 0x26e2410>
  errorlog: -
  enable_stdio_inheritance: False
  worker_class: gevent
  ssl_version: 2
  suppress_ragged_eofs: True
  syslog: False
  syslog_facility: user
  when_ready: <function when_ready at 0x26e2140>
  pre_fork: <function pre_fork at 0x26e22a8>
  cert_reqs: 0
  preload_app: False
  keepalive: 2
  accesslog: None
  group: 0
  graceful_timeout: 30
  do_handshake_on_connect: False
  spew: False
  workers: 2
  proc_name: gunicorn.pid
  sendfile: None
  pidfile: /var/log/gunicorn/debug.log
  umask: 0
  on_reload: <function on_reload at 0x26aff50>
  pre_exec: <function pre_exec at 0x26e29b0>
  worker_tmp_dir: None
  limit_request_fields: 100
  pythonpath: None
  on_exit: <function on_exit at 0x26e4230>
  config: /var/www/projects/myblog/deploy_config.py
  logconfig: None
  check_config: False
  statsd_prefix: 
  secure_scheme_headers: {'X-FORWARDED-PROTOCOL': 'ssl', 'X-FORWARDED-PROTO': 'https', 'X-FORWARDED-SSL': 'on'}
  reload_engine: auto
  proxy_allow_ips: ['127.0.0.1']
  pre_request: <function pre_request at 0x26e2b18>
  post_request: <function post_request at 0x26e2c08>
  forwarded_allow_ips: ['127.0.0.1']
  worker_int: <function worker_int at 0x26e26e0>
  raw_paste_global_conf: []
  threads: 1
  max_requests: 0
  chdir: /var/www/projects/myblog
  daemon: False
  user: 0
  limit_request_line: 4094
  access_log_format: %(h)s %(l)s %(u)s %(t)s "%(r)s" %(s)s %(b)s "%(f)s" "%(a)s"
  certfile: None
  on_starting: <function on_starting at 0x26afde8>
  post_worker_init: <function post_worker_init at 0x26e2578>
  child_exit: <function child_exit at 0x26e2d70>
  worker_exit: <function worker_exit at 0x26e2ed8>
  paste: None
  default_proc_name: manage:app
  syslog_addr: udp://localhost:514
  syslog_prefix: None
  ciphers: TLSv1
  worker_abort: <function worker_abort at 0x26e2848>
  loglevel: debug
  bind: ['127.0.0.1:8080']
  raw_env: []
  initgroups: False
  capture_output: False
  reload: False
  limit_request_field_size: 8190
  nworkers_changed: <function nworkers_changed at 0x26e40c8>
  timeout: 30
  keyfile: None
  ca_certs: None
  tmp_upload_dir: None
  backlog: 2048
  logger_class: gunicorn.glogging.Logger
[2017-09-29 15:28:33 +0000] [18178] [INFO] Starting gunicorn 19.7.1
[2017-09-29 15:28:33 +0000] [18178] [DEBUG] Arbiter booted
[2017-09-29 15:28:33 +0000] [18178] [INFO] Listening at: http://127.0.0.1:8080 (18178)
[2017-09-29 15:28:33 +0000] [18178] [INFO] Using worker: gevent
[2017-09-29 15:28:33 +0000] [18183] [INFO] Booting worker with pid: 18183
[2017-09-29 15:28:33 +0000] [18184] [INFO] Booting worker with pid: 18184
[2017-09-29 15:28:33 +0000] [18178] [DEBUG] 2 workers
[2017-09-29 15:28:39 +0000] [18183] [ERROR] Exception in worker process
Traceback (most recent call last):
  File "/var/www/projects/myblog/venv/lib/python2.7/site-packages/gunicorn/arbiter.py", line 578, in spawn_worker
    worker.init_process()
  File "/var/www/projects/myblog/venv/lib/python2.7/site-packages/gunicorn/workers/ggevent.py", line 190, in init_process
    super(GeventWorker, self).init_process()
  File "/var/www/projects/myblog/venv/lib/python2.7/site-packages/gunicorn/workers/base.py", line 126, in init_process
    self.load_wsgi()
  File "/var/www/projects/myblog/venv/lib/python2.7/site-packages/gunicorn/workers/base.py", line 135, in load_wsgi
    self.wsgi = self.app.wsgi()
  File "/var/www/projects/myblog/venv/lib/python2.7/site-packages/gunicorn/app/base.py", line 67, in wsgi
    self.callable = self.load()
  File "/var/www/projects/myblog/venv/lib/python2.7/site-packages/gunicorn/app/wsgiapp.py", line 65, in load
    return self.load_wsgiapp()
  File "/var/www/projects/myblog/venv/lib/python2.7/site-packages/gunicorn/app/wsgiapp.py", line 52, in load_wsgiapp
    return util.import_app(self.app_uri)
  File "/var/www/projects/myblog/venv/lib/python2.7/site-packages/gunicorn/util.py", line 352, in import_app
    __import__(module)
  File "/var/www/projects/myblog/venv/lib/python2.7/site-packages/gevent/builtins.py", line 93, in __import__
    result = _import(*args, **kwargs)
  File "/var/www/projects/myblog/manage.py", line 15, in <module>
    app = create_app(os.getenv('BLOG_CONFIG') or 'default')
  File "/var/www/projects/myblog/app/__init__.py", line 26, in create_app
    config[config_name].init_app(app)
  File "/var/www/projects/myblog/config.py", line 60, in init_app
    if gettattr(cls, 'MAIL_USE_TLS', None):
NameError: global name 'gettattr' is not defined
[2017-09-29 15:28:39 +0000] [18183] [INFO] Worker exiting (pid: 18183)
[2017-09-29 15:28:39 +0000] [18184] [ERROR] Exception in worker process
Traceback (most recent call last):
  File "/var/www/projects/myblog/venv/lib/python2.7/site-packages/gunicorn/arbiter.py", line 578, in spawn_worker
    worker.init_process()
  File "/var/www/projects/myblog/venv/lib/python2.7/site-packages/gunicorn/workers/ggevent.py", line 190, in init_process
    super(GeventWorker, self).init_process()
  File "/var/www/projects/myblog/venv/lib/python2.7/site-packages/gunicorn/workers/base.py", line 126, in init_process
    self.load_wsgi()
  File "/var/www/projects/myblog/venv/lib/python2.7/site-packages/gunicorn/workers/base.py", line 135, in load_wsgi
    self.wsgi = self.app.wsgi()
  File "/var/www/projects/myblog/venv/lib/python2.7/site-packages/gunicorn/app/base.py", line 67, in wsgi
    self.callable = self.load()
  File "/var/www/projects/myblog/venv/lib/python2.7/site-packages/gunicorn/app/wsgiapp.py", line 65, in load
    return self.load_wsgiapp()
  File "/var/www/projects/myblog/venv/lib/python2.7/site-packages/gunicorn/app/wsgiapp.py", line 52, in load_wsgiapp
    return util.import_app(self.app_uri)
  File "/var/www/projects/myblog/venv/lib/python2.7/site-packages/gunicorn/util.py", line 352, in import_app
    __import__(module)
  File "/var/www/projects/myblog/venv/lib/python2.7/site-packages/gevent/builtins.py", line 93, in __import__
    result = _import(*args, **kwargs)
  File "/var/www/projects/myblog/manage.py", line 15, in <module>
    app = create_app(os.getenv('BLOG_CONFIG') or 'default')
  File "/var/www/projects/myblog/app/__init__.py", line 26, in create_app
    config[config_name].init_app(app)
  File "/var/www/projects/myblog/config.py", line 60, in init_app
    if gettattr(cls, 'MAIL_USE_TLS', None):
NameError: global name 'gettattr' is not defined
[2017-09-29 15:28:39 +0000] [18184] [INFO] Worker exiting (pid: 18184)
Traceback (most recent call last):
  File "/var/www/projects/myblog/venv/bin/gunicorn", line 11, in <module>
    sys.exit(run())
  File "/var/www/projects/myblog/venv/lib/python2.7/site-packages/gunicorn/app/wsgiapp.py", line 74, in run
    WSGIApplication("%(prog)s [OPTIONS] [APP_MODULE]").run()
  File "/var/www/projects/myblog/venv/lib/python2.7/site-packages/gunicorn/app/base.py", line 203, in run
    super(Application, self).run()
  File "/var/www/projects/myblog/venv/lib/python2.7/site-packages/gunicorn/app/base.py", line 72, in run
    Arbiter(self).run()
  File "/var/www/projects/myblog/venv/lib/python2.7/site-packages/gunicorn/arbiter.py", line 231, in run
    self.halt(reason=inst.reason, exit_status=inst.exit_status)
  File "/var/www/projects/myblog/venv/lib/python2.7/site-packages/gunicorn/arbiter.py", line 344, in halt
    self.stop()
  File "/var/www/projects/myblog/venv/lib/python2.7/site-packages/gunicorn/arbiter.py", line 393, in stop
    time.sleep(0.1)
  File "/var/www/projects/myblog/venv/lib/python2.7/site-packages/gunicorn/arbiter.py", line 244, in handle_chld
    self.reap_workers()
  File "/var/www/projects/myblog/venv/lib/python2.7/site-packages/gunicorn/arbiter.py", line 524, in reap_workers
    raise HaltServer(reason, self.WORKER_BOOT_ERROR)
gunicorn.errors.HaltServer: <HaltServer 'Worker failed to boot.' 3>
[2017-09-29 15:28:41 +0000] [18193] [DEBUG] Current configuration:
  proxy_protocol: False
  worker_connections: 1000
  statsd_host: None
  max_requests_jitter: 0
  post_fork: <function post_fork at 0x2211410>
  errorlog: -
  enable_stdio_inheritance: False
  worker_class: gevent
  ssl_version: 2
  suppress_ragged_eofs: True
  syslog: False
  syslog_facility: user
  when_ready: <function when_ready at 0x2211140>
  pre_fork: <function pre_fork at 0x22112a8>
  cert_reqs: 0
  preload_app: False
  keepalive: 2
  accesslog: None
  group: 0
  graceful_timeout: 30
  do_handshake_on_connect: False
  spew: False
  workers: 2
  proc_name: gunicorn.pid
  sendfile: None
  pidfile: /var/log/gunicorn/debug.log
  umask: 0
  on_reload: <function on_reload at 0x21def50>
  pre_exec: <function pre_exec at 0x22119b0>
  worker_tmp_dir: None
  limit_request_fields: 100
  pythonpath: None
  on_exit: <function on_exit at 0x2213230>
  config: /var/www/projects/myblog/deploy_config.py
  logconfig: None
  check_config: False
  statsd_prefix: 
  secure_scheme_headers: {'X-FORWARDED-PROTOCOL': 'ssl', 'X-FORWARDED-PROTO': 'https', 'X-FORWARDED-SSL': 'on'}
  reload_engine: auto
  proxy_allow_ips: ['127.0.0.1']
  pre_request: <function pre_request at 0x2211b18>
  post_request: <function post_request at 0x2211c08>
  forwarded_allow_ips: ['127.0.0.1']
  worker_int: <function worker_int at 0x22116e0>
  raw_paste_global_conf: []
  threads: 1
  max_requests: 0
  chdir: /var/www/projects/myblog
  daemon: False
  user: 0
  limit_request_line: 4094
  access_log_format: %(h)s %(l)s %(u)s %(t)s "%(r)s" %(s)s %(b)s "%(f)s" "%(a)s"
  certfile: None
  on_starting: <function on_starting at 0x21dede8>
  post_worker_init: <function post_worker_init at 0x2211578>
  child_exit: <function child_exit at 0x2211d70>
  worker_exit: <function worker_exit at 0x2211ed8>
  paste: None
  default_proc_name: manage:app
  syslog_addr: udp://localhost:514
  syslog_prefix: None
  ciphers: TLSv1
  worker_abort: <function worker_abort at 0x2211848>
  loglevel: debug
  bind: ['127.0.0.1:8080']
  raw_env: []
  initgroups: False
  capture_output: False
  reload: False
  limit_request_field_size: 8190
  nworkers_changed: <function nworkers_changed at 0x22130c8>
  timeout: 30
  keyfile: None
  ca_certs: None
  tmp_upload_dir: None
  backlog: 2048
  logger_class: gunicorn.glogging.Logger
[2017-09-29 15:28:41 +0000] [18193] [INFO] Starting gunicorn 19.7.1
[2017-09-29 15:28:41 +0000] [18193] [DEBUG] Arbiter booted
[2017-09-29 15:28:41 +0000] [18193] [INFO] Listening at: http://127.0.0.1:8080 (18193)
[2017-09-29 15:28:41 +0000] [18193] [INFO] Using worker: gevent
[2017-09-29 15:28:41 +0000] [18198] [INFO] Booting worker with pid: 18198
[2017-09-29 15:28:41 +0000] [18199] [INFO] Booting worker with pid: 18199
[2017-09-29 15:28:41 +0000] [18193] [DEBUG] 2 workers
[2017-09-29 15:28:45 +0000] [18198] [ERROR] Exception in worker process
Traceback (most recent call last):
  File "/var/www/projects/myblog/venv/lib/python2.7/site-packages/gunicorn/arbiter.py", line 578, in spawn_worker
    worker.init_process()
  File "/var/www/projects/myblog/venv/lib/python2.7/site-packages/gunicorn/workers/ggevent.py", line 190, in init_process
    super(GeventWorker, self).init_process()
  File "/var/www/projects/myblog/venv/lib/python2.7/site-packages/gunicorn/workers/base.py", line 126, in init_process
    self.load_wsgi()
  File "/var/www/projects/myblog/venv/lib/python2.7/site-packages/gunicorn/workers/base.py", line 135, in load_wsgi
    self.wsgi = self.app.wsgi()
  File "/var/www/projects/myblog/venv/lib/python2.7/site-packages/gunicorn/app/base.py", line 67, in wsgi
    self.callable = self.load()
  File "/var/www/projects/myblog/venv/lib/python2.7/site-packages/gunicorn/app/wsgiapp.py", line 65, in load
    return self.load_wsgiapp()
  File "/var/www/projects/myblog/venv/lib/python2.7/site-packages/gunicorn/app/wsgiapp.py", line 52, in load_wsgiapp
    return util.import_app(self.app_uri)
  File "/var/www/projects/myblog/venv/lib/python2.7/site-packages/gunicorn/util.py", line 352, in import_app
    __import__(module)
  File "/var/www/projects/myblog/venv/lib/python2.7/site-packages/gevent/builtins.py", line 93, in __import__
    result = _import(*args, **kwargs)
  File "/var/www/projects/myblog/manage.py", line 15, in <module>
    app = create_app(os.getenv('BLOG_CONFIG') or 'default')
  File "/var/www/projects/myblog/app/__init__.py", line 26, in create_app
    config[config_name].init_app(app)
  File "/var/www/projects/myblog/config.py", line 60, in init_app
    if gettattr(cls, 'MAIL_USE_TLS', None):
NameError: global name 'gettattr' is not defined
[2017-09-29 15:28:45 +0000] [18198] [INFO] Worker exiting (pid: 18198)
[2017-09-29 15:28:45 +0000] [18199] [ERROR] Exception in worker process
Traceback (most recent call last):
  File "/var/www/projects/myblog/venv/lib/python2.7/site-packages/gunicorn/arbiter.py", line 578, in spawn_worker
    worker.init_process()
  File "/var/www/projects/myblog/venv/lib/python2.7/site-packages/gunicorn/workers/ggevent.py", line 190, in init_process
    super(GeventWorker, self).init_process()
  File "/var/www/projects/myblog/venv/lib/python2.7/site-packages/gunicorn/workers/base.py", line 126, in init_process
    self.load_wsgi()
  File "/var/www/projects/myblog/venv/lib/python2.7/site-packages/gunicorn/workers/base.py", line 135, in load_wsgi
    self.wsgi = self.app.wsgi()
  File "/var/www/projects/myblog/venv/lib/python2.7/site-packages/gunicorn/app/base.py", line 67, in wsgi
    self.callable = self.load()
  File "/var/www/projects/myblog/venv/lib/python2.7/site-packages/gunicorn/app/wsgiapp.py", line 65, in load
    return self.load_wsgiapp()
  File "/var/www/projects/myblog/venv/lib/python2.7/site-packages/gunicorn/app/wsgiapp.py", line 52, in load_wsgiapp
    return util.import_app(self.app_uri)
  File "/var/www/projects/myblog/venv/lib/python2.7/site-packages/gunicorn/util.py", line 352, in import_app
    __import__(module)
  File "/var/www/projects/myblog/venv/lib/python2.7/site-packages/gevent/builtins.py", line 93, in __import__
    result = _import(*args, **kwargs)
  File "/var/www/projects/myblog/manage.py", line 15, in <module>
    app = create_app(os.getenv('BLOG_CONFIG') or 'default')
  File "/var/www/projects/myblog/app/__init__.py", line 26, in create_app
    config[config_name].init_app(app)
  File "/var/www/projects/myblog/config.py", line 60, in init_app
    if gettattr(cls, 'MAIL_USE_TLS', None):
NameError: global name 'gettattr' is not defined
[2017-09-29 15:28:45 +0000] [18199] [INFO] Worker exiting (pid: 18199)
[2017-09-29 15:28:46 +0000] [18193] [INFO] Shutting down: Master
[2017-09-29 15:28:46 +0000] [18193] [INFO] Reason: Worker failed to boot.
[2017-09-29 15:28:47 +0000] [18208] [DEBUG] Current configuration:
  proxy_protocol: False
  worker_connections: 1000
  statsd_host: None
  max_requests_jitter: 0
  post_fork: <function post_fork at 0x1ff6410>
  errorlog: -
  enable_stdio_inheritance: False
  worker_class: gevent
  ssl_version: 2
  suppress_ragged_eofs: True
  syslog: False
  syslog_facility: user
  when_ready: <function when_ready at 0x1ff6140>
  pre_fork: <function pre_fork at 0x1ff62a8>
  cert_reqs: 0
  preload_app: False
  keepalive: 2
  accesslog: None
  group: 0
  graceful_timeout: 30
  do_handshake_on_connect: False
  spew: False
  workers: 2
  proc_name: gunicorn.pid
  sendfile: None
  pidfile: /var/log/gunicorn/debug.log
  umask: 0
  on_reload: <function on_reload at 0x1fc2f50>
  pre_exec: <function pre_exec at 0x1ff69b0>
  worker_tmp_dir: None
  limit_request_fields: 100
  pythonpath: None
  on_exit: <function on_exit at 0x1ff8230>
  config: /var/www/projects/myblog/deploy_config.py
  logconfig: None
  check_config: False
  statsd_prefix: 
  secure_scheme_headers: {'X-FORWARDED-PROTOCOL': 'ssl', 'X-FORWARDED-PROTO': 'https', 'X-FORWARDED-SSL': 'on'}
  reload_engine: auto
  proxy_allow_ips: ['127.0.0.1']
  pre_request: <function pre_request at 0x1ff6b18>
  post_request: <function post_request at 0x1ff6c08>
  forwarded_allow_ips: ['127.0.0.1']
  worker_int: <function worker_int at 0x1ff66e0>
  raw_paste_global_conf: []
  threads: 1
  max_requests: 0
  chdir: /var/www/projects/myblog
  daemon: False
  user: 0
  limit_request_line: 4094
  access_log_format: %(h)s %(l)s %(u)s %(t)s "%(r)s" %(s)s %(b)s "%(f)s" "%(a)s"
  certfile: None
  on_starting: <function on_starting at 0x1fc2de8>
  post_worker_init: <function post_worker_init at 0x1ff6578>
  child_exit: <function child_exit at 0x1ff6d70>
  worker_exit: <function worker_exit at 0x1ff6ed8>
  paste: None
  default_proc_name: manage:app
  syslog_addr: udp://localhost:514
  syslog_prefix: None
  ciphers: TLSv1
  worker_abort: <function worker_abort at 0x1ff6848>
  loglevel: debug
  bind: ['127.0.0.1:8080']
  raw_env: []
  initgroups: False
  capture_output: False
  reload: False
  limit_request_field_size: 8190
  nworkers_changed: <function nworkers_changed at 0x1ff80c8>
  timeout: 30
  keyfile: None
  ca_certs: None
  tmp_upload_dir: None
  backlog: 2048
  logger_class: gunicorn.glogging.Logger
[2017-09-29 15:28:47 +0000] [18208] [INFO] Starting gunicorn 19.7.1
[2017-09-29 15:28:47 +0000] [18208] [DEBUG] Arbiter booted
[2017-09-29 15:28:47 +0000] [18208] [INFO] Listening at: http://127.0.0.1:8080 (18208)
[2017-09-29 15:28:47 +0000] [18208] [INFO] Using worker: gevent
[2017-09-29 15:28:47 +0000] [18213] [INFO] Booting worker with pid: 18213
[2017-09-29 15:28:47 +0000] [18208] [DEBUG] 2 workers
[2017-09-29 15:28:47 +0000] [18214] [INFO] Booting worker with pid: 18214
[2017-09-29 15:28:52 +0000] [18213] [ERROR] Exception in worker process
Traceback (most recent call last):
  File "/var/www/projects/myblog/venv/lib/python2.7/site-packages/gunicorn/arbiter.py", line 578, in spawn_worker
    worker.init_process()
  File "/var/www/projects/myblog/venv/lib/python2.7/site-packages/gunicorn/workers/ggevent.py", line 190, in init_process
    super(GeventWorker, self).init_process()
  File "/var/www/projects/myblog/venv/lib/python2.7/site-packages/gunicorn/workers/base.py", line 126, in init_process
    self.load_wsgi()
  File "/var/www/projects/myblog/venv/lib/python2.7/site-packages/gunicorn/workers/base.py", line 135, in load_wsgi
    self.wsgi = self.app.wsgi()
  File "/var/www/projects/myblog/venv/lib/python2.7/site-packages/gunicorn/app/base.py", line 67, in wsgi
    self.callable = self.load()
  File "/var/www/projects/myblog/venv/lib/python2.7/site-packages/gunicorn/app/wsgiapp.py", line 65, in load
    return self.load_wsgiapp()
  File "/var/www/projects/myblog/venv/lib/python2.7/site-packages/gunicorn/app/wsgiapp.py", line 52, in load_wsgiapp
    return util.import_app(self.app_uri)
  File "/var/www/projects/myblog/venv/lib/python2.7/site-packages/gunicorn/util.py", line 352, in import_app
    __import__(module)
  File "/var/www/projects/myblog/venv/lib/python2.7/site-packages/gevent/builtins.py", line 93, in __import__
    result = _import(*args, **kwargs)
  File "/var/www/projects/myblog/manage.py", line 15, in <module>
    app = create_app(os.getenv('BLOG_CONFIG') or 'default')
  File "/var/www/projects/myblog/app/__init__.py", line 26, in create_app
    config[config_name].init_app(app)
  File "/var/www/projects/myblog/config.py", line 60, in init_app
    if gettattr(cls, 'MAIL_USE_TLS', None):
NameError: global name 'gettattr' is not defined
[2017-09-29 15:28:52 +0000] [18213] [INFO] Worker exiting (pid: 18213)
[2017-09-29 15:28:52 +0000] [18214] [ERROR] Exception in worker process
Traceback (most recent call last):
  File "/var/www/projects/myblog/venv/lib/python2.7/site-packages/gunicorn/arbiter.py", line 578, in spawn_worker
    worker.init_process()
  File "/var/www/projects/myblog/venv/lib/python2.7/site-packages/gunicorn/workers/ggevent.py", line 190, in init_process
    super(GeventWorker, self).init_process()
  File "/var/www/projects/myblog/venv/lib/python2.7/site-packages/gunicorn/workers/base.py", line 126, in init_process
    self.load_wsgi()
  File "/var/www/projects/myblog/venv/lib/python2.7/site-packages/gunicorn/workers/base.py", line 135, in load_wsgi
    self.wsgi = self.app.wsgi()
  File "/var/www/projects/myblog/venv/lib/python2.7/site-packages/gunicorn/app/base.py", line 67, in wsgi
    self.callable = self.load()
  File "/var/www/projects/myblog/venv/lib/python2.7/site-packages/gunicorn/app/wsgiapp.py", line 65, in load
    return self.load_wsgiapp()
  File "/var/www/projects/myblog/venv/lib/python2.7/site-packages/gunicorn/app/wsgiapp.py", line 52, in load_wsgiapp
    return util.import_app(self.app_uri)
  File "/var/www/projects/myblog/venv/lib/python2.7/site-packages/gunicorn/util.py", line 352, in import_app
    __import__(module)
  File "/var/www/projects/myblog/venv/lib/python2.7/site-packages/gevent/builtins.py", line 93, in __import__
    result = _import(*args, **kwargs)
  File "/var/www/projects/myblog/manage.py", line 15, in <module>
    app = create_app(os.getenv('BLOG_CONFIG') or 'default')
  File "/var/www/projects/myblog/app/__init__.py", line 26, in create_app
    config[config_name].init_app(app)
  File "/var/www/projects/myblog/config.py", line 60, in init_app
    if gettattr(cls, 'MAIL_USE_TLS', None):
NameError: global name 'gettattr' is not defined
[2017-09-29 15:28:52 +0000] [18214] [INFO] Worker exiting (pid: 18214)
[2017-09-29 15:28:52 +0000] [18208] [INFO] Shutting down: Master
[2017-09-29 15:28:52 +0000] [18208] [INFO] Reason: Worker failed to boot.
[2017-09-29 15:28:53 +0000] [18223] [DEBUG] Current configuration:
  proxy_protocol: False
  worker_connections: 1000
  statsd_host: None
  max_requests_jitter: 0
  post_fork: <function post_fork at 0x2416410>
  errorlog: -
  enable_stdio_inheritance: False
  worker_class: gevent
  ssl_version: 2
  suppress_ragged_eofs: True
  syslog: False
  syslog_facility: user
  when_ready: <function when_ready at 0x2416140>
  pre_fork: <function pre_fork at 0x24162a8>
  cert_reqs: 0
  preload_app: False
  keepalive: 2
  accesslog: None
  group: 0
  graceful_timeout: 30
  do_handshake_on_connect: False
  spew: False
  workers: 2
  proc_name: gunicorn.pid
  sendfile: None
  pidfile: /var/log/gunicorn/debug.log
  umask: 0
  on_reload: <function on_reload at 0x23e2f50>
  pre_exec: <function pre_exec at 0x24169b0>
  worker_tmp_dir: None
  limit_request_fields: 100
  pythonpath: None
  on_exit: <function on_exit at 0x2418230>
  config: /var/www/projects/myblog/deploy_config.py
  logconfig: None
  check_config: False
  statsd_prefix: 
  secure_scheme_headers: {'X-FORWARDED-PROTOCOL': 'ssl', 'X-FORWARDED-PROTO': 'https', 'X-FORWARDED-SSL': 'on'}
  reload_engine: auto
  proxy_allow_ips: ['127.0.0.1']
  pre_request: <function pre_request at 0x2416b18>
  post_request: <function post_request at 0x2416c08>
  forwarded_allow_ips: ['127.0.0.1']
  worker_int: <function worker_int at 0x24166e0>
  raw_paste_global_conf: []
  threads: 1
  max_requests: 0
  chdir: /var/www/projects/myblog
  daemon: False
  user: 0
  limit_request_line: 4094
  access_log_format: %(h)s %(l)s %(u)s %(t)s "%(r)s" %(s)s %(b)s "%(f)s" "%(a)s"
  certfile: None
  on_starting: <function on_starting at 0x23e2de8>
  post_worker_init: <function post_worker_init at 0x2416578>
  child_exit: <function child_exit at 0x2416d70>
  worker_exit: <function worker_exit at 0x2416ed8>
  paste: None
  default_proc_name: manage:app
  syslog_addr: udp://localhost:514
  syslog_prefix: None
  ciphers: TLSv1
  worker_abort: <function worker_abort at 0x2416848>
  loglevel: debug
  bind: ['127.0.0.1:8080']
  raw_env: []
  initgroups: False
  capture_output: False
  reload: False
  limit_request_field_size: 8190
  nworkers_changed: <function nworkers_changed at 0x24180c8>
  timeout: 30
  keyfile: None
  ca_certs: None
  tmp_upload_dir: None
  backlog: 2048
  logger_class: gunicorn.glogging.Logger
[2017-09-29 15:28:53 +0000] [18223] [INFO] Starting gunicorn 19.7.1
[2017-09-29 15:28:53 +0000] [18223] [DEBUG] Arbiter booted
[2017-09-29 15:28:53 +0000] [18223] [INFO] Listening at: http://127.0.0.1:8080 (18223)
[2017-09-29 15:28:53 +0000] [18223] [INFO] Using worker: gevent
[2017-09-29 15:28:53 +0000] [18228] [INFO] Booting worker with pid: 18228
[2017-09-29 15:28:53 +0000] [18229] [INFO] Booting worker with pid: 18229
[2017-09-29 15:28:54 +0000] [18223] [DEBUG] 2 workers
[2017-09-29 15:28:58 +0000] [18228] [ERROR] Exception in worker process
Traceback (most recent call last):
  File "/var/www/projects/myblog/venv/lib/python2.7/site-packages/gunicorn/arbiter.py", line 578, in spawn_worker
    worker.init_process()
  File "/var/www/projects/myblog/venv/lib/python2.7/site-packages/gunicorn/workers/ggevent.py", line 190, in init_process
    super(GeventWorker, self).init_process()
  File "/var/www/projects/myblog/venv/lib/python2.7/site-packages/gunicorn/workers/base.py", line 126, in init_process
    self.load_wsgi()
  File "/var/www/projects/myblog/venv/lib/python2.7/site-packages/gunicorn/workers/base.py", line 135, in load_wsgi
    self.wsgi = self.app.wsgi()
  File "/var/www/projects/myblog/venv/lib/python2.7/site-packages/gunicorn/app/base.py", line 67, in wsgi
    self.callable = self.load()
  File "/var/www/projects/myblog/venv/lib/python2.7/site-packages/gunicorn/app/wsgiapp.py", line 65, in load
    return self.load_wsgiapp()
  File "/var/www/projects/myblog/venv/lib/python2.7/site-packages/gunicorn/app/wsgiapp.py", line 52, in load_wsgiapp
    return util.import_app(self.app_uri)
  File "/var/www/projects/myblog/venv/lib/python2.7/site-packages/gunicorn/util.py", line 352, in import_app
    __import__(module)
  File "/var/www/projects/myblog/venv/lib/python2.7/site-packages/gevent/builtins.py", line 93, in __import__
    result = _import(*args, **kwargs)
  File "/var/www/projects/myblog/manage.py", line 15, in <module>
    app = create_app(os.getenv('BLOG_CONFIG') or 'default')
  File "/var/www/projects/myblog/app/__init__.py", line 26, in create_app
    config[config_name].init_app(app)
  File "/var/www/projects/myblog/config.py", line 60, in init_app
    if gettattr(cls, 'MAIL_USE_TLS', None):
NameError: global name 'gettattr' is not defined
[2017-09-29 15:28:58 +0000] [18228] [INFO] Worker exiting (pid: 18228)
[2017-09-29 15:28:58 +0000] [18229] [ERROR] Exception in worker process
Traceback (most recent call last):
  File "/var/www/projects/myblog/venv/lib/python2.7/site-packages/gunicorn/arbiter.py", line 578, in spawn_worker
    worker.init_process()
  File "/var/www/projects/myblog/venv/lib/python2.7/site-packages/gunicorn/workers/ggevent.py", line 190, in init_process
    super(GeventWorker, self).init_process()
  File "/var/www/projects/myblog/venv/lib/python2.7/site-packages/gunicorn/workers/base.py", line 126, in init_process
    self.load_wsgi()
  File "/var/www/projects/myblog/venv/lib/python2.7/site-packages/gunicorn/workers/base.py", line 135, in load_wsgi
    self.wsgi = self.app.wsgi()
  File "/var/www/projects/myblog/venv/lib/python2.7/site-packages/gunicorn/app/base.py", line 67, in wsgi
    self.callable = self.load()
  File "/var/www/projects/myblog/venv/lib/python2.7/site-packages/gunicorn/app/wsgiapp.py", line 65, in load
    return self.load_wsgiapp()
  File "/var/www/projects/myblog/venv/lib/python2.7/site-packages/gunicorn/app/wsgiapp.py", line 52, in load_wsgiapp
    return util.import_app(self.app_uri)
  File "/var/www/projects/myblog/venv/lib/python2.7/site-packages/gunicorn/util.py", line 352, in import_app
    __import__(module)
  File "/var/www/projects/myblog/venv/lib/python2.7/site-packages/gevent/builtins.py", line 93, in __import__
    result = _import(*args, **kwargs)
  File "/var/www/projects/myblog/manage.py", line 15, in <module>
    app = create_app(os.getenv('BLOG_CONFIG') or 'default')
  File "/var/www/projects/myblog/app/__init__.py", line 26, in create_app
    config[config_name].init_app(app)
  File "/var/www/projects/myblog/config.py", line 60, in init_app
    if gettattr(cls, 'MAIL_USE_TLS', None):
NameError: global name 'gettattr' is not defined
[2017-09-29 15:28:58 +0000] [18229] [INFO] Worker exiting (pid: 18229)
[2017-09-29 15:28:58 +0000] [18223] [INFO] Shutting down: Master
[2017-09-29 15:28:58 +0000] [18223] [INFO] Reason: Worker failed to boot.
[2017-09-29 15:29:00 +0000] [18238] [DEBUG] Current configuration:
  proxy_protocol: False
  worker_connections: 1000
  statsd_host: None
  max_requests_jitter: 0
  post_fork: <function post_fork at 0x1294410>
  errorlog: -
  enable_stdio_inheritance: False
  worker_class: gevent
  ssl_version: 2
  suppress_ragged_eofs: True
  syslog: False
  syslog_facility: user
  when_ready: <function when_ready at 0x1294140>
  pre_fork: <function pre_fork at 0x12942a8>
  cert_reqs: 0
  preload_app: False
  keepalive: 2
  accesslog: None
  group: 0
  graceful_timeout: 30
  do_handshake_on_connect: False
  spew: False
  workers: 2
  proc_name: gunicorn.pid
  sendfile: None
  pidfile: /var/log/gunicorn/debug.log
  umask: 0
  on_reload: <function on_reload at 0x1261f50>
  pre_exec: <function pre_exec at 0x12949b0>
  worker_tmp_dir: None
  limit_request_fields: 100
  pythonpath: None
  on_exit: <function on_exit at 0x1296230>
  config: /var/www/projects/myblog/deploy_config.py
  logconfig: None
  check_config: False
  statsd_prefix: 
  secure_scheme_headers: {'X-FORWARDED-PROTOCOL': 'ssl', 'X-FORWARDED-PROTO': 'https', 'X-FORWARDED-SSL': 'on'}
  reload_engine: auto
  proxy_allow_ips: ['127.0.0.1']
  pre_request: <function pre_request at 0x1294b18>
  post_request: <function post_request at 0x1294c08>
  forwarded_allow_ips: ['127.0.0.1']
  worker_int: <function worker_int at 0x12946e0>
  raw_paste_global_conf: []
  threads: 1
  max_requests: 0
  chdir: /var/www/projects/myblog
  daemon: False
  user: 0
  limit_request_line: 4094
  access_log_format: %(h)s %(l)s %(u)s %(t)s "%(r)s" %(s)s %(b)s "%(f)s" "%(a)s"
  certfile: None
  on_starting: <function on_starting at 0x1261de8>
  post_worker_init: <function post_worker_init at 0x1294578>
  child_exit: <function child_exit at 0x1294d70>
  worker_exit: <function worker_exit at 0x1294ed8>
  paste: None
  default_proc_name: manage:app
  syslog_addr: udp://localhost:514
  syslog_prefix: None
  ciphers: TLSv1
  worker_abort: <function worker_abort at 0x1294848>
  loglevel: debug
  bind: ['127.0.0.1:8080']
  raw_env: []
  initgroups: False
  capture_output: False
  reload: False
  limit_request_field_size: 8190
  nworkers_changed: <function nworkers_changed at 0x12960c8>
  timeout: 30
  keyfile: None
  ca_certs: None
  tmp_upload_dir: None
  backlog: 2048
  logger_class: gunicorn.glogging.Logger
[2017-09-29 15:29:00 +0000] [18238] [INFO] Starting gunicorn 19.7.1
[2017-09-29 15:29:00 +0000] [18238] [DEBUG] Arbiter booted
[2017-09-29 15:29:00 +0000] [18238] [INFO] Listening at: http://127.0.0.1:8080 (18238)
[2017-09-29 15:29:00 +0000] [18238] [INFO] Using worker: gevent
[2017-09-29 15:29:00 +0000] [18243] [INFO] Booting worker with pid: 18243
[2017-09-29 15:29:00 +0000] [18244] [INFO] Booting worker with pid: 18244
[2017-09-29 15:29:00 +0000] [18238] [DEBUG] 2 workers
[2017-09-29 15:29:04 +0000] [18243] [ERROR] Exception in worker process
Traceback (most recent call last):
  File "/var/www/projects/myblog/venv/lib/python2.7/site-packages/gunicorn/arbiter.py", line 578, in spawn_worker
    worker.init_process()
  File "/var/www/projects/myblog/venv/lib/python2.7/site-packages/gunicorn/workers/ggevent.py", line 190, in init_process
    super(GeventWorker, self).init_process()
  File "/var/www/projects/myblog/venv/lib/python2.7/site-packages/gunicorn/workers/base.py", line 126, in init_process
    self.load_wsgi()
  File "/var/www/projects/myblog/venv/lib/python2.7/site-packages/gunicorn/workers/base.py", line 135, in load_wsgi
    self.wsgi = self.app.wsgi()
  File "/var/www/projects/myblog/venv/lib/python2.7/site-packages/gunicorn/app/base.py", line 67, in wsgi
    self.callable = self.load()
  File "/var/www/projects/myblog/venv/lib/python2.7/site-packages/gunicorn/app/wsgiapp.py", line 65, in load
    return self.load_wsgiapp()
  File "/var/www/projects/myblog/venv/lib/python2.7/site-packages/gunicorn/app/wsgiapp.py", line 52, in load_wsgiapp
    return util.import_app(self.app_uri)
  File "/var/www/projects/myblog/venv/lib/python2.7/site-packages/gunicorn/util.py", line 352, in import_app
    __import__(module)
  File "/var/www/projects/myblog/venv/lib/python2.7/site-packages/gevent/builtins.py", line 93, in __import__
    result = _import(*args, **kwargs)
  File "/var/www/projects/myblog/manage.py", line 15, in <module>
    app = create_app(os.getenv('BLOG_CONFIG') or 'default')
  File "/var/www/projects/myblog/app/__init__.py", line 26, in create_app
    config[config_name].init_app(app)
  File "/var/www/projects/myblog/config.py", line 60, in init_app
    if gettattr(cls, 'MAIL_USE_TLS', None):
NameError: global name 'gettattr' is not defined
[2017-09-29 15:29:04 +0000] [18243] [INFO] Worker exiting (pid: 18243)
[2017-09-29 15:29:04 +0000] [18244] [ERROR] Exception in worker process
Traceback (most recent call last):
  File "/var/www/projects/myblog/venv/lib/python2.7/site-packages/gunicorn/arbiter.py", line 578, in spawn_worker
    worker.init_process()
  File "/var/www/projects/myblog/venv/lib/python2.7/site-packages/gunicorn/workers/ggevent.py", line 190, in init_process
    super(GeventWorker, self).init_process()
  File "/var/www/projects/myblog/venv/lib/python2.7/site-packages/gunicorn/workers/base.py", line 126, in init_process
    self.load_wsgi()
  File "/var/www/projects/myblog/venv/lib/python2.7/site-packages/gunicorn/workers/base.py", line 135, in load_wsgi
    self.wsgi = self.app.wsgi()
  File "/var/www/projects/myblog/venv/lib/python2.7/site-packages/gunicorn/app/base.py", line 67, in wsgi
    self.callable = self.load()
  File "/var/www/projects/myblog/venv/lib/python2.7/site-packages/gunicorn/app/wsgiapp.py", line 65, in load
    return self.load_wsgiapp()
  File "/var/www/projects/myblog/venv/lib/python2.7/site-packages/gunicorn/app/wsgiapp.py", line 52, in load_wsgiapp
    return util.import_app(self.app_uri)
  File "/var/www/projects/myblog/venv/lib/python2.7/site-packages/gunicorn/util.py", line 352, in import_app
    __import__(module)
  File "/var/www/projects/myblog/venv/lib/python2.7/site-packages/gevent/builtins.py", line 93, in __import__
    result = _import(*args, **kwargs)
  File "/var/www/projects/myblog/manage.py", line 15, in <module>
    app = create_app(os.getenv('BLOG_CONFIG') or 'default')
  File "/var/www/projects/myblog/app/__init__.py", line 26, in create_app
    config[config_name].init_app(app)
  File "/var/www/projects/myblog/config.py", line 60, in init_app
    if gettattr(cls, 'MAIL_USE_TLS', None):
NameError: global name 'gettattr' is not defined
[2017-09-29 15:29:04 +0000] [18244] [INFO] Worker exiting (pid: 18244)
Traceback (most recent call last):
  File "/var/www/projects/myblog/venv/bin/gunicorn", line 11, in <module>
    sys.exit(run())
  File "/var/www/projects/myblog/venv/lib/python2.7/site-packages/gunicorn/app/wsgiapp.py", line 74, in run
    WSGIApplication("%(prog)s [OPTIONS] [APP_MODULE]").run()
  File "/var/www/projects/myblog/venv/lib/python2.7/site-packages/gunicorn/app/base.py", line 203, in run
    super(Application, self).run()
  File "/var/www/projects/myblog/venv/lib/python2.7/site-packages/gunicorn/app/base.py", line 72, in run
    Arbiter(self).run()
  File "/var/www/projects/myblog/venv/lib/python2.7/site-packages/gunicorn/arbiter.py", line 231, in run
    self.halt(reason=inst.reason, exit_status=inst.exit_status)
  File "/var/www/projects/myblog/venv/lib/python2.7/site-packages/gunicorn/arbiter.py", line 344, in halt
    self.stop()
  File "/var/www/projects/myblog/venv/lib/python2.7/site-packages/gunicorn/arbiter.py", line 393, in stop
    time.sleep(0.1)
  File "/var/www/projects/myblog/venv/lib/python2.7/site-packages/gunicorn/arbiter.py", line 244, in handle_chld
    self.reap_workers()
  File "/var/www/projects/myblog/venv/lib/python2.7/site-packages/gunicorn/arbiter.py", line 524, in reap_workers
    raise HaltServer(reason, self.WORKER_BOOT_ERROR)
gunicorn.errors.HaltServer: <HaltServer 'Worker failed to boot.' 3>
[2017-09-29 15:29:06 +0000] [18253] [DEBUG] Current configuration:
  proxy_protocol: False
  worker_connections: 1000
  statsd_host: None
  max_requests_jitter: 0
  post_fork: <function post_fork at 0x2c24410>
  errorlog: -
  enable_stdio_inheritance: False
  worker_class: gevent
  ssl_version: 2
  suppress_ragged_eofs: True
  syslog: False
  syslog_facility: user
  when_ready: <function when_ready at 0x2c24140>
  pre_fork: <function pre_fork at 0x2c242a8>
  cert_reqs: 0
  preload_app: False
  keepalive: 2
  accesslog: None
  group: 0
  graceful_timeout: 30
  do_handshake_on_connect: False
  spew: False
  workers: 2
  proc_name: gunicorn.pid
  sendfile: None
  pidfile: /var/log/gunicorn/debug.log
  umask: 0
  on_reload: <function on_reload at 0x2bf0f50>
  pre_exec: <function pre_exec at 0x2c249b0>
  worker_tmp_dir: None
  limit_request_fields: 100
  pythonpath: None
  on_exit: <function on_exit at 0x2c26230>
  config: /var/www/projects/myblog/deploy_config.py
  logconfig: None
  check_config: False
  statsd_prefix: 
  secure_scheme_headers: {'X-FORWARDED-PROTOCOL': 'ssl', 'X-FORWARDED-PROTO': 'https', 'X-FORWARDED-SSL': 'on'}
  reload_engine: auto
  proxy_allow_ips: ['127.0.0.1']
  pre_request: <function pre_request at 0x2c24b18>
  post_request: <function post_request at 0x2c24c08>
  forwarded_allow_ips: ['127.0.0.1']
  worker_int: <function worker_int at 0x2c246e0>
  raw_paste_global_conf: []
  threads: 1
  max_requests: 0
  chdir: /var/www/projects/myblog
  daemon: False
  user: 0
  limit_request_line: 4094
  access_log_format: %(h)s %(l)s %(u)s %(t)s "%(r)s" %(s)s %(b)s "%(f)s" "%(a)s"
  certfile: None
  on_starting: <function on_starting at 0x2bf0de8>
  post_worker_init: <function post_worker_init at 0x2c24578>
  child_exit: <function child_exit at 0x2c24d70>
  worker_exit: <function worker_exit at 0x2c24ed8>
  paste: None
  default_proc_name: manage:app
  syslog_addr: udp://localhost:514
  syslog_prefix: None
  ciphers: TLSv1
  worker_abort: <function worker_abort at 0x2c24848>
  loglevel: debug
  bind: ['127.0.0.1:8080']
  raw_env: []
  initgroups: False
  capture_output: False
  reload: False
  limit_request_field_size: 8190
  nworkers_changed: <function nworkers_changed at 0x2c260c8>
  timeout: 30
  keyfile: None
  ca_certs: None
  tmp_upload_dir: None
  backlog: 2048
  logger_class: gunicorn.glogging.Logger
[2017-09-29 15:29:06 +0000] [18253] [INFO] Starting gunicorn 19.7.1
[2017-09-29 15:29:06 +0000] [18253] [DEBUG] Arbiter booted
[2017-09-29 15:29:06 +0000] [18253] [INFO] Listening at: http://127.0.0.1:8080 (18253)
[2017-09-29 15:29:06 +0000] [18253] [INFO] Using worker: gevent
[2017-09-29 15:29:06 +0000] [18258] [INFO] Booting worker with pid: 18258
[2017-09-29 15:29:06 +0000] [18259] [INFO] Booting worker with pid: 18259
[2017-09-29 15:29:06 +0000] [18253] [DEBUG] 2 workers
[2017-09-29 15:29:10 +0000] [18258] [ERROR] Exception in worker process
Traceback (most recent call last):
  File "/var/www/projects/myblog/venv/lib/python2.7/site-packages/gunicorn/arbiter.py", line 578, in spawn_worker
    worker.init_process()
  File "/var/www/projects/myblog/venv/lib/python2.7/site-packages/gunicorn/workers/ggevent.py", line 190, in init_process
    super(GeventWorker, self).init_process()
  File "/var/www/projects/myblog/venv/lib/python2.7/site-packages/gunicorn/workers/base.py", line 126, in init_process
    self.load_wsgi()
  File "/var/www/projects/myblog/venv/lib/python2.7/site-packages/gunicorn/workers/base.py", line 135, in load_wsgi
    self.wsgi = self.app.wsgi()
  File "/var/www/projects/myblog/venv/lib/python2.7/site-packages/gunicorn/app/base.py", line 67, in wsgi
    self.callable = self.load()
  File "/var/www/projects/myblog/venv/lib/python2.7/site-packages/gunicorn/app/wsgiapp.py", line 65, in load
    return self.load_wsgiapp()
  File "/var/www/projects/myblog/venv/lib/python2.7/site-packages/gunicorn/app/wsgiapp.py", line 52, in load_wsgiapp
    return util.import_app(self.app_uri)
  File "/var/www/projects/myblog/venv/lib/python2.7/site-packages/gunicorn/util.py", line 352, in import_app
    __import__(module)
  File "/var/www/projects/myblog/venv/lib/python2.7/site-packages/gevent/builtins.py", line 93, in __import__
    result = _import(*args, **kwargs)
  File "/var/www/projects/myblog/manage.py", line 15, in <module>
    app = create_app(os.getenv('BLOG_CONFIG') or 'default')
  File "/var/www/projects/myblog/app/__init__.py", line 26, in create_app
    config[config_name].init_app(app)
  File "/var/www/projects/myblog/config.py", line 60, in init_app
    if gettattr(cls, 'MAIL_USE_TLS', None):
NameError: global name 'gettattr' is not defined
[2017-09-29 15:29:10 +0000] [18258] [INFO] Worker exiting (pid: 18258)
[2017-09-29 15:29:10 +0000] [18259] [ERROR] Exception in worker process
Traceback (most recent call last):
  File "/var/www/projects/myblog/venv/lib/python2.7/site-packages/gunicorn/arbiter.py", line 578, in spawn_worker
    worker.init_process()
  File "/var/www/projects/myblog/venv/lib/python2.7/site-packages/gunicorn/workers/ggevent.py", line 190, in init_process
    super(GeventWorker, self).init_process()
  File "/var/www/projects/myblog/venv/lib/python2.7/site-packages/gunicorn/workers/base.py", line 126, in init_process
    self.load_wsgi()
  File "/var/www/projects/myblog/venv/lib/python2.7/site-packages/gunicorn/workers/base.py", line 135, in load_wsgi
    self.wsgi = self.app.wsgi()
  File "/var/www/projects/myblog/venv/lib/python2.7/site-packages/gunicorn/app/base.py", line 67, in wsgi
    self.callable = self.load()
  File "/var/www/projects/myblog/venv/lib/python2.7/site-packages/gunicorn/app/wsgiapp.py", line 65, in load
    return self.load_wsgiapp()
  File "/var/www/projects/myblog/venv/lib/python2.7/site-packages/gunicorn/app/wsgiapp.py", line 52, in load_wsgiapp
    return util.import_app(self.app_uri)
  File "/var/www/projects/myblog/venv/lib/python2.7/site-packages/gunicorn/util.py", line 352, in import_app
    __import__(module)
  File "/var/www/projects/myblog/venv/lib/python2.7/site-packages/gevent/builtins.py", line 93, in __import__
    result = _import(*args, **kwargs)
  File "/var/www/projects/myblog/manage.py", line 15, in <module>
    app = create_app(os.getenv('BLOG_CONFIG') or 'default')
  File "/var/www/projects/myblog/app/__init__.py", line 26, in create_app
    config[config_name].init_app(app)
  File "/var/www/projects/myblog/config.py", line 60, in init_app
    if gettattr(cls, 'MAIL_USE_TLS', None):
NameError: global name 'gettattr' is not defined
[2017-09-29 15:29:10 +0000] [18259] [INFO] Worker exiting (pid: 18259)
[2017-09-29 15:29:10 +0000] [18253] [INFO] Shutting down: Master
[2017-09-29 15:29:10 +0000] [18253] [INFO] Reason: Worker failed to boot.
[2017-09-29 15:29:12 +0000] [18268] [DEBUG] Current configuration:
  proxy_protocol: False
  worker_connections: 1000
  statsd_host: None
  max_requests_jitter: 0
  post_fork: <function post_fork at 0x150b410>
  errorlog: -
  enable_stdio_inheritance: False
  worker_class: gevent
  ssl_version: 2
  suppress_ragged_eofs: True
  syslog: False
  syslog_facility: user
  when_ready: <function when_ready at 0x150b140>
  pre_fork: <function pre_fork at 0x150b2a8>
  cert_reqs: 0
  preload_app: False
  keepalive: 2
  accesslog: None
  group: 0
  graceful_timeout: 30
  do_handshake_on_connect: False
  spew: False
  workers: 2
  proc_name: gunicorn.pid
  sendfile: None
  pidfile: /var/log/gunicorn/debug.log
  umask: 0
  on_reload: <function on_reload at 0x14d7f50>
  pre_exec: <function pre_exec at 0x150b9b0>
  worker_tmp_dir: None
  limit_request_fields: 100
  pythonpath: None
  on_exit: <function on_exit at 0x150d230>
  config: /var/www/projects/myblog/deploy_config.py
  logconfig: None
  check_config: False
  statsd_prefix: 
  secure_scheme_headers: {'X-FORWARDED-PROTOCOL': 'ssl', 'X-FORWARDED-PROTO': 'https', 'X-FORWARDED-SSL': 'on'}
  reload_engine: auto
  proxy_allow_ips: ['127.0.0.1']
  pre_request: <function pre_request at 0x150bb18>
  post_request: <function post_request at 0x150bc08>
  forwarded_allow_ips: ['127.0.0.1']
  worker_int: <function worker_int at 0x150b6e0>
  raw_paste_global_conf: []
  threads: 1
  max_requests: 0
  chdir: /var/www/projects/myblog
  daemon: False
  user: 0
  limit_request_line: 4094
  access_log_format: %(h)s %(l)s %(u)s %(t)s "%(r)s" %(s)s %(b)s "%(f)s" "%(a)s"
  certfile: None
  on_starting: <function on_starting at 0x14d7de8>
  post_worker_init: <function post_worker_init at 0x150b578>
  child_exit: <function child_exit at 0x150bd70>
  worker_exit: <function worker_exit at 0x150bed8>
  paste: None
  default_proc_name: manage:app
  syslog_addr: udp://localhost:514
  syslog_prefix: None
  ciphers: TLSv1
  worker_abort: <function worker_abort at 0x150b848>
  loglevel: debug
  bind: ['127.0.0.1:8080']
  raw_env: []
  initgroups: False
  capture_output: False
  reload: False
  limit_request_field_size: 8190
  nworkers_changed: <function nworkers_changed at 0x150d0c8>
  timeout: 30
  keyfile: None
  ca_certs: None
  tmp_upload_dir: None
  backlog: 2048
  logger_class: gunicorn.glogging.Logger
[2017-09-29 15:29:12 +0000] [18268] [INFO] Starting gunicorn 19.7.1
[2017-09-29 15:29:12 +0000] [18268] [DEBUG] Arbiter booted
[2017-09-29 15:29:12 +0000] [18268] [INFO] Listening at: http://127.0.0.1:8080 (18268)
[2017-09-29 15:29:12 +0000] [18268] [INFO] Using worker: gevent
[2017-09-29 15:29:12 +0000] [18273] [INFO] Booting worker with pid: 18273
[2017-09-29 15:29:12 +0000] [18274] [INFO] Booting worker with pid: 18274
[2017-09-29 15:29:12 +0000] [18268] [DEBUG] 2 workers
[2017-09-29 15:29:15 +0000] [18273] [ERROR] Exception in worker process
Traceback (most recent call last):
  File "/var/www/projects/myblog/venv/lib/python2.7/site-packages/gunicorn/arbiter.py", line 578, in spawn_worker
    worker.init_process()
  File "/var/www/projects/myblog/venv/lib/python2.7/site-packages/gunicorn/workers/ggevent.py", line 190, in init_process
    super(GeventWorker, self).init_process()
  File "/var/www/projects/myblog/venv/lib/python2.7/site-packages/gunicorn/workers/base.py", line 126, in init_process
    self.load_wsgi()
  File "/var/www/projects/myblog/venv/lib/python2.7/site-packages/gunicorn/workers/base.py", line 135, in load_wsgi
    self.wsgi = self.app.wsgi()
  File "/var/www/projects/myblog/venv/lib/python2.7/site-packages/gunicorn/app/base.py", line 67, in wsgi
    self.callable = self.load()
  File "/var/www/projects/myblog/venv/lib/python2.7/site-packages/gunicorn/app/wsgiapp.py", line 65, in load
    return self.load_wsgiapp()
  File "/var/www/projects/myblog/venv/lib/python2.7/site-packages/gunicorn/app/wsgiapp.py", line 52, in load_wsgiapp
    return util.import_app(self.app_uri)
  File "/var/www/projects/myblog/venv/lib/python2.7/site-packages/gunicorn/util.py", line 352, in import_app
    __import__(module)
  File "/var/www/projects/myblog/venv/lib/python2.7/site-packages/gevent/builtins.py", line 93, in __import__
    result = _import(*args, **kwargs)
  File "/var/www/projects/myblog/manage.py", line 15, in <module>
    app = create_app(os.getenv('BLOG_CONFIG') or 'default')
  File "/var/www/projects/myblog/app/__init__.py", line 26, in create_app
    config[config_name].init_app(app)
  File "/var/www/projects/myblog/config.py", line 60, in init_app
    if gettattr(cls, 'MAIL_USE_TLS', None):
NameError: global name 'gettattr' is not defined
[2017-09-29 15:29:15 +0000] [18273] [INFO] Worker exiting (pid: 18273)
[2017-09-29 15:29:16 +0000] [18274] [ERROR] Exception in worker process
Traceback (most recent call last):
  File "/var/www/projects/myblog/venv/lib/python2.7/site-packages/gunicorn/arbiter.py", line 578, in spawn_worker
    worker.init_process()
  File "/var/www/projects/myblog/venv/lib/python2.7/site-packages/gunicorn/workers/ggevent.py", line 190, in init_process
    super(GeventWorker, self).init_process()
  File "/var/www/projects/myblog/venv/lib/python2.7/site-packages/gunicorn/workers/base.py", line 126, in init_process
    self.load_wsgi()
  File "/var/www/projects/myblog/venv/lib/python2.7/site-packages/gunicorn/workers/base.py", line 135, in load_wsgi
    self.wsgi = self.app.wsgi()
  File "/var/www/projects/myblog/venv/lib/python2.7/site-packages/gunicorn/app/base.py", line 67, in wsgi
    self.callable = self.load()
  File "/var/www/projects/myblog/venv/lib/python2.7/site-packages/gunicorn/app/wsgiapp.py", line 65, in load
    return self.load_wsgiapp()
  File "/var/www/projects/myblog/venv/lib/python2.7/site-packages/gunicorn/app/wsgiapp.py", line 52, in load_wsgiapp
    return util.import_app(self.app_uri)
  File "/var/www/projects/myblog/venv/lib/python2.7/site-packages/gunicorn/util.py", line 352, in import_app
    __import__(module)
  File "/var/www/projects/myblog/venv/lib/python2.7/site-packages/gevent/builtins.py", line 93, in __import__
    result = _import(*args, **kwargs)
  File "/var/www/projects/myblog/manage.py", line 15, in <module>
    app = create_app(os.getenv('BLOG_CONFIG') or 'default')
  File "/var/www/projects/myblog/app/__init__.py", line 26, in create_app
    config[config_name].init_app(app)
  File "/var/www/projects/myblog/config.py", line 60, in init_app
    if gettattr(cls, 'MAIL_USE_TLS', None):
NameError: global name 'gettattr' is not defined
[2017-09-29 15:29:16 +0000] [18274] [INFO] Worker exiting (pid: 18274)
[2017-09-29 15:29:16 +0000] [18268] [INFO] Shutting down: Master
[2017-09-29 15:29:16 +0000] [18268] [INFO] Reason: Worker failed to boot.
[2017-09-29 15:29:17 +0000] [18283] [DEBUG] Current configuration:
  proxy_protocol: False
  worker_connections: 1000
  statsd_host: None
  max_requests_jitter: 0
  post_fork: <function post_fork at 0x2bcf410>
  errorlog: -
  enable_stdio_inheritance: False
  worker_class: gevent
  ssl_version: 2
  suppress_ragged_eofs: True
  syslog: False
  syslog_facility: user
  when_ready: <function when_ready at 0x2bcf140>
  pre_fork: <function pre_fork at 0x2bcf2a8>
  cert_reqs: 0
  preload_app: False
  keepalive: 2
  accesslog: None
  group: 0
  graceful_timeout: 30
  do_handshake_on_connect: False
  spew: False
  workers: 2
  proc_name: gunicorn.pid
  sendfile: None
  pidfile: /var/log/gunicorn/debug.log
  umask: 0
  on_reload: <function on_reload at 0x2b9bf50>
  pre_exec: <function pre_exec at 0x2bcf9b0>
  worker_tmp_dir: None
  limit_request_fields: 100
  pythonpath: None
  on_exit: <function on_exit at 0x2bd1230>
  config: /var/www/projects/myblog/deploy_config.py
  logconfig: None
  check_config: False
  statsd_prefix: 
  secure_scheme_headers: {'X-FORWARDED-PROTOCOL': 'ssl', 'X-FORWARDED-PROTO': 'https', 'X-FORWARDED-SSL': 'on'}
  reload_engine: auto
  proxy_allow_ips: ['127.0.0.1']
  pre_request: <function pre_request at 0x2bcfb18>
  post_request: <function post_request at 0x2bcfc08>
  forwarded_allow_ips: ['127.0.0.1']
  worker_int: <function worker_int at 0x2bcf6e0>
  raw_paste_global_conf: []
  threads: 1
  max_requests: 0
  chdir: /var/www/projects/myblog
  daemon: False
  user: 0
  limit_request_line: 4094
  access_log_format: %(h)s %(l)s %(u)s %(t)s "%(r)s" %(s)s %(b)s "%(f)s" "%(a)s"
  certfile: None
  on_starting: <function on_starting at 0x2b9bde8>
  post_worker_init: <function post_worker_init at 0x2bcf578>
  child_exit: <function child_exit at 0x2bcfd70>
  worker_exit: <function worker_exit at 0x2bcfed8>
  paste: None
  default_proc_name: manage:app
  syslog_addr: udp://localhost:514
  syslog_prefix: None
  ciphers: TLSv1
  worker_abort: <function worker_abort at 0x2bcf848>
  loglevel: debug
  bind: ['127.0.0.1:8080']
  raw_env: []
  initgroups: False
  capture_output: False
  reload: False
  limit_request_field_size: 8190
  nworkers_changed: <function nworkers_changed at 0x2bd10c8>
  timeout: 30
  keyfile: None
  ca_certs: None
  tmp_upload_dir: None
  backlog: 2048
  logger_class: gunicorn.glogging.Logger
[2017-09-29 15:29:17 +0000] [18283] [INFO] Starting gunicorn 19.7.1
[2017-09-29 15:29:17 +0000] [18283] [DEBUG] Arbiter booted
[2017-09-29 15:29:17 +0000] [18283] [INFO] Listening at: http://127.0.0.1:8080 (18283)
[2017-09-29 15:29:17 +0000] [18283] [INFO] Using worker: gevent
[2017-09-29 15:29:17 +0000] [18288] [INFO] Booting worker with pid: 18288
[2017-09-29 15:29:17 +0000] [18289] [INFO] Booting worker with pid: 18289
[2017-09-29 15:29:17 +0000] [18283] [DEBUG] 2 workers
[2017-09-29 15:29:22 +0000] [18289] [ERROR] Exception in worker process
Traceback (most recent call last):
  File "/var/www/projects/myblog/venv/lib/python2.7/site-packages/gunicorn/arbiter.py", line 578, in spawn_worker
    worker.init_process()
  File "/var/www/projects/myblog/venv/lib/python2.7/site-packages/gunicorn/workers/ggevent.py", line 190, in init_process
    super(GeventWorker, self).init_process()
  File "/var/www/projects/myblog/venv/lib/python2.7/site-packages/gunicorn/workers/base.py", line 126, in init_process
    self.load_wsgi()
  File "/var/www/projects/myblog/venv/lib/python2.7/site-packages/gunicorn/workers/base.py", line 135, in load_wsgi
    self.wsgi = self.app.wsgi()
  File "/var/www/projects/myblog/venv/lib/python2.7/site-packages/gunicorn/app/base.py", line 67, in wsgi
    self.callable = self.load()
  File "/var/www/projects/myblog/venv/lib/python2.7/site-packages/gunicorn/app/wsgiapp.py", line 65, in load
    return self.load_wsgiapp()
  File "/var/www/projects/myblog/venv/lib/python2.7/site-packages/gunicorn/app/wsgiapp.py", line 52, in load_wsgiapp
    return util.import_app(self.app_uri)
  File "/var/www/projects/myblog/venv/lib/python2.7/site-packages/gunicorn/util.py", line 352, in import_app
    __import__(module)
  File "/var/www/projects/myblog/venv/lib/python2.7/site-packages/gevent/builtins.py", line 93, in __import__
    result = _import(*args, **kwargs)
  File "/var/www/projects/myblog/manage.py", line 15, in <module>
    app = create_app(os.getenv('BLOG_CONFIG') or 'default')
  File "/var/www/projects/myblog/app/__init__.py", line 26, in create_app
    config[config_name].init_app(app)
  File "/var/www/projects/myblog/config.py", line 60, in init_app
    if gettattr(cls, 'MAIL_USE_TLS', None):
NameError: global name 'gettattr' is not defined
[2017-09-29 15:29:22 +0000] [18289] [INFO] Worker exiting (pid: 18289)
[2017-09-29 15:29:22 +0000] [18288] [ERROR] Exception in worker process
Traceback (most recent call last):
  File "/var/www/projects/myblog/venv/lib/python2.7/site-packages/gunicorn/arbiter.py", line 578, in spawn_worker
    worker.init_process()
  File "/var/www/projects/myblog/venv/lib/python2.7/site-packages/gunicorn/workers/ggevent.py", line 190, in init_process
    super(GeventWorker, self).init_process()
  File "/var/www/projects/myblog/venv/lib/python2.7/site-packages/gunicorn/workers/base.py", line 126, in init_process
    self.load_wsgi()
  File "/var/www/projects/myblog/venv/lib/python2.7/site-packages/gunicorn/workers/base.py", line 135, in load_wsgi
    self.wsgi = self.app.wsgi()
  File "/var/www/projects/myblog/venv/lib/python2.7/site-packages/gunicorn/app/base.py", line 67, in wsgi
    self.callable = self.load()
  File "/var/www/projects/myblog/venv/lib/python2.7/site-packages/gunicorn/app/wsgiapp.py", line 65, in load
    return self.load_wsgiapp()
  File "/var/www/projects/myblog/venv/lib/python2.7/site-packages/gunicorn/app/wsgiapp.py", line 52, in load_wsgiapp
    return util.import_app(self.app_uri)
  File "/var/www/projects/myblog/venv/lib/python2.7/site-packages/gunicorn/util.py", line 352, in import_app
    __import__(module)
  File "/var/www/projects/myblog/venv/lib/python2.7/site-packages/gevent/builtins.py", line 93, in __import__
    result = _import(*args, **kwargs)
  File "/var/www/projects/myblog/manage.py", line 15, in <module>
    app = create_app(os.getenv('BLOG_CONFIG') or 'default')
  File "/var/www/projects/myblog/app/__init__.py", line 26, in create_app
    config[config_name].init_app(app)
  File "/var/www/projects/myblog/config.py", line 60, in init_app
    if gettattr(cls, 'MAIL_USE_TLS', None):
NameError: global name 'gettattr' is not defined
[2017-09-29 15:29:22 +0000] [18288] [INFO] Worker exiting (pid: 18288)
Traceback (most recent call last):
  File "/var/www/projects/myblog/venv/bin/gunicorn", line 11, in <module>
    sys.exit(run())
  File "/var/www/projects/myblog/venv/lib/python2.7/site-packages/gunicorn/app/wsgiapp.py", line 74, in run
    WSGIApplication("%(prog)s [OPTIONS] [APP_MODULE]").run()
  File "/var/www/projects/myblog/venv/lib/python2.7/site-packages/gunicorn/app/base.py", line 203, in run
    super(Application, self).run()
  File "/var/www/projects/myblog/venv/lib/python2.7/site-packages/gunicorn/app/base.py", line 72, in run
    Arbiter(self).run()
  File "/var/www/projects/myblog/venv/lib/python2.7/site-packages/gunicorn/arbiter.py", line 231, in run
    self.halt(reason=inst.reason, exit_status=inst.exit_status)
  File "/var/www/projects/myblog/venv/lib/python2.7/site-packages/gunicorn/arbiter.py", line 344, in halt
    self.stop()
  File "/var/www/projects/myblog/venv/lib/python2.7/site-packages/gunicorn/arbiter.py", line 393, in stop
    time.sleep(0.1)
  File "/var/www/projects/myblog/venv/lib/python2.7/site-packages/gunicorn/arbiter.py", line 244, in handle_chld
    self.reap_workers()
  File "/var/www/projects/myblog/venv/lib/python2.7/site-packages/gunicorn/arbiter.py", line 524, in reap_workers
    raise HaltServer(reason, self.WORKER_BOOT_ERROR)
gunicorn.errors.HaltServer: <HaltServer 'Worker failed to boot.' 3>
[2017-09-29 15:29:24 +0000] [18298] [DEBUG] Current configuration:
  proxy_protocol: False
  worker_connections: 1000
  statsd_host: None
  max_requests_jitter: 0
  post_fork: <function post_fork at 0x1e95410>
  errorlog: -
  enable_stdio_inheritance: False
  worker_class: gevent
  ssl_version: 2
  suppress_ragged_eofs: True
  syslog: False
  syslog_facility: user
  when_ready: <function when_ready at 0x1e95140>
  pre_fork: <function pre_fork at 0x1e952a8>
  cert_reqs: 0
  preload_app: False
  keepalive: 2
  accesslog: None
  group: 0
  graceful_timeout: 30
  do_handshake_on_connect: False
  spew: False
  workers: 2
  proc_name: gunicorn.pid
  sendfile: None
  pidfile: /var/log/gunicorn/debug.log
  umask: 0
  on_reload: <function on_reload at 0x1e61f50>
  pre_exec: <function pre_exec at 0x1e959b0>
  worker_tmp_dir: None
  limit_request_fields: 100
  pythonpath: None
  on_exit: <function on_exit at 0x1e97230>
  config: /var/www/projects/myblog/deploy_config.py
  logconfig: None
  check_config: False
  statsd_prefix: 
  secure_scheme_headers: {'X-FORWARDED-PROTOCOL': 'ssl', 'X-FORWARDED-PROTO': 'https', 'X-FORWARDED-SSL': 'on'}
  reload_engine: auto
  proxy_allow_ips: ['127.0.0.1']
  pre_request: <function pre_request at 0x1e95b18>
  post_request: <function post_request at 0x1e95c08>
  forwarded_allow_ips: ['127.0.0.1']
  worker_int: <function worker_int at 0x1e956e0>
  raw_paste_global_conf: []
  threads: 1
  max_requests: 0
  chdir: /var/www/projects/myblog
  daemon: False
  user: 0
  limit_request_line: 4094
  access_log_format: %(h)s %(l)s %(u)s %(t)s "%(r)s" %(s)s %(b)s "%(f)s" "%(a)s"
  certfile: None
  on_starting: <function on_starting at 0x1e61de8>
  post_worker_init: <function post_worker_init at 0x1e95578>
  child_exit: <function child_exit at 0x1e95d70>
  worker_exit: <function worker_exit at 0x1e95ed8>
  paste: None
  default_proc_name: manage:app
  syslog_addr: udp://localhost:514
  syslog_prefix: None
  ciphers: TLSv1
  worker_abort: <function worker_abort at 0x1e95848>
  loglevel: debug
  bind: ['127.0.0.1:8080']
  raw_env: []
  initgroups: False
  capture_output: False
  reload: False
  limit_request_field_size: 8190
  nworkers_changed: <function nworkers_changed at 0x1e970c8>
  timeout: 30
  keyfile: None
  ca_certs: None
  tmp_upload_dir: None
  backlog: 2048
  logger_class: gunicorn.glogging.Logger
[2017-09-29 15:29:24 +0000] [18298] [INFO] Starting gunicorn 19.7.1
[2017-09-29 15:29:24 +0000] [18298] [DEBUG] Arbiter booted
[2017-09-29 15:29:24 +0000] [18298] [INFO] Listening at: http://127.0.0.1:8080 (18298)
[2017-09-29 15:29:24 +0000] [18298] [INFO] Using worker: gevent
[2017-09-29 15:29:24 +0000] [18303] [INFO] Booting worker with pid: 18303
[2017-09-29 15:29:24 +0000] [18298] [DEBUG] 2 workers
[2017-09-29 15:29:24 +0000] [18304] [INFO] Booting worker with pid: 18304
[2017-09-29 15:29:29 +0000] [18303] [ERROR] Exception in worker process
Traceback (most recent call last):
  File "/var/www/projects/myblog/venv/lib/python2.7/site-packages/gunicorn/arbiter.py", line 578, in spawn_worker
    worker.init_process()
  File "/var/www/projects/myblog/venv/lib/python2.7/site-packages/gunicorn/workers/ggevent.py", line 190, in init_process
    super(GeventWorker, self).init_process()
  File "/var/www/projects/myblog/venv/lib/python2.7/site-packages/gunicorn/workers/base.py", line 126, in init_process
    self.load_wsgi()
  File "/var/www/projects/myblog/venv/lib/python2.7/site-packages/gunicorn/workers/base.py", line 135, in load_wsgi
    self.wsgi = self.app.wsgi()
  File "/var/www/projects/myblog/venv/lib/python2.7/site-packages/gunicorn/app/base.py", line 67, in wsgi
    self.callable = self.load()
  File "/var/www/projects/myblog/venv/lib/python2.7/site-packages/gunicorn/app/wsgiapp.py", line 65, in load
    return self.load_wsgiapp()
  File "/var/www/projects/myblog/venv/lib/python2.7/site-packages/gunicorn/app/wsgiapp.py", line 52, in load_wsgiapp
    return util.import_app(self.app_uri)
  File "/var/www/projects/myblog/venv/lib/python2.7/site-packages/gunicorn/util.py", line 352, in import_app
    __import__(module)
  File "/var/www/projects/myblog/venv/lib/python2.7/site-packages/gevent/builtins.py", line 93, in __import__
    result = _import(*args, **kwargs)
  File "/var/www/projects/myblog/manage.py", line 15, in <module>
    app = create_app(os.getenv('BLOG_CONFIG') or 'default')
  File "/var/www/projects/myblog/app/__init__.py", line 26, in create_app
    config[config_name].init_app(app)
  File "/var/www/projects/myblog/config.py", line 60, in init_app
    if gettattr(cls, 'MAIL_USE_TLS', None):
NameError: global name 'gettattr' is not defined
[2017-09-29 15:29:29 +0000] [18303] [INFO] Worker exiting (pid: 18303)
[2017-09-29 15:29:29 +0000] [18304] [ERROR] Exception in worker process
Traceback (most recent call last):
  File "/var/www/projects/myblog/venv/lib/python2.7/site-packages/gunicorn/arbiter.py", line 578, in spawn_worker
    worker.init_process()
  File "/var/www/projects/myblog/venv/lib/python2.7/site-packages/gunicorn/workers/ggevent.py", line 190, in init_process
    super(GeventWorker, self).init_process()
  File "/var/www/projects/myblog/venv/lib/python2.7/site-packages/gunicorn/workers/base.py", line 126, in init_process
    self.load_wsgi()
  File "/var/www/projects/myblog/venv/lib/python2.7/site-packages/gunicorn/workers/base.py", line 135, in load_wsgi
    self.wsgi = self.app.wsgi()
  File "/var/www/projects/myblog/venv/lib/python2.7/site-packages/gunicorn/app/base.py", line 67, in wsgi
    self.callable = self.load()
  File "/var/www/projects/myblog/venv/lib/python2.7/site-packages/gunicorn/app/wsgiapp.py", line 65, in load
    return self.load_wsgiapp()
  File "/var/www/projects/myblog/venv/lib/python2.7/site-packages/gunicorn/app/wsgiapp.py", line 52, in load_wsgiapp
    return util.import_app(self.app_uri)
  File "/var/www/projects/myblog/venv/lib/python2.7/site-packages/gunicorn/util.py", line 352, in import_app
    __import__(module)
  File "/var/www/projects/myblog/venv/lib/python2.7/site-packages/gevent/builtins.py", line 93, in __import__
    result = _import(*args, **kwargs)
  File "/var/www/projects/myblog/manage.py", line 15, in <module>
    app = create_app(os.getenv('BLOG_CONFIG') or 'default')
  File "/var/www/projects/myblog/app/__init__.py", line 26, in create_app
    config[config_name].init_app(app)
  File "/var/www/projects/myblog/config.py", line 60, in init_app
    if gettattr(cls, 'MAIL_USE_TLS', None):
NameError: global name 'gettattr' is not defined
[2017-09-29 15:29:29 +0000] [18304] [INFO] Worker exiting (pid: 18304)
[2017-09-29 15:29:29 +0000] [18298] [INFO] Shutting down: Master
[2017-09-29 15:29:29 +0000] [18298] [INFO] Reason: Worker failed to boot.
[2017-09-29 15:29:30 +0000] [18313] [DEBUG] Current configuration:
  proxy_protocol: False
  worker_connections: 1000
  statsd_host: None
  max_requests_jitter: 0
  post_fork: <function post_fork at 0x2632410>
  errorlog: -
  enable_stdio_inheritance: False
  worker_class: gevent
  ssl_version: 2
  suppress_ragged_eofs: True
  syslog: False
  syslog_facility: user
  when_ready: <function when_ready at 0x2632140>
  pre_fork: <function pre_fork at 0x26322a8>
  cert_reqs: 0
  preload_app: False
  keepalive: 2
  accesslog: None
  group: 0
  graceful_timeout: 30
  do_handshake_on_connect: False
  spew: False
  workers: 2
  proc_name: gunicorn.pid
  sendfile: None
  pidfile: /var/log/gunicorn/debug.log
  umask: 0
  on_reload: <function on_reload at 0x25fff50>
  pre_exec: <function pre_exec at 0x26329b0>
  worker_tmp_dir: None
  limit_request_fields: 100
  pythonpath: None
  on_exit: <function on_exit at 0x2634230>
  config: /var/www/projects/myblog/deploy_config.py
  logconfig: None
  check_config: False
  statsd_prefix: 
  secure_scheme_headers: {'X-FORWARDED-PROTOCOL': 'ssl', 'X-FORWARDED-PROTO': 'https', 'X-FORWARDED-SSL': 'on'}
  reload_engine: auto
  proxy_allow_ips: ['127.0.0.1']
  pre_request: <function pre_request at 0x2632b18>
  post_request: <function post_request at 0x2632c08>
  forwarded_allow_ips: ['127.0.0.1']
  worker_int: <function worker_int at 0x26326e0>
  raw_paste_global_conf: []
  threads: 1
  max_requests: 0
  chdir: /var/www/projects/myblog
  daemon: False
  user: 0
  limit_request_line: 4094
  access_log_format: %(h)s %(l)s %(u)s %(t)s "%(r)s" %(s)s %(b)s "%(f)s" "%(a)s"
  certfile: None
  on_starting: <function on_starting at 0x25ffde8>
  post_worker_init: <function post_worker_init at 0x2632578>
  child_exit: <function child_exit at 0x2632d70>
  worker_exit: <function worker_exit at 0x2632ed8>
  paste: None
  default_proc_name: manage:app
  syslog_addr: udp://localhost:514
  syslog_prefix: None
  ciphers: TLSv1
  worker_abort: <function worker_abort at 0x2632848>
  loglevel: debug
  bind: ['127.0.0.1:8080']
  raw_env: []
  initgroups: False
  capture_output: False
  reload: False
  limit_request_field_size: 8190
  nworkers_changed: <function nworkers_changed at 0x26340c8>
  timeout: 30
  keyfile: None
  ca_certs: None
  tmp_upload_dir: None
  backlog: 2048
  logger_class: gunicorn.glogging.Logger
[2017-09-29 15:29:30 +0000] [18313] [INFO] Starting gunicorn 19.7.1
[2017-09-29 15:29:30 +0000] [18313] [DEBUG] Arbiter booted
[2017-09-29 15:29:30 +0000] [18313] [INFO] Listening at: http://127.0.0.1:8080 (18313)
[2017-09-29 15:29:30 +0000] [18313] [INFO] Using worker: gevent
[2017-09-29 15:29:30 +0000] [18318] [INFO] Booting worker with pid: 18318
[2017-09-29 15:29:30 +0000] [18319] [INFO] Booting worker with pid: 18319
[2017-09-29 15:29:30 +0000] [18313] [DEBUG] 2 workers
[2017-09-29 15:29:35 +0000] [18318] [ERROR] Exception in worker process
Traceback (most recent call last):
  File "/var/www/projects/myblog/venv/lib/python2.7/site-packages/gunicorn/arbiter.py", line 578, in spawn_worker
    worker.init_process()
  File "/var/www/projects/myblog/venv/lib/python2.7/site-packages/gunicorn/workers/ggevent.py", line 190, in init_process
    super(GeventWorker, self).init_process()
  File "/var/www/projects/myblog/venv/lib/python2.7/site-packages/gunicorn/workers/base.py", line 126, in init_process
    self.load_wsgi()
  File "/var/www/projects/myblog/venv/lib/python2.7/site-packages/gunicorn/workers/base.py", line 135, in load_wsgi
    self.wsgi = self.app.wsgi()
  File "/var/www/projects/myblog/venv/lib/python2.7/site-packages/gunicorn/app/base.py", line 67, in wsgi
    self.callable = self.load()
  File "/var/www/projects/myblog/venv/lib/python2.7/site-packages/gunicorn/app/wsgiapp.py", line 65, in load
    return self.load_wsgiapp()
  File "/var/www/projects/myblog/venv/lib/python2.7/site-packages/gunicorn/app/wsgiapp.py", line 52, in load_wsgiapp
    return util.import_app(self.app_uri)
  File "/var/www/projects/myblog/venv/lib/python2.7/site-packages/gunicorn/util.py", line 352, in import_app
    __import__(module)
  File "/var/www/projects/myblog/venv/lib/python2.7/site-packages/gevent/builtins.py", line 93, in __import__
    result = _import(*args, **kwargs)
  File "/var/www/projects/myblog/manage.py", line 15, in <module>
    app = create_app(os.getenv('BLOG_CONFIG') or 'default')
  File "/var/www/projects/myblog/app/__init__.py", line 26, in create_app
    config[config_name].init_app(app)
  File "/var/www/projects/myblog/config.py", line 60, in init_app
    if gettattr(cls, 'MAIL_USE_TLS', None):
NameError: global name 'gettattr' is not defined
[2017-09-29 15:29:35 +0000] [18318] [INFO] Worker exiting (pid: 18318)
[2017-09-29 15:29:35 +0000] [18319] [ERROR] Exception in worker process
Traceback (most recent call last):
  File "/var/www/projects/myblog/venv/lib/python2.7/site-packages/gunicorn/arbiter.py", line 578, in spawn_worker
    worker.init_process()
  File "/var/www/projects/myblog/venv/lib/python2.7/site-packages/gunicorn/workers/ggevent.py", line 190, in init_process
    super(GeventWorker, self).init_process()
  File "/var/www/projects/myblog/venv/lib/python2.7/site-packages/gunicorn/workers/base.py", line 126, in init_process
    self.load_wsgi()
  File "/var/www/projects/myblog/venv/lib/python2.7/site-packages/gunicorn/workers/base.py", line 135, in load_wsgi
    self.wsgi = self.app.wsgi()
  File "/var/www/projects/myblog/venv/lib/python2.7/site-packages/gunicorn/app/base.py", line 67, in wsgi
    self.callable = self.load()
  File "/var/www/projects/myblog/venv/lib/python2.7/site-packages/gunicorn/app/wsgiapp.py", line 65, in load
    return self.load_wsgiapp()
  File "/var/www/projects/myblog/venv/lib/python2.7/site-packages/gunicorn/app/wsgiapp.py", line 52, in load_wsgiapp
    return util.import_app(self.app_uri)
  File "/var/www/projects/myblog/venv/lib/python2.7/site-packages/gunicorn/util.py", line 352, in import_app
    __import__(module)
  File "/var/www/projects/myblog/venv/lib/python2.7/site-packages/gevent/builtins.py", line 93, in __import__
    result = _import(*args, **kwargs)
  File "/var/www/projects/myblog/manage.py", line 15, in <module>
    app = create_app(os.getenv('BLOG_CONFIG') or 'default')
  File "/var/www/projects/myblog/app/__init__.py", line 26, in create_app
    config[config_name].init_app(app)
  File "/var/www/projects/myblog/config.py", line 60, in init_app
    if gettattr(cls, 'MAIL_USE_TLS', None):
NameError: global name 'gettattr' is not defined
[2017-09-29 15:29:35 +0000] [18319] [INFO] Worker exiting (pid: 18319)
[2017-09-29 15:29:36 +0000] [18313] [INFO] Shutting down: Master
[2017-09-29 15:29:36 +0000] [18313] [INFO] Reason: Worker failed to boot.
[2017-09-29 15:29:37 +0000] [18328] [DEBUG] Current configuration:
  proxy_protocol: False
  worker_connections: 1000
  statsd_host: None
  max_requests_jitter: 0
  post_fork: <function post_fork at 0x2709410>
  errorlog: -
  enable_stdio_inheritance: False
  worker_class: gevent
  ssl_version: 2
  suppress_ragged_eofs: True
  syslog: False
  syslog_facility: user
  when_ready: <function when_ready at 0x2709140>
  pre_fork: <function pre_fork at 0x27092a8>
  cert_reqs: 0
  preload_app: False
  keepalive: 2
  accesslog: None
  group: 0
  graceful_timeout: 30
  do_handshake_on_connect: False
  spew: False
  workers: 2
  proc_name: gunicorn.pid
  sendfile: None
  pidfile: /var/log/gunicorn/debug.log
  umask: 0
  on_reload: <function on_reload at 0x26d6f50>
  pre_exec: <function pre_exec at 0x27099b0>
  worker_tmp_dir: None
  limit_request_fields: 100
  pythonpath: None
  on_exit: <function on_exit at 0x270b230>
  config: /var/www/projects/myblog/deploy_config.py
  logconfig: None
  check_config: False
  statsd_prefix: 
  secure_scheme_headers: {'X-FORWARDED-PROTOCOL': 'ssl', 'X-FORWARDED-PROTO': 'https', 'X-FORWARDED-SSL': 'on'}
  reload_engine: auto
  proxy_allow_ips: ['127.0.0.1']
  pre_request: <function pre_request at 0x2709b18>
  post_request: <function post_request at 0x2709c08>
  forwarded_allow_ips: ['127.0.0.1']
  worker_int: <function worker_int at 0x27096e0>
  raw_paste_global_conf: []
  threads: 1
  max_requests: 0
  chdir: /var/www/projects/myblog
  daemon: False
  user: 0
  limit_request_line: 4094
  access_log_format: %(h)s %(l)s %(u)s %(t)s "%(r)s" %(s)s %(b)s "%(f)s" "%(a)s"
  certfile: None
  on_starting: <function on_starting at 0x26d6de8>
  post_worker_init: <function post_worker_init at 0x2709578>
  child_exit: <function child_exit at 0x2709d70>
  worker_exit: <function worker_exit at 0x2709ed8>
  paste: None
  default_proc_name: manage:app
  syslog_addr: udp://localhost:514
  syslog_prefix: None
  ciphers: TLSv1
  worker_abort: <function worker_abort at 0x2709848>
  loglevel: debug
  bind: ['127.0.0.1:8080']
  raw_env: []
  initgroups: False
  capture_output: False
  reload: False
  limit_request_field_size: 8190
  nworkers_changed: <function nworkers_changed at 0x270b0c8>
  timeout: 30
  keyfile: None
  ca_certs: None
  tmp_upload_dir: None
  backlog: 2048
  logger_class: gunicorn.glogging.Logger
[2017-09-29 15:29:37 +0000] [18328] [INFO] Starting gunicorn 19.7.1
[2017-09-29 15:29:37 +0000] [18328] [DEBUG] Arbiter booted
[2017-09-29 15:29:37 +0000] [18328] [INFO] Listening at: http://127.0.0.1:8080 (18328)
[2017-09-29 15:29:37 +0000] [18328] [INFO] Using worker: gevent
[2017-09-29 15:29:37 +0000] [18333] [INFO] Booting worker with pid: 18333
[2017-09-29 15:29:37 +0000] [18328] [DEBUG] 2 workers
[2017-09-29 15:29:37 +0000] [18334] [INFO] Booting worker with pid: 18334
[2017-09-29 15:29:42 +0000] [18333] [ERROR] Exception in worker process
Traceback (most recent call last):
  File "/var/www/projects/myblog/venv/lib/python2.7/site-packages/gunicorn/arbiter.py", line 578, in spawn_worker
    worker.init_process()
  File "/var/www/projects/myblog/venv/lib/python2.7/site-packages/gunicorn/workers/ggevent.py", line 190, in init_process
    super(GeventWorker, self).init_process()
  File "/var/www/projects/myblog/venv/lib/python2.7/site-packages/gunicorn/workers/base.py", line 126, in init_process
    self.load_wsgi()
  File "/var/www/projects/myblog/venv/lib/python2.7/site-packages/gunicorn/workers/base.py", line 135, in load_wsgi
    self.wsgi = self.app.wsgi()
  File "/var/www/projects/myblog/venv/lib/python2.7/site-packages/gunicorn/app/base.py", line 67, in wsgi
    self.callable = self.load()
  File "/var/www/projects/myblog/venv/lib/python2.7/site-packages/gunicorn/app/wsgiapp.py", line 65, in load
    return self.load_wsgiapp()
  File "/var/www/projects/myblog/venv/lib/python2.7/site-packages/gunicorn/app/wsgiapp.py", line 52, in load_wsgiapp
    return util.import_app(self.app_uri)
  File "/var/www/projects/myblog/venv/lib/python2.7/site-packages/gunicorn/util.py", line 352, in import_app
    __import__(module)
  File "/var/www/projects/myblog/venv/lib/python2.7/site-packages/gevent/builtins.py", line 93, in __import__
    result = _import(*args, **kwargs)
  File "/var/www/projects/myblog/manage.py", line 15, in <module>
    app = create_app(os.getenv('BLOG_CONFIG') or 'default')
  File "/var/www/projects/myblog/app/__init__.py", line 26, in create_app
    config[config_name].init_app(app)
  File "/var/www/projects/myblog/config.py", line 60, in init_app
    if gettattr(cls, 'MAIL_USE_TLS', None):
NameError: global name 'gettattr' is not defined
[2017-09-29 15:29:42 +0000] [18333] [INFO] Worker exiting (pid: 18333)
[2017-09-29 15:29:42 +0000] [18334] [ERROR] Exception in worker process
Traceback (most recent call last):
  File "/var/www/projects/myblog/venv/lib/python2.7/site-packages/gunicorn/arbiter.py", line 578, in spawn_worker
    worker.init_process()
  File "/var/www/projects/myblog/venv/lib/python2.7/site-packages/gunicorn/workers/ggevent.py", line 190, in init_process
    super(GeventWorker, self).init_process()
  File "/var/www/projects/myblog/venv/lib/python2.7/site-packages/gunicorn/workers/base.py", line 126, in init_process
    self.load_wsgi()
  File "/var/www/projects/myblog/venv/lib/python2.7/site-packages/gunicorn/workers/base.py", line 135, in load_wsgi
    self.wsgi = self.app.wsgi()
  File "/var/www/projects/myblog/venv/lib/python2.7/site-packages/gunicorn/app/base.py", line 67, in wsgi
    self.callable = self.load()
  File "/var/www/projects/myblog/venv/lib/python2.7/site-packages/gunicorn/app/wsgiapp.py", line 65, in load
    return self.load_wsgiapp()
  File "/var/www/projects/myblog/venv/lib/python2.7/site-packages/gunicorn/app/wsgiapp.py", line 52, in load_wsgiapp
    return util.import_app(self.app_uri)
  File "/var/www/projects/myblog/venv/lib/python2.7/site-packages/gunicorn/util.py", line 352, in import_app
    __import__(module)
  File "/var/www/projects/myblog/venv/lib/python2.7/site-packages/gevent/builtins.py", line 93, in __import__
    result = _import(*args, **kwargs)
  File "/var/www/projects/myblog/manage.py", line 15, in <module>
    app = create_app(os.getenv('BLOG_CONFIG') or 'default')
  File "/var/www/projects/myblog/app/__init__.py", line 26, in create_app
    config[config_name].init_app(app)
  File "/var/www/projects/myblog/config.py", line 60, in init_app
    if gettattr(cls, 'MAIL_USE_TLS', None):
NameError: global name 'gettattr' is not defined
[2017-09-29 15:29:42 +0000] [18334] [INFO] Worker exiting (pid: 18334)
[2017-09-29 15:29:42 +0000] [18328] [INFO] Shutting down: Master
[2017-09-29 15:29:42 +0000] [18328] [INFO] Reason: Worker failed to boot.
[2017-09-29 15:29:43 +0000] [18343] [DEBUG] Current configuration:
  proxy_protocol: False
  worker_connections: 1000
  statsd_host: None
  max_requests_jitter: 0
  post_fork: <function post_fork at 0x1bb7410>
  errorlog: -
  enable_stdio_inheritance: False
  worker_class: gevent
  ssl_version: 2
  suppress_ragged_eofs: True
  syslog: False
  syslog_facility: user
  when_ready: <function when_ready at 0x1bb7140>
  pre_fork: <function pre_fork at 0x1bb72a8>
  cert_reqs: 0
  preload_app: False
  keepalive: 2
  accesslog: None
  group: 0
  graceful_timeout: 30
  do_handshake_on_connect: False
  spew: False
  workers: 2
  proc_name: gunicorn.pid
  sendfile: None
  pidfile: /var/log/gunicorn/debug.log
  umask: 0
  on_reload: <function on_reload at 0x1b84f50>
  pre_exec: <function pre_exec at 0x1bb79b0>
  worker_tmp_dir: None
  limit_request_fields: 100
  pythonpath: None
  on_exit: <function on_exit at 0x1bb9230>
  config: /var/www/projects/myblog/deploy_config.py
  logconfig: None
  check_config: False
  statsd_prefix: 
  secure_scheme_headers: {'X-FORWARDED-PROTOCOL': 'ssl', 'X-FORWARDED-PROTO': 'https', 'X-FORWARDED-SSL': 'on'}
  reload_engine: auto
  proxy_allow_ips: ['127.0.0.1']
  pre_request: <function pre_request at 0x1bb7b18>
  post_request: <function post_request at 0x1bb7c08>
  forwarded_allow_ips: ['127.0.0.1']
  worker_int: <function worker_int at 0x1bb76e0>
  raw_paste_global_conf: []
  threads: 1
  max_requests: 0
  chdir: /var/www/projects/myblog
  daemon: False
  user: 0
  limit_request_line: 4094
  access_log_format: %(h)s %(l)s %(u)s %(t)s "%(r)s" %(s)s %(b)s "%(f)s" "%(a)s"
  certfile: None
  on_starting: <function on_starting at 0x1b84de8>
  post_worker_init: <function post_worker_init at 0x1bb7578>
  child_exit: <function child_exit at 0x1bb7d70>
  worker_exit: <function worker_exit at 0x1bb7ed8>
  paste: None
  default_proc_name: manage:app
  syslog_addr: udp://localhost:514
  syslog_prefix: None
  ciphers: TLSv1
  worker_abort: <function worker_abort at 0x1bb7848>
  loglevel: debug
  bind: ['127.0.0.1:8080']
  raw_env: []
  initgroups: False
  capture_output: False
  reload: False
  limit_request_field_size: 8190
  nworkers_changed: <function nworkers_changed at 0x1bb90c8>
  timeout: 30
  keyfile: None
  ca_certs: None
  tmp_upload_dir: None
  backlog: 2048
  logger_class: gunicorn.glogging.Logger
[2017-09-29 15:29:43 +0000] [18343] [INFO] Starting gunicorn 19.7.1
[2017-09-29 15:29:43 +0000] [18343] [DEBUG] Arbiter booted
[2017-09-29 15:29:43 +0000] [18343] [INFO] Listening at: http://127.0.0.1:8080 (18343)
[2017-09-29 15:29:43 +0000] [18343] [INFO] Using worker: gevent
[2017-09-29 15:29:43 +0000] [18348] [INFO] Booting worker with pid: 18348
[2017-09-29 15:29:43 +0000] [18349] [INFO] Booting worker with pid: 18349
[2017-09-29 15:29:43 +0000] [18343] [DEBUG] 2 workers
[2017-09-29 15:29:47 +0000] [18348] [ERROR] Exception in worker process
Traceback (most recent call last):
  File "/var/www/projects/myblog/venv/lib/python2.7/site-packages/gunicorn/arbiter.py", line 578, in spawn_worker
    worker.init_process()
  File "/var/www/projects/myblog/venv/lib/python2.7/site-packages/gunicorn/workers/ggevent.py", line 190, in init_process
    super(GeventWorker, self).init_process()
  File "/var/www/projects/myblog/venv/lib/python2.7/site-packages/gunicorn/workers/base.py", line 126, in init_process
    self.load_wsgi()
  File "/var/www/projects/myblog/venv/lib/python2.7/site-packages/gunicorn/workers/base.py", line 135, in load_wsgi
    self.wsgi = self.app.wsgi()
  File "/var/www/projects/myblog/venv/lib/python2.7/site-packages/gunicorn/app/base.py", line 67, in wsgi
    self.callable = self.load()
  File "/var/www/projects/myblog/venv/lib/python2.7/site-packages/gunicorn/app/wsgiapp.py", line 65, in load
    return self.load_wsgiapp()
  File "/var/www/projects/myblog/venv/lib/python2.7/site-packages/gunicorn/app/wsgiapp.py", line 52, in load_wsgiapp
    return util.import_app(self.app_uri)
  File "/var/www/projects/myblog/venv/lib/python2.7/site-packages/gunicorn/util.py", line 352, in import_app
    __import__(module)
  File "/var/www/projects/myblog/venv/lib/python2.7/site-packages/gevent/builtins.py", line 93, in __import__
    result = _import(*args, **kwargs)
  File "/var/www/projects/myblog/manage.py", line 15, in <module>
    app = create_app(os.getenv('BLOG_CONFIG') or 'default')
  File "/var/www/projects/myblog/app/__init__.py", line 26, in create_app
    config[config_name].init_app(app)
  File "/var/www/projects/myblog/config.py", line 60, in init_app
    if gettattr(cls, 'MAIL_USE_TLS', None):
NameError: global name 'gettattr' is not defined
[2017-09-29 15:29:47 +0000] [18348] [INFO] Worker exiting (pid: 18348)
[2017-09-29 15:29:48 +0000] [18349] [ERROR] Exception in worker process
Traceback (most recent call last):
  File "/var/www/projects/myblog/venv/lib/python2.7/site-packages/gunicorn/arbiter.py", line 578, in spawn_worker
    worker.init_process()
  File "/var/www/projects/myblog/venv/lib/python2.7/site-packages/gunicorn/workers/ggevent.py", line 190, in init_process
    super(GeventWorker, self).init_process()
  File "/var/www/projects/myblog/venv/lib/python2.7/site-packages/gunicorn/workers/base.py", line 126, in init_process
    self.load_wsgi()
  File "/var/www/projects/myblog/venv/lib/python2.7/site-packages/gunicorn/workers/base.py", line 135, in load_wsgi
    self.wsgi = self.app.wsgi()
  File "/var/www/projects/myblog/venv/lib/python2.7/site-packages/gunicorn/app/base.py", line 67, in wsgi
    self.callable = self.load()
  File "/var/www/projects/myblog/venv/lib/python2.7/site-packages/gunicorn/app/wsgiapp.py", line 65, in load
    return self.load_wsgiapp()
  File "/var/www/projects/myblog/venv/lib/python2.7/site-packages/gunicorn/app/wsgiapp.py", line 52, in load_wsgiapp
    return util.import_app(self.app_uri)
  File "/var/www/projects/myblog/venv/lib/python2.7/site-packages/gunicorn/util.py", line 352, in import_app
    __import__(module)
  File "/var/www/projects/myblog/venv/lib/python2.7/site-packages/gevent/builtins.py", line 93, in __import__
    result = _import(*args, **kwargs)
  File "/var/www/projects/myblog/manage.py", line 15, in <module>
    app = create_app(os.getenv('BLOG_CONFIG') or 'default')
  File "/var/www/projects/myblog/app/__init__.py", line 26, in create_app
    config[config_name].init_app(app)
  File "/var/www/projects/myblog/config.py", line 60, in init_app
    if gettattr(cls, 'MAIL_USE_TLS', None):
NameError: global name 'gettattr' is not defined
[2017-09-29 15:29:48 +0000] [18349] [INFO] Worker exiting (pid: 18349)
[2017-09-29 15:29:48 +0000] [18343] [INFO] Shutting down: Master
[2017-09-29 15:29:48 +0000] [18343] [INFO] Reason: Worker failed to boot.
[2017-09-29 15:29:49 +0000] [18358] [DEBUG] Current configuration:
  proxy_protocol: False
  worker_connections: 1000
  statsd_host: None
  max_requests_jitter: 0
  post_fork: <function post_fork at 0x2c5e410>
  errorlog: -
  enable_stdio_inheritance: False
  worker_class: gevent
  ssl_version: 2
  suppress_ragged_eofs: True
  syslog: False
  syslog_facility: user
  when_ready: <function when_ready at 0x2c5e140>
  pre_fork: <function pre_fork at 0x2c5e2a8>
  cert_reqs: 0
  preload_app: False
  keepalive: 2
  accesslog: None
  group: 0
  graceful_timeout: 30
  do_handshake_on_connect: False
  spew: False
  workers: 2
  proc_name: gunicorn.pid
  sendfile: None
  pidfile: /var/log/gunicorn/debug.log
  umask: 0
  on_reload: <function on_reload at 0x2c2af50>
  pre_exec: <function pre_exec at 0x2c5e9b0>
  worker_tmp_dir: None
  limit_request_fields: 100
  pythonpath: None
  on_exit: <function on_exit at 0x2c60230>
  config: /var/www/projects/myblog/deploy_config.py
  logconfig: None
  check_config: False
  statsd_prefix: 
  secure_scheme_headers: {'X-FORWARDED-PROTOCOL': 'ssl', 'X-FORWARDED-PROTO': 'https', 'X-FORWARDED-SSL': 'on'}
  reload_engine: auto
  proxy_allow_ips: ['127.0.0.1']
  pre_request: <function pre_request at 0x2c5eb18>
  post_request: <function post_request at 0x2c5ec08>
  forwarded_allow_ips: ['127.0.0.1']
  worker_int: <function worker_int at 0x2c5e6e0>
  raw_paste_global_conf: []
  threads: 1
  max_requests: 0
  chdir: /var/www/projects/myblog
  daemon: False
  user: 0
  limit_request_line: 4094
  access_log_format: %(h)s %(l)s %(u)s %(t)s "%(r)s" %(s)s %(b)s "%(f)s" "%(a)s"
  certfile: None
  on_starting: <function on_starting at 0x2c2ade8>
  post_worker_init: <function post_worker_init at 0x2c5e578>
  child_exit: <function child_exit at 0x2c5ed70>
  worker_exit: <function worker_exit at 0x2c5eed8>
  paste: None
  default_proc_name: manage:app
  syslog_addr: udp://localhost:514
  syslog_prefix: None
  ciphers: TLSv1
  worker_abort: <function worker_abort at 0x2c5e848>
  loglevel: debug
  bind: ['127.0.0.1:8080']
  raw_env: []
  initgroups: False
  capture_output: False
  reload: False
  limit_request_field_size: 8190
  nworkers_changed: <function nworkers_changed at 0x2c600c8>
  timeout: 30
  keyfile: None
  ca_certs: None
  tmp_upload_dir: None
  backlog: 2048
  logger_class: gunicorn.glogging.Logger
[2017-09-29 15:29:49 +0000] [18358] [INFO] Starting gunicorn 19.7.1
[2017-09-29 15:29:49 +0000] [18358] [DEBUG] Arbiter booted
[2017-09-29 15:29:49 +0000] [18358] [INFO] Listening at: http://127.0.0.1:8080 (18358)
[2017-09-29 15:29:49 +0000] [18358] [INFO] Using worker: gevent
[2017-09-29 15:29:49 +0000] [18363] [INFO] Booting worker with pid: 18363
[2017-09-29 15:29:49 +0000] [18364] [INFO] Booting worker with pid: 18364
[2017-09-29 15:29:49 +0000] [18358] [DEBUG] 2 workers
[2017-09-29 15:29:54 +0000] [18363] [ERROR] Exception in worker process
Traceback (most recent call last):
  File "/var/www/projects/myblog/venv/lib/python2.7/site-packages/gunicorn/arbiter.py", line 578, in spawn_worker
    worker.init_process()
  File "/var/www/projects/myblog/venv/lib/python2.7/site-packages/gunicorn/workers/ggevent.py", line 190, in init_process
    super(GeventWorker, self).init_process()
  File "/var/www/projects/myblog/venv/lib/python2.7/site-packages/gunicorn/workers/base.py", line 126, in init_process
    self.load_wsgi()
  File "/var/www/projects/myblog/venv/lib/python2.7/site-packages/gunicorn/workers/base.py", line 135, in load_wsgi
    self.wsgi = self.app.wsgi()
  File "/var/www/projects/myblog/venv/lib/python2.7/site-packages/gunicorn/app/base.py", line 67, in wsgi
    self.callable = self.load()
  File "/var/www/projects/myblog/venv/lib/python2.7/site-packages/gunicorn/app/wsgiapp.py", line 65, in load
    return self.load_wsgiapp()
  File "/var/www/projects/myblog/venv/lib/python2.7/site-packages/gunicorn/app/wsgiapp.py", line 52, in load_wsgiapp
    return util.import_app(self.app_uri)
  File "/var/www/projects/myblog/venv/lib/python2.7/site-packages/gunicorn/util.py", line 352, in import_app
    __import__(module)
  File "/var/www/projects/myblog/venv/lib/python2.7/site-packages/gevent/builtins.py", line 93, in __import__
    result = _import(*args, **kwargs)
  File "/var/www/projects/myblog/manage.py", line 15, in <module>
    app = create_app(os.getenv('BLOG_CONFIG') or 'default')
  File "/var/www/projects/myblog/app/__init__.py", line 26, in create_app
    config[config_name].init_app(app)
  File "/var/www/projects/myblog/config.py", line 60, in init_app
    if gettattr(cls, 'MAIL_USE_TLS', None):
NameError: global name 'gettattr' is not defined
[2017-09-29 15:29:54 +0000] [18363] [INFO] Worker exiting (pid: 18363)
[2017-09-29 15:29:54 +0000] [18364] [ERROR] Exception in worker process
Traceback (most recent call last):
  File "/var/www/projects/myblog/venv/lib/python2.7/site-packages/gunicorn/arbiter.py", line 578, in spawn_worker
    worker.init_process()
  File "/var/www/projects/myblog/venv/lib/python2.7/site-packages/gunicorn/workers/ggevent.py", line 190, in init_process
    super(GeventWorker, self).init_process()
  File "/var/www/projects/myblog/venv/lib/python2.7/site-packages/gunicorn/workers/base.py", line 126, in init_process
    self.load_wsgi()
  File "/var/www/projects/myblog/venv/lib/python2.7/site-packages/gunicorn/workers/base.py", line 135, in load_wsgi
    self.wsgi = self.app.wsgi()
  File "/var/www/projects/myblog/venv/lib/python2.7/site-packages/gunicorn/app/base.py", line 67, in wsgi
    self.callable = self.load()
  File "/var/www/projects/myblog/venv/lib/python2.7/site-packages/gunicorn/app/wsgiapp.py", line 65, in load
    return self.load_wsgiapp()
  File "/var/www/projects/myblog/venv/lib/python2.7/site-packages/gunicorn/app/wsgiapp.py", line 52, in load_wsgiapp
    return util.import_app(self.app_uri)
  File "/var/www/projects/myblog/venv/lib/python2.7/site-packages/gunicorn/util.py", line 352, in import_app
    __import__(module)
  File "/var/www/projects/myblog/venv/lib/python2.7/site-packages/gevent/builtins.py", line 93, in __import__
    result = _import(*args, **kwargs)
  File "/var/www/projects/myblog/manage.py", line 15, in <module>
    app = create_app(os.getenv('BLOG_CONFIG') or 'default')
  File "/var/www/projects/myblog/app/__init__.py", line 26, in create_app
    config[config_name].init_app(app)
  File "/var/www/projects/myblog/config.py", line 60, in init_app
    if gettattr(cls, 'MAIL_USE_TLS', None):
NameError: global name 'gettattr' is not defined
[2017-09-29 15:29:54 +0000] [18364] [INFO] Worker exiting (pid: 18364)
[2017-09-29 15:29:54 +0000] [18358] [INFO] Shutting down: Master
[2017-09-29 15:29:54 +0000] [18358] [INFO] Reason: Worker failed to boot.
[2017-09-29 15:29:55 +0000] [18373] [DEBUG] Current configuration:
  proxy_protocol: False
  worker_connections: 1000
  statsd_host: None
  max_requests_jitter: 0
  post_fork: <function post_fork at 0x1666410>
  errorlog: -
  enable_stdio_inheritance: False
  worker_class: gevent
  ssl_version: 2
  suppress_ragged_eofs: True
  syslog: False
  syslog_facility: user
  when_ready: <function when_ready at 0x1666140>
  pre_fork: <function pre_fork at 0x16662a8>
  cert_reqs: 0
  preload_app: False
  keepalive: 2
  accesslog: None
  group: 0
  graceful_timeout: 30
  do_handshake_on_connect: False
  spew: False
  workers: 2
  proc_name: gunicorn.pid
  sendfile: None
  pidfile: /var/log/gunicorn/debug.log
  umask: 0
  on_reload: <function on_reload at 0x1632f50>
  pre_exec: <function pre_exec at 0x16669b0>
  worker_tmp_dir: None
  limit_request_fields: 100
  pythonpath: None
  on_exit: <function on_exit at 0x1668230>
  config: /var/www/projects/myblog/deploy_config.py
  logconfig: None
  check_config: False
  statsd_prefix: 
  secure_scheme_headers: {'X-FORWARDED-PROTOCOL': 'ssl', 'X-FORWARDED-PROTO': 'https', 'X-FORWARDED-SSL': 'on'}
  reload_engine: auto
  proxy_allow_ips: ['127.0.0.1']
  pre_request: <function pre_request at 0x1666b18>
  post_request: <function post_request at 0x1666c08>
  forwarded_allow_ips: ['127.0.0.1']
  worker_int: <function worker_int at 0x16666e0>
  raw_paste_global_conf: []
  threads: 1
  max_requests: 0
  chdir: /var/www/projects/myblog
  daemon: False
  user: 0
  limit_request_line: 4094
  access_log_format: %(h)s %(l)s %(u)s %(t)s "%(r)s" %(s)s %(b)s "%(f)s" "%(a)s"
  certfile: None
  on_starting: <function on_starting at 0x1632de8>
  post_worker_init: <function post_worker_init at 0x1666578>
  child_exit: <function child_exit at 0x1666d70>
  worker_exit: <function worker_exit at 0x1666ed8>
  paste: None
  default_proc_name: manage:app
  syslog_addr: udp://localhost:514
  syslog_prefix: None
  ciphers: TLSv1
  worker_abort: <function worker_abort at 0x1666848>
  loglevel: debug
  bind: ['127.0.0.1:8080']
  raw_env: []
  initgroups: False
  capture_output: False
  reload: False
  limit_request_field_size: 8190
  nworkers_changed: <function nworkers_changed at 0x16680c8>
  timeout: 30
  keyfile: None
  ca_certs: None
  tmp_upload_dir: None
  backlog: 2048
  logger_class: gunicorn.glogging.Logger
[2017-09-29 15:29:55 +0000] [18373] [INFO] Starting gunicorn 19.7.1
[2017-09-29 15:29:55 +0000] [18373] [DEBUG] Arbiter booted
[2017-09-29 15:29:55 +0000] [18373] [INFO] Listening at: http://127.0.0.1:8080 (18373)
[2017-09-29 15:29:55 +0000] [18373] [INFO] Using worker: gevent
[2017-09-29 15:29:55 +0000] [18378] [INFO] Booting worker with pid: 18378
[2017-09-29 15:29:55 +0000] [18379] [INFO] Booting worker with pid: 18379
[2017-09-29 15:29:55 +0000] [18373] [DEBUG] 2 workers
[2017-09-29 15:29:59 +0000] [18378] [ERROR] Exception in worker process
Traceback (most recent call last):
  File "/var/www/projects/myblog/venv/lib/python2.7/site-packages/gunicorn/arbiter.py", line 578, in spawn_worker
    worker.init_process()
  File "/var/www/projects/myblog/venv/lib/python2.7/site-packages/gunicorn/workers/ggevent.py", line 190, in init_process
    super(GeventWorker, self).init_process()
  File "/var/www/projects/myblog/venv/lib/python2.7/site-packages/gunicorn/workers/base.py", line 126, in init_process
    self.load_wsgi()
  File "/var/www/projects/myblog/venv/lib/python2.7/site-packages/gunicorn/workers/base.py", line 135, in load_wsgi
    self.wsgi = self.app.wsgi()
  File "/var/www/projects/myblog/venv/lib/python2.7/site-packages/gunicorn/app/base.py", line 67, in wsgi
    self.callable = self.load()
  File "/var/www/projects/myblog/venv/lib/python2.7/site-packages/gunicorn/app/wsgiapp.py", line 65, in load
    return self.load_wsgiapp()
  File "/var/www/projects/myblog/venv/lib/python2.7/site-packages/gunicorn/app/wsgiapp.py", line 52, in load_wsgiapp
    return util.import_app(self.app_uri)
  File "/var/www/projects/myblog/venv/lib/python2.7/site-packages/gunicorn/util.py", line 352, in import_app
    __import__(module)
  File "/var/www/projects/myblog/venv/lib/python2.7/site-packages/gevent/builtins.py", line 93, in __import__
    result = _import(*args, **kwargs)
  File "/var/www/projects/myblog/manage.py", line 15, in <module>
    app = create_app(os.getenv('BLOG_CONFIG') or 'default')
  File "/var/www/projects/myblog/app/__init__.py", line 26, in create_app
    config[config_name].init_app(app)
  File "/var/www/projects/myblog/config.py", line 60, in init_app
    if gettattr(cls, 'MAIL_USE_TLS', None):
NameError: global name 'gettattr' is not defined
[2017-09-29 15:29:59 +0000] [18378] [INFO] Worker exiting (pid: 18378)
[2017-09-29 15:29:59 +0000] [18379] [ERROR] Exception in worker process
Traceback (most recent call last):
  File "/var/www/projects/myblog/venv/lib/python2.7/site-packages/gunicorn/arbiter.py", line 578, in spawn_worker
    worker.init_process()
  File "/var/www/projects/myblog/venv/lib/python2.7/site-packages/gunicorn/workers/ggevent.py", line 190, in init_process
    super(GeventWorker, self).init_process()
  File "/var/www/projects/myblog/venv/lib/python2.7/site-packages/gunicorn/workers/base.py", line 126, in init_process
    self.load_wsgi()
  File "/var/www/projects/myblog/venv/lib/python2.7/site-packages/gunicorn/workers/base.py", line 135, in load_wsgi
    self.wsgi = self.app.wsgi()
  File "/var/www/projects/myblog/venv/lib/python2.7/site-packages/gunicorn/app/base.py", line 67, in wsgi
    self.callable = self.load()
  File "/var/www/projects/myblog/venv/lib/python2.7/site-packages/gunicorn/app/wsgiapp.py", line 65, in load
    return self.load_wsgiapp()
  File "/var/www/projects/myblog/venv/lib/python2.7/site-packages/gunicorn/app/wsgiapp.py", line 52, in load_wsgiapp
    return util.import_app(self.app_uri)
  File "/var/www/projects/myblog/venv/lib/python2.7/site-packages/gunicorn/util.py", line 352, in import_app
    __import__(module)
  File "/var/www/projects/myblog/venv/lib/python2.7/site-packages/gevent/builtins.py", line 93, in __import__
    result = _import(*args, **kwargs)
  File "/var/www/projects/myblog/manage.py", line 15, in <module>
    app = create_app(os.getenv('BLOG_CONFIG') or 'default')
  File "/var/www/projects/myblog/app/__init__.py", line 26, in create_app
    config[config_name].init_app(app)
  File "/var/www/projects/myblog/config.py", line 60, in init_app
    if gettattr(cls, 'MAIL_USE_TLS', None):
NameError: global name 'gettattr' is not defined
[2017-09-29 15:29:59 +0000] [18379] [INFO] Worker exiting (pid: 18379)
[2017-09-29 15:29:59 +0000] [18373] [INFO] Shutting down: Master
[2017-09-29 15:29:59 +0000] [18373] [INFO] Reason: Worker failed to boot.
[2017-09-29 15:30:01 +0000] [18388] [DEBUG] Current configuration:
  proxy_protocol: False
  worker_connections: 1000
  statsd_host: None
  max_requests_jitter: 0
  post_fork: <function post_fork at 0x1395410>
  errorlog: -
  enable_stdio_inheritance: False
  worker_class: gevent
  ssl_version: 2
  suppress_ragged_eofs: True
  syslog: False
  syslog_facility: user
  when_ready: <function when_ready at 0x1395140>
  pre_fork: <function pre_fork at 0x13952a8>
  cert_reqs: 0
  preload_app: False
  keepalive: 2
  accesslog: None
  group: 0
  graceful_timeout: 30
  do_handshake_on_connect: False
  spew: False
  workers: 2
  proc_name: gunicorn.pid
  sendfile: None
  pidfile: /var/log/gunicorn/debug.log
  umask: 0
  on_reload: <function on_reload at 0x1361f50>
  pre_exec: <function pre_exec at 0x13959b0>
  worker_tmp_dir: None
  limit_request_fields: 100
  pythonpath: None
  on_exit: <function on_exit at 0x1397230>
  config: /var/www/projects/myblog/deploy_config.py
  logconfig: None
  check_config: False
  statsd_prefix: 
  secure_scheme_headers: {'X-FORWARDED-PROTOCOL': 'ssl', 'X-FORWARDED-PROTO': 'https', 'X-FORWARDED-SSL': 'on'}
  reload_engine: auto
  proxy_allow_ips: ['127.0.0.1']
  pre_request: <function pre_request at 0x1395b18>
  post_request: <function post_request at 0x1395c08>
  forwarded_allow_ips: ['127.0.0.1']
  worker_int: <function worker_int at 0x13956e0>
  raw_paste_global_conf: []
  threads: 1
  max_requests: 0
  chdir: /var/www/projects/myblog
  daemon: False
  user: 0
  limit_request_line: 4094
  access_log_format: %(h)s %(l)s %(u)s %(t)s "%(r)s" %(s)s %(b)s "%(f)s" "%(a)s"
  certfile: None
  on_starting: <function on_starting at 0x1361de8>
  post_worker_init: <function post_worker_init at 0x1395578>
  child_exit: <function child_exit at 0x1395d70>
  worker_exit: <function worker_exit at 0x1395ed8>
  paste: None
  default_proc_name: manage:app
  syslog_addr: udp://localhost:514
  syslog_prefix: None
  ciphers: TLSv1
  worker_abort: <function worker_abort at 0x1395848>
  loglevel: debug
  bind: ['127.0.0.1:8080']
  raw_env: []
  initgroups: False
  capture_output: False
  reload: False
  limit_request_field_size: 8190
  nworkers_changed: <function nworkers_changed at 0x13970c8>
  timeout: 30
  keyfile: None
  ca_certs: None
  tmp_upload_dir: None
  backlog: 2048
  logger_class: gunicorn.glogging.Logger
[2017-09-29 15:30:01 +0000] [18388] [INFO] Starting gunicorn 19.7.1
[2017-09-29 15:30:01 +0000] [18388] [DEBUG] Arbiter booted
[2017-09-29 15:30:01 +0000] [18388] [INFO] Listening at: http://127.0.0.1:8080 (18388)
[2017-09-29 15:30:01 +0000] [18388] [INFO] Using worker: gevent
[2017-09-29 15:30:01 +0000] [18393] [INFO] Booting worker with pid: 18393
[2017-09-29 15:30:01 +0000] [18394] [INFO] Booting worker with pid: 18394
[2017-09-29 15:30:01 +0000] [18388] [DEBUG] 2 workers
[2017-09-29 15:30:05 +0000] [18393] [ERROR] Exception in worker process
Traceback (most recent call last):
  File "/var/www/projects/myblog/venv/lib/python2.7/site-packages/gunicorn/arbiter.py", line 578, in spawn_worker
    worker.init_process()
  File "/var/www/projects/myblog/venv/lib/python2.7/site-packages/gunicorn/workers/ggevent.py", line 190, in init_process
    super(GeventWorker, self).init_process()
  File "/var/www/projects/myblog/venv/lib/python2.7/site-packages/gunicorn/workers/base.py", line 126, in init_process
    self.load_wsgi()
  File "/var/www/projects/myblog/venv/lib/python2.7/site-packages/gunicorn/workers/base.py", line 135, in load_wsgi
    self.wsgi = self.app.wsgi()
  File "/var/www/projects/myblog/venv/lib/python2.7/site-packages/gunicorn/app/base.py", line 67, in wsgi
    self.callable = self.load()
  File "/var/www/projects/myblog/venv/lib/python2.7/site-packages/gunicorn/app/wsgiapp.py", line 65, in load
    return self.load_wsgiapp()
  File "/var/www/projects/myblog/venv/lib/python2.7/site-packages/gunicorn/app/wsgiapp.py", line 52, in load_wsgiapp
    return util.import_app(self.app_uri)
  File "/var/www/projects/myblog/venv/lib/python2.7/site-packages/gunicorn/util.py", line 352, in import_app
    __import__(module)
  File "/var/www/projects/myblog/venv/lib/python2.7/site-packages/gevent/builtins.py", line 93, in __import__
    result = _import(*args, **kwargs)
  File "/var/www/projects/myblog/manage.py", line 15, in <module>
    app = create_app(os.getenv('BLOG_CONFIG') or 'default')
  File "/var/www/projects/myblog/app/__init__.py", line 26, in create_app
    config[config_name].init_app(app)
  File "/var/www/projects/myblog/config.py", line 60, in init_app
    if gettattr(cls, 'MAIL_USE_TLS', None):
NameError: global name 'gettattr' is not defined
[2017-09-29 15:30:05 +0000] [18393] [INFO] Worker exiting (pid: 18393)
[2017-09-29 15:30:05 +0000] [18394] [ERROR] Exception in worker process
Traceback (most recent call last):
  File "/var/www/projects/myblog/venv/lib/python2.7/site-packages/gunicorn/arbiter.py", line 578, in spawn_worker
    worker.init_process()
  File "/var/www/projects/myblog/venv/lib/python2.7/site-packages/gunicorn/workers/ggevent.py", line 190, in init_process
    super(GeventWorker, self).init_process()
  File "/var/www/projects/myblog/venv/lib/python2.7/site-packages/gunicorn/workers/base.py", line 126, in init_process
    self.load_wsgi()
  File "/var/www/projects/myblog/venv/lib/python2.7/site-packages/gunicorn/workers/base.py", line 135, in load_wsgi
    self.wsgi = self.app.wsgi()
  File "/var/www/projects/myblog/venv/lib/python2.7/site-packages/gunicorn/app/base.py", line 67, in wsgi
    self.callable = self.load()
  File "/var/www/projects/myblog/venv/lib/python2.7/site-packages/gunicorn/app/wsgiapp.py", line 65, in load
    return self.load_wsgiapp()
  File "/var/www/projects/myblog/venv/lib/python2.7/site-packages/gunicorn/app/wsgiapp.py", line 52, in load_wsgiapp
    return util.import_app(self.app_uri)
  File "/var/www/projects/myblog/venv/lib/python2.7/site-packages/gunicorn/util.py", line 352, in import_app
    __import__(module)
  File "/var/www/projects/myblog/venv/lib/python2.7/site-packages/gevent/builtins.py", line 93, in __import__
    result = _import(*args, **kwargs)
  File "/var/www/projects/myblog/manage.py", line 15, in <module>
    app = create_app(os.getenv('BLOG_CONFIG') or 'default')
  File "/var/www/projects/myblog/app/__init__.py", line 26, in create_app
    config[config_name].init_app(app)
  File "/var/www/projects/myblog/config.py", line 60, in init_app
    if gettattr(cls, 'MAIL_USE_TLS', None):
NameError: global name 'gettattr' is not defined
[2017-09-29 15:30:05 +0000] [18394] [INFO] Worker exiting (pid: 18394)
[2017-09-29 15:30:05 +0000] [18388] [INFO] Shutting down: Master
[2017-09-29 15:30:05 +0000] [18388] [INFO] Reason: Worker failed to boot.
[2017-09-29 15:30:08 +0000] [18403] [DEBUG] Current configuration:
  proxy_protocol: False
  worker_connections: 1000
  statsd_host: None
  max_requests_jitter: 0
  post_fork: <function post_fork at 0x2c1c410>
  errorlog: -
  enable_stdio_inheritance: False
  worker_class: gevent
  ssl_version: 2
  suppress_ragged_eofs: True
  syslog: False
  syslog_facility: user
  when_ready: <function when_ready at 0x2c1c140>
  pre_fork: <function pre_fork at 0x2c1c2a8>
  cert_reqs: 0
  preload_app: False
  keepalive: 2
  accesslog: None
  group: 0
  graceful_timeout: 30
  do_handshake_on_connect: False
  spew: False
  workers: 2
  proc_name: gunicorn.pid
  sendfile: None
  pidfile: /var/log/gunicorn/debug.log
  umask: 0
  on_reload: <function on_reload at 0x2be9f50>
  pre_exec: <function pre_exec at 0x2c1c9b0>
  worker_tmp_dir: None
  limit_request_fields: 100
  pythonpath: None
  on_exit: <function on_exit at 0x2c1e230>
  config: /var/www/projects/myblog/deploy_config.py
  logconfig: None
  check_config: False
  statsd_prefix: 
  secure_scheme_headers: {'X-FORWARDED-PROTOCOL': 'ssl', 'X-FORWARDED-PROTO': 'https', 'X-FORWARDED-SSL': 'on'}
  reload_engine: auto
  proxy_allow_ips: ['127.0.0.1']
  pre_request: <function pre_request at 0x2c1cb18>
  post_request: <function post_request at 0x2c1cc08>
  forwarded_allow_ips: ['127.0.0.1']
  worker_int: <function worker_int at 0x2c1c6e0>
  raw_paste_global_conf: []
  threads: 1
  max_requests: 0
  chdir: /var/www/projects/myblog
  daemon: False
  user: 0
  limit_request_line: 4094
  access_log_format: %(h)s %(l)s %(u)s %(t)s "%(r)s" %(s)s %(b)s "%(f)s" "%(a)s"
  certfile: None
  on_starting: <function on_starting at 0x2be9de8>
  post_worker_init: <function post_worker_init at 0x2c1c578>
  child_exit: <function child_exit at 0x2c1cd70>
  worker_exit: <function worker_exit at 0x2c1ced8>
  paste: None
  default_proc_name: manage:app
  syslog_addr: udp://localhost:514
  syslog_prefix: None
  ciphers: TLSv1
  worker_abort: <function worker_abort at 0x2c1c848>
  loglevel: debug
  bind: ['127.0.0.1:8080']
  raw_env: []
  initgroups: False
  capture_output: False
  reload: False
  limit_request_field_size: 8190
  nworkers_changed: <function nworkers_changed at 0x2c1e0c8>
  timeout: 30
  keyfile: None
  ca_certs: None
  tmp_upload_dir: None
  backlog: 2048
  logger_class: gunicorn.glogging.Logger
[2017-09-29 15:30:08 +0000] [18403] [INFO] Starting gunicorn 19.7.1
[2017-09-29 15:30:08 +0000] [18403] [DEBUG] Arbiter booted
[2017-09-29 15:30:08 +0000] [18403] [INFO] Listening at: http://127.0.0.1:8080 (18403)
[2017-09-29 15:30:08 +0000] [18403] [INFO] Using worker: gevent
[2017-09-29 15:30:08 +0000] [18408] [INFO] Booting worker with pid: 18408
[2017-09-29 15:30:08 +0000] [18409] [INFO] Booting worker with pid: 18409
[2017-09-29 15:30:08 +0000] [18403] [DEBUG] 2 workers
[2017-09-29 15:30:12 +0000] [18408] [ERROR] Exception in worker process
Traceback (most recent call last):
  File "/var/www/projects/myblog/venv/lib/python2.7/site-packages/gunicorn/arbiter.py", line 578, in spawn_worker
    worker.init_process()
  File "/var/www/projects/myblog/venv/lib/python2.7/site-packages/gunicorn/workers/ggevent.py", line 190, in init_process
    super(GeventWorker, self).init_process()
  File "/var/www/projects/myblog/venv/lib/python2.7/site-packages/gunicorn/workers/base.py", line 126, in init_process
    self.load_wsgi()
  File "/var/www/projects/myblog/venv/lib/python2.7/site-packages/gunicorn/workers/base.py", line 135, in load_wsgi
    self.wsgi = self.app.wsgi()
  File "/var/www/projects/myblog/venv/lib/python2.7/site-packages/gunicorn/app/base.py", line 67, in wsgi
    self.callable = self.load()
  File "/var/www/projects/myblog/venv/lib/python2.7/site-packages/gunicorn/app/wsgiapp.py", line 65, in load
    return self.load_wsgiapp()
  File "/var/www/projects/myblog/venv/lib/python2.7/site-packages/gunicorn/app/wsgiapp.py", line 52, in load_wsgiapp
    return util.import_app(self.app_uri)
  File "/var/www/projects/myblog/venv/lib/python2.7/site-packages/gunicorn/util.py", line 352, in import_app
    __import__(module)
  File "/var/www/projects/myblog/venv/lib/python2.7/site-packages/gevent/builtins.py", line 93, in __import__
    result = _import(*args, **kwargs)
  File "/var/www/projects/myblog/manage.py", line 15, in <module>
    app = create_app(os.getenv('BLOG_CONFIG') or 'default')
  File "/var/www/projects/myblog/app/__init__.py", line 26, in create_app
    config[config_name].init_app(app)
  File "/var/www/projects/myblog/config.py", line 60, in init_app
    if gettattr(cls, 'MAIL_USE_TLS', None):
NameError: global name 'gettattr' is not defined
[2017-09-29 15:30:12 +0000] [18408] [INFO] Worker exiting (pid: 18408)
[2017-09-29 15:30:12 +0000] [18409] [ERROR] Exception in worker process
Traceback (most recent call last):
  File "/var/www/projects/myblog/venv/lib/python2.7/site-packages/gunicorn/arbiter.py", line 578, in spawn_worker
    worker.init_process()
  File "/var/www/projects/myblog/venv/lib/python2.7/site-packages/gunicorn/workers/ggevent.py", line 190, in init_process
    super(GeventWorker, self).init_process()
  File "/var/www/projects/myblog/venv/lib/python2.7/site-packages/gunicorn/workers/base.py", line 126, in init_process
    self.load_wsgi()
  File "/var/www/projects/myblog/venv/lib/python2.7/site-packages/gunicorn/workers/base.py", line 135, in load_wsgi
    self.wsgi = self.app.wsgi()
  File "/var/www/projects/myblog/venv/lib/python2.7/site-packages/gunicorn/app/base.py", line 67, in wsgi
    self.callable = self.load()
  File "/var/www/projects/myblog/venv/lib/python2.7/site-packages/gunicorn/app/wsgiapp.py", line 65, in load
    return self.load_wsgiapp()
  File "/var/www/projects/myblog/venv/lib/python2.7/site-packages/gunicorn/app/wsgiapp.py", line 52, in load_wsgiapp
    return util.import_app(self.app_uri)
  File "/var/www/projects/myblog/venv/lib/python2.7/site-packages/gunicorn/util.py", line 352, in import_app
    __import__(module)
  File "/var/www/projects/myblog/venv/lib/python2.7/site-packages/gevent/builtins.py", line 93, in __import__
    result = _import(*args, **kwargs)
  File "/var/www/projects/myblog/manage.py", line 15, in <module>
    app = create_app(os.getenv('BLOG_CONFIG') or 'default')
  File "/var/www/projects/myblog/app/__init__.py", line 26, in create_app
    config[config_name].init_app(app)
  File "/var/www/projects/myblog/config.py", line 60, in init_app
    if gettattr(cls, 'MAIL_USE_TLS', None):
NameError: global name 'gettattr' is not defined
[2017-09-29 15:30:12 +0000] [18409] [INFO] Worker exiting (pid: 18409)
Traceback (most recent call last):
  File "/var/www/projects/myblog/venv/bin/gunicorn", line 11, in <module>
    sys.exit(run())
  File "/var/www/projects/myblog/venv/lib/python2.7/site-packages/gunicorn/app/wsgiapp.py", line 74, in run
    WSGIApplication("%(prog)s [OPTIONS] [APP_MODULE]").run()
  File "/var/www/projects/myblog/venv/lib/python2.7/site-packages/gunicorn/app/base.py", line 203, in run
    super(Application, self).run()
  File "/var/www/projects/myblog/venv/lib/python2.7/site-packages/gunicorn/app/base.py", line 72, in run
    Arbiter(self).run()
  File "/var/www/projects/myblog/venv/lib/python2.7/site-packages/gunicorn/arbiter.py", line 231, in run
    self.halt(reason=inst.reason, exit_status=inst.exit_status)
  File "/var/www/projects/myblog/venv/lib/python2.7/site-packages/gunicorn/arbiter.py", line 344, in halt
    self.stop()
  File "/var/www/projects/myblog/venv/lib/python2.7/site-packages/gunicorn/arbiter.py", line 393, in stop
    time.sleep(0.1)
  File "/var/www/projects/myblog/venv/lib/python2.7/site-packages/gunicorn/arbiter.py", line 244, in handle_chld
    self.reap_workers()
  File "/var/www/projects/myblog/venv/lib/python2.7/site-packages/gunicorn/arbiter.py", line 524, in reap_workers
    raise HaltServer(reason, self.WORKER_BOOT_ERROR)
gunicorn.errors.HaltServer: <HaltServer 'Worker failed to boot.' 3>
[2017-09-29 15:30:14 +0000] [18418] [DEBUG] Current configuration:
  proxy_protocol: False
  worker_connections: 1000
  statsd_host: None
  max_requests_jitter: 0
  post_fork: <function post_fork at 0x20e4410>
  errorlog: -
  enable_stdio_inheritance: False
  worker_class: gevent
  ssl_version: 2
  suppress_ragged_eofs: True
  syslog: False
  syslog_facility: user
  when_ready: <function when_ready at 0x20e4140>
  pre_fork: <function pre_fork at 0x20e42a8>
  cert_reqs: 0
  preload_app: False
  keepalive: 2
  accesslog: None
  group: 0
  graceful_timeout: 30
  do_handshake_on_connect: False
  spew: False
  workers: 2
  proc_name: gunicorn.pid
  sendfile: None
  pidfile: /var/log/gunicorn/debug.log
  umask: 0
  on_reload: <function on_reload at 0x20b1f50>
  pre_exec: <function pre_exec at 0x20e49b0>
  worker_tmp_dir: None
  limit_request_fields: 100
  pythonpath: None
  on_exit: <function on_exit at 0x20e6230>
  config: /var/www/projects/myblog/deploy_config.py
  logconfig: None
  check_config: False
  statsd_prefix: 
  secure_scheme_headers: {'X-FORWARDED-PROTOCOL': 'ssl', 'X-FORWARDED-PROTO': 'https', 'X-FORWARDED-SSL': 'on'}
  reload_engine: auto
  proxy_allow_ips: ['127.0.0.1']
  pre_request: <function pre_request at 0x20e4b18>
  post_request: <function post_request at 0x20e4c08>
  forwarded_allow_ips: ['127.0.0.1']
  worker_int: <function worker_int at 0x20e46e0>
  raw_paste_global_conf: []
  threads: 1
  max_requests: 0
  chdir: /var/www/projects/myblog
  daemon: False
  user: 0
  limit_request_line: 4094
  access_log_format: %(h)s %(l)s %(u)s %(t)s "%(r)s" %(s)s %(b)s "%(f)s" "%(a)s"
  certfile: None
  on_starting: <function on_starting at 0x20b1de8>
  post_worker_init: <function post_worker_init at 0x20e4578>
  child_exit: <function child_exit at 0x20e4d70>
  worker_exit: <function worker_exit at 0x20e4ed8>
  paste: None
  default_proc_name: manage:app
  syslog_addr: udp://localhost:514
  syslog_prefix: None
  ciphers: TLSv1
  worker_abort: <function worker_abort at 0x20e4848>
  loglevel: debug
  bind: ['127.0.0.1:8080']
  raw_env: []
  initgroups: False
  capture_output: False
  reload: False
  limit_request_field_size: 8190
  nworkers_changed: <function nworkers_changed at 0x20e60c8>
  timeout: 30
  keyfile: None
  ca_certs: None
  tmp_upload_dir: None
  backlog: 2048
  logger_class: gunicorn.glogging.Logger
[2017-09-29 15:30:14 +0000] [18418] [INFO] Starting gunicorn 19.7.1
[2017-09-29 15:30:14 +0000] [18418] [DEBUG] Arbiter booted
[2017-09-29 15:30:14 +0000] [18418] [INFO] Listening at: http://127.0.0.1:8080 (18418)
[2017-09-29 15:30:14 +0000] [18418] [INFO] Using worker: gevent
[2017-09-29 15:30:14 +0000] [18423] [INFO] Booting worker with pid: 18423
[2017-09-29 15:30:14 +0000] [18424] [INFO] Booting worker with pid: 18424
[2017-09-29 15:30:14 +0000] [18418] [DEBUG] 2 workers
[2017-09-29 15:30:19 +0000] [18423] [ERROR] Exception in worker process
Traceback (most recent call last):
  File "/var/www/projects/myblog/venv/lib/python2.7/site-packages/gunicorn/arbiter.py", line 578, in spawn_worker
    worker.init_process()
  File "/var/www/projects/myblog/venv/lib/python2.7/site-packages/gunicorn/workers/ggevent.py", line 190, in init_process
    super(GeventWorker, self).init_process()
  File "/var/www/projects/myblog/venv/lib/python2.7/site-packages/gunicorn/workers/base.py", line 126, in init_process
    self.load_wsgi()
  File "/var/www/projects/myblog/venv/lib/python2.7/site-packages/gunicorn/workers/base.py", line 135, in load_wsgi
    self.wsgi = self.app.wsgi()
  File "/var/www/projects/myblog/venv/lib/python2.7/site-packages/gunicorn/app/base.py", line 67, in wsgi
    self.callable = self.load()
  File "/var/www/projects/myblog/venv/lib/python2.7/site-packages/gunicorn/app/wsgiapp.py", line 65, in load
    return self.load_wsgiapp()
  File "/var/www/projects/myblog/venv/lib/python2.7/site-packages/gunicorn/app/wsgiapp.py", line 52, in load_wsgiapp
    return util.import_app(self.app_uri)
  File "/var/www/projects/myblog/venv/lib/python2.7/site-packages/gunicorn/util.py", line 352, in import_app
    __import__(module)
  File "/var/www/projects/myblog/venv/lib/python2.7/site-packages/gevent/builtins.py", line 93, in __import__
    result = _import(*args, **kwargs)
  File "/var/www/projects/myblog/manage.py", line 15, in <module>
    app = create_app(os.getenv('BLOG_CONFIG') or 'default')
  File "/var/www/projects/myblog/app/__init__.py", line 26, in create_app
    config[config_name].init_app(app)
  File "/var/www/projects/myblog/config.py", line 60, in init_app
    if gettattr(cls, 'MAIL_USE_TLS', None):
NameError: global name 'gettattr' is not defined
[2017-09-29 15:30:19 +0000] [18423] [INFO] Worker exiting (pid: 18423)
[2017-09-29 15:30:19 +0000] [18424] [ERROR] Exception in worker process
Traceback (most recent call last):
  File "/var/www/projects/myblog/venv/lib/python2.7/site-packages/gunicorn/arbiter.py", line 578, in spawn_worker
    worker.init_process()
  File "/var/www/projects/myblog/venv/lib/python2.7/site-packages/gunicorn/workers/ggevent.py", line 190, in init_process
    super(GeventWorker, self).init_process()
  File "/var/www/projects/myblog/venv/lib/python2.7/site-packages/gunicorn/workers/base.py", line 126, in init_process
    self.load_wsgi()
  File "/var/www/projects/myblog/venv/lib/python2.7/site-packages/gunicorn/workers/base.py", line 135, in load_wsgi
    self.wsgi = self.app.wsgi()
  File "/var/www/projects/myblog/venv/lib/python2.7/site-packages/gunicorn/app/base.py", line 67, in wsgi
    self.callable = self.load()
  File "/var/www/projects/myblog/venv/lib/python2.7/site-packages/gunicorn/app/wsgiapp.py", line 65, in load
    return self.load_wsgiapp()
  File "/var/www/projects/myblog/venv/lib/python2.7/site-packages/gunicorn/app/wsgiapp.py", line 52, in load_wsgiapp
    return util.import_app(self.app_uri)
  File "/var/www/projects/myblog/venv/lib/python2.7/site-packages/gunicorn/util.py", line 352, in import_app
    __import__(module)
  File "/var/www/projects/myblog/venv/lib/python2.7/site-packages/gevent/builtins.py", line 93, in __import__
    result = _import(*args, **kwargs)
  File "/var/www/projects/myblog/manage.py", line 15, in <module>
    app = create_app(os.getenv('BLOG_CONFIG') or 'default')
  File "/var/www/projects/myblog/app/__init__.py", line 26, in create_app
    config[config_name].init_app(app)
  File "/var/www/projects/myblog/config.py", line 60, in init_app
    if gettattr(cls, 'MAIL_USE_TLS', None):
NameError: global name 'gettattr' is not defined
[2017-09-29 15:30:19 +0000] [18424] [INFO] Worker exiting (pid: 18424)
[2017-09-29 15:30:19 +0000] [18418] [INFO] Shutting down: Master
[2017-09-29 15:30:19 +0000] [18418] [INFO] Reason: Worker failed to boot.
[2017-09-29 15:30:20 +0000] [18433] [DEBUG] Current configuration:
  proxy_protocol: False
  worker_connections: 1000
  statsd_host: None
  max_requests_jitter: 0
  post_fork: <function post_fork at 0x2a56410>
  errorlog: -
  enable_stdio_inheritance: False
  worker_class: gevent
  ssl_version: 2
  suppress_ragged_eofs: True
  syslog: False
  syslog_facility: user
  when_ready: <function when_ready at 0x2a56140>
  pre_fork: <function pre_fork at 0x2a562a8>
  cert_reqs: 0
  preload_app: False
  keepalive: 2
  accesslog: None
  group: 0
  graceful_timeout: 30
  do_handshake_on_connect: False
  spew: False
  workers: 2
  proc_name: gunicorn.pid
  sendfile: None
  pidfile: /var/log/gunicorn/debug.log
  umask: 0
  on_reload: <function on_reload at 0x2a22f50>
  pre_exec: <function pre_exec at 0x2a569b0>
  worker_tmp_dir: None
  limit_request_fields: 100
  pythonpath: None
  on_exit: <function on_exit at 0x2a58230>
  config: /var/www/projects/myblog/deploy_config.py
  logconfig: None
  check_config: False
  statsd_prefix: 
  secure_scheme_headers: {'X-FORWARDED-PROTOCOL': 'ssl', 'X-FORWARDED-PROTO': 'https', 'X-FORWARDED-SSL': 'on'}
  reload_engine: auto
  proxy_allow_ips: ['127.0.0.1']
  pre_request: <function pre_request at 0x2a56b18>
  post_request: <function post_request at 0x2a56c08>
  forwarded_allow_ips: ['127.0.0.1']
  worker_int: <function worker_int at 0x2a566e0>
  raw_paste_global_conf: []
  threads: 1
  max_requests: 0
  chdir: /var/www/projects/myblog
  daemon: False
  user: 0
  limit_request_line: 4094
  access_log_format: %(h)s %(l)s %(u)s %(t)s "%(r)s" %(s)s %(b)s "%(f)s" "%(a)s"
  certfile: None
  on_starting: <function on_starting at 0x2a22de8>
  post_worker_init: <function post_worker_init at 0x2a56578>
  child_exit: <function child_exit at 0x2a56d70>
  worker_exit: <function worker_exit at 0x2a56ed8>
  paste: None
  default_proc_name: manage:app
  syslog_addr: udp://localhost:514
  syslog_prefix: None
  ciphers: TLSv1
  worker_abort: <function worker_abort at 0x2a56848>
  loglevel: debug
  bind: ['127.0.0.1:8080']
  raw_env: []
  initgroups: False
  capture_output: False
  reload: False
  limit_request_field_size: 8190
  nworkers_changed: <function nworkers_changed at 0x2a580c8>
  timeout: 30
  keyfile: None
  ca_certs: None
  tmp_upload_dir: None
  backlog: 2048
  logger_class: gunicorn.glogging.Logger
[2017-09-29 15:30:20 +0000] [18433] [INFO] Starting gunicorn 19.7.1
[2017-09-29 15:30:20 +0000] [18433] [DEBUG] Arbiter booted
[2017-09-29 15:30:20 +0000] [18433] [INFO] Listening at: http://127.0.0.1:8080 (18433)
[2017-09-29 15:30:20 +0000] [18433] [INFO] Using worker: gevent
[2017-09-29 15:30:20 +0000] [18438] [INFO] Booting worker with pid: 18438
[2017-09-29 15:30:21 +0000] [18439] [INFO] Booting worker with pid: 18439
[2017-09-29 15:30:21 +0000] [18433] [DEBUG] 2 workers
[2017-09-29 15:30:24 +0000] [18438] [ERROR] Exception in worker process
Traceback (most recent call last):
  File "/var/www/projects/myblog/venv/lib/python2.7/site-packages/gunicorn/arbiter.py", line 578, in spawn_worker
    worker.init_process()
  File "/var/www/projects/myblog/venv/lib/python2.7/site-packages/gunicorn/workers/ggevent.py", line 190, in init_process
    super(GeventWorker, self).init_process()
  File "/var/www/projects/myblog/venv/lib/python2.7/site-packages/gunicorn/workers/base.py", line 126, in init_process
    self.load_wsgi()
  File "/var/www/projects/myblog/venv/lib/python2.7/site-packages/gunicorn/workers/base.py", line 135, in load_wsgi
    self.wsgi = self.app.wsgi()
  File "/var/www/projects/myblog/venv/lib/python2.7/site-packages/gunicorn/app/base.py", line 67, in wsgi
    self.callable = self.load()
  File "/var/www/projects/myblog/venv/lib/python2.7/site-packages/gunicorn/app/wsgiapp.py", line 65, in load
    return self.load_wsgiapp()
  File "/var/www/projects/myblog/venv/lib/python2.7/site-packages/gunicorn/app/wsgiapp.py", line 52, in load_wsgiapp
    return util.import_app(self.app_uri)
  File "/var/www/projects/myblog/venv/lib/python2.7/site-packages/gunicorn/util.py", line 352, in import_app
    __import__(module)
  File "/var/www/projects/myblog/venv/lib/python2.7/site-packages/gevent/builtins.py", line 93, in __import__
    result = _import(*args, **kwargs)
  File "/var/www/projects/myblog/manage.py", line 15, in <module>
    app = create_app(os.getenv('BLOG_CONFIG') or 'default')
  File "/var/www/projects/myblog/app/__init__.py", line 26, in create_app
    config[config_name].init_app(app)
  File "/var/www/projects/myblog/config.py", line 60, in init_app
    if gettattr(cls, 'MAIL_USE_TLS', None):
NameError: global name 'gettattr' is not defined
[2017-09-29 15:30:24 +0000] [18438] [INFO] Worker exiting (pid: 18438)
[2017-09-29 15:30:24 +0000] [18439] [ERROR] Exception in worker process
Traceback (most recent call last):
  File "/var/www/projects/myblog/venv/lib/python2.7/site-packages/gunicorn/arbiter.py", line 578, in spawn_worker
    worker.init_process()
  File "/var/www/projects/myblog/venv/lib/python2.7/site-packages/gunicorn/workers/ggevent.py", line 190, in init_process
    super(GeventWorker, self).init_process()
  File "/var/www/projects/myblog/venv/lib/python2.7/site-packages/gunicorn/workers/base.py", line 126, in init_process
    self.load_wsgi()
  File "/var/www/projects/myblog/venv/lib/python2.7/site-packages/gunicorn/workers/base.py", line 135, in load_wsgi
    self.wsgi = self.app.wsgi()
  File "/var/www/projects/myblog/venv/lib/python2.7/site-packages/gunicorn/app/base.py", line 67, in wsgi
    self.callable = self.load()
  File "/var/www/projects/myblog/venv/lib/python2.7/site-packages/gunicorn/app/wsgiapp.py", line 65, in load
    return self.load_wsgiapp()
  File "/var/www/projects/myblog/venv/lib/python2.7/site-packages/gunicorn/app/wsgiapp.py", line 52, in load_wsgiapp
    return util.import_app(self.app_uri)
  File "/var/www/projects/myblog/venv/lib/python2.7/site-packages/gunicorn/util.py", line 352, in import_app
    __import__(module)
  File "/var/www/projects/myblog/venv/lib/python2.7/site-packages/gevent/builtins.py", line 93, in __import__
    result = _import(*args, **kwargs)
  File "/var/www/projects/myblog/manage.py", line 15, in <module>
    app = create_app(os.getenv('BLOG_CONFIG') or 'default')
  File "/var/www/projects/myblog/app/__init__.py", line 26, in create_app
    config[config_name].init_app(app)
  File "/var/www/projects/myblog/config.py", line 60, in init_app
    if gettattr(cls, 'MAIL_USE_TLS', None):
NameError: global name 'gettattr' is not defined
[2017-09-29 15:30:24 +0000] [18439] [INFO] Worker exiting (pid: 18439)
Traceback (most recent call last):
  File "/var/www/projects/myblog/venv/bin/gunicorn", line 11, in <module>
    sys.exit(run())
  File "/var/www/projects/myblog/venv/lib/python2.7/site-packages/gunicorn/app/wsgiapp.py", line 74, in run
    WSGIApplication("%(prog)s [OPTIONS] [APP_MODULE]").run()
  File "/var/www/projects/myblog/venv/lib/python2.7/site-packages/gunicorn/app/base.py", line 203, in run
    super(Application, self).run()
  File "/var/www/projects/myblog/venv/lib/python2.7/site-packages/gunicorn/app/base.py", line 72, in run
    Arbiter(self).run()
  File "/var/www/projects/myblog/venv/lib/python2.7/site-packages/gunicorn/arbiter.py", line 231, in run
    self.halt(reason=inst.reason, exit_status=inst.exit_status)
  File "/var/www/projects/myblog/venv/lib/python2.7/site-packages/gunicorn/arbiter.py", line 344, in halt
    self.stop()
  File "/var/www/projects/myblog/venv/lib/python2.7/site-packages/gunicorn/arbiter.py", line 393, in stop
    time.sleep(0.1)
  File "/var/www/projects/myblog/venv/lib/python2.7/site-packages/gunicorn/arbiter.py", line 244, in handle_chld
    self.reap_workers()
  File "/var/www/projects/myblog/venv/lib/python2.7/site-packages/gunicorn/arbiter.py", line 524, in reap_workers
    raise HaltServer(reason, self.WORKER_BOOT_ERROR)
gunicorn.errors.HaltServer: <HaltServer 'Worker failed to boot.' 3>
[2017-09-29 15:30:26 +0000] [18448] [DEBUG] Current configuration:
  proxy_protocol: False
  worker_connections: 1000
  statsd_host: None
  max_requests_jitter: 0
  post_fork: <function post_fork at 0x1ac5410>
  errorlog: -
  enable_stdio_inheritance: False
  worker_class: gevent
  ssl_version: 2
  suppress_ragged_eofs: True
  syslog: False
  syslog_facility: user
  when_ready: <function when_ready at 0x1ac5140>
  pre_fork: <function pre_fork at 0x1ac52a8>
  cert_reqs: 0
  preload_app: False
  keepalive: 2
  accesslog: None
  group: 0
  graceful_timeout: 30
  do_handshake_on_connect: False
  spew: False
  workers: 2
  proc_name: gunicorn.pid
  sendfile: None
  pidfile: /var/log/gunicorn/debug.log
  umask: 0
  on_reload: <function on_reload at 0x1a91f50>
  pre_exec: <function pre_exec at 0x1ac59b0>
  worker_tmp_dir: None
  limit_request_fields: 100
  pythonpath: None
  on_exit: <function on_exit at 0x1ac7230>
  config: /var/www/projects/myblog/deploy_config.py
  logconfig: None
  check_config: False
  statsd_prefix: 
  secure_scheme_headers: {'X-FORWARDED-PROTOCOL': 'ssl', 'X-FORWARDED-PROTO': 'https', 'X-FORWARDED-SSL': 'on'}
  reload_engine: auto
  proxy_allow_ips: ['127.0.0.1']
  pre_request: <function pre_request at 0x1ac5b18>
  post_request: <function post_request at 0x1ac5c08>
  forwarded_allow_ips: ['127.0.0.1']
  worker_int: <function worker_int at 0x1ac56e0>
  raw_paste_global_conf: []
  threads: 1
  max_requests: 0
  chdir: /var/www/projects/myblog
  daemon: False
  user: 0
  limit_request_line: 4094
  access_log_format: %(h)s %(l)s %(u)s %(t)s "%(r)s" %(s)s %(b)s "%(f)s" "%(a)s"
  certfile: None
  on_starting: <function on_starting at 0x1a91de8>
  post_worker_init: <function post_worker_init at 0x1ac5578>
  child_exit: <function child_exit at 0x1ac5d70>
  worker_exit: <function worker_exit at 0x1ac5ed8>
  paste: None
  default_proc_name: manage:app
  syslog_addr: udp://localhost:514
  syslog_prefix: None
  ciphers: TLSv1
  worker_abort: <function worker_abort at 0x1ac5848>
  loglevel: debug
  bind: ['127.0.0.1:8080']
  raw_env: []
  initgroups: False
  capture_output: False
  reload: False
  limit_request_field_size: 8190
  nworkers_changed: <function nworkers_changed at 0x1ac70c8>
  timeout: 30
  keyfile: None
  ca_certs: None
  tmp_upload_dir: None
  backlog: 2048
  logger_class: gunicorn.glogging.Logger
[2017-09-29 15:30:26 +0000] [18448] [INFO] Starting gunicorn 19.7.1
[2017-09-29 15:30:26 +0000] [18448] [DEBUG] Arbiter booted
[2017-09-29 15:30:26 +0000] [18448] [INFO] Listening at: http://127.0.0.1:8080 (18448)
[2017-09-29 15:30:26 +0000] [18448] [INFO] Using worker: gevent
[2017-09-29 15:30:26 +0000] [18453] [INFO] Booting worker with pid: 18453
[2017-09-29 15:30:26 +0000] [18448] [DEBUG] 2 workers
[2017-09-29 15:30:26 +0000] [18454] [INFO] Booting worker with pid: 18454
[2017-09-29 15:30:31 +0000] [18453] [ERROR] Exception in worker process
Traceback (most recent call last):
  File "/var/www/projects/myblog/venv/lib/python2.7/site-packages/gunicorn/arbiter.py", line 578, in spawn_worker
    worker.init_process()
  File "/var/www/projects/myblog/venv/lib/python2.7/site-packages/gunicorn/workers/ggevent.py", line 190, in init_process
    super(GeventWorker, self).init_process()
  File "/var/www/projects/myblog/venv/lib/python2.7/site-packages/gunicorn/workers/base.py", line 126, in init_process
    self.load_wsgi()
  File "/var/www/projects/myblog/venv/lib/python2.7/site-packages/gunicorn/workers/base.py", line 135, in load_wsgi
    self.wsgi = self.app.wsgi()
  File "/var/www/projects/myblog/venv/lib/python2.7/site-packages/gunicorn/app/base.py", line 67, in wsgi
    self.callable = self.load()
  File "/var/www/projects/myblog/venv/lib/python2.7/site-packages/gunicorn/app/wsgiapp.py", line 65, in load
    return self.load_wsgiapp()
  File "/var/www/projects/myblog/venv/lib/python2.7/site-packages/gunicorn/app/wsgiapp.py", line 52, in load_wsgiapp
    return util.import_app(self.app_uri)
  File "/var/www/projects/myblog/venv/lib/python2.7/site-packages/gunicorn/util.py", line 352, in import_app
    __import__(module)
  File "/var/www/projects/myblog/venv/lib/python2.7/site-packages/gevent/builtins.py", line 93, in __import__
    result = _import(*args, **kwargs)
  File "/var/www/projects/myblog/manage.py", line 15, in <module>
    app = create_app(os.getenv('BLOG_CONFIG') or 'default')
  File "/var/www/projects/myblog/app/__init__.py", line 26, in create_app
    config[config_name].init_app(app)
  File "/var/www/projects/myblog/config.py", line 60, in init_app
    if gettattr(cls, 'MAIL_USE_TLS', None):
NameError: global name 'gettattr' is not defined
[2017-09-29 15:30:31 +0000] [18453] [INFO] Worker exiting (pid: 18453)
[2017-09-29 15:30:31 +0000] [18454] [ERROR] Exception in worker process
Traceback (most recent call last):
  File "/var/www/projects/myblog/venv/lib/python2.7/site-packages/gunicorn/arbiter.py", line 578, in spawn_worker
    worker.init_process()
  File "/var/www/projects/myblog/venv/lib/python2.7/site-packages/gunicorn/workers/ggevent.py", line 190, in init_process
    super(GeventWorker, self).init_process()
  File "/var/www/projects/myblog/venv/lib/python2.7/site-packages/gunicorn/workers/base.py", line 126, in init_process
    self.load_wsgi()
  File "/var/www/projects/myblog/venv/lib/python2.7/site-packages/gunicorn/workers/base.py", line 135, in load_wsgi
    self.wsgi = self.app.wsgi()
  File "/var/www/projects/myblog/venv/lib/python2.7/site-packages/gunicorn/app/base.py", line 67, in wsgi
    self.callable = self.load()
  File "/var/www/projects/myblog/venv/lib/python2.7/site-packages/gunicorn/app/wsgiapp.py", line 65, in load
    return self.load_wsgiapp()
  File "/var/www/projects/myblog/venv/lib/python2.7/site-packages/gunicorn/app/wsgiapp.py", line 52, in load_wsgiapp
    return util.import_app(self.app_uri)
  File "/var/www/projects/myblog/venv/lib/python2.7/site-packages/gunicorn/util.py", line 352, in import_app
    __import__(module)
  File "/var/www/projects/myblog/venv/lib/python2.7/site-packages/gevent/builtins.py", line 93, in __import__
    result = _import(*args, **kwargs)
  File "/var/www/projects/myblog/manage.py", line 15, in <module>
    app = create_app(os.getenv('BLOG_CONFIG') or 'default')
  File "/var/www/projects/myblog/app/__init__.py", line 26, in create_app
    config[config_name].init_app(app)
  File "/var/www/projects/myblog/config.py", line 60, in init_app
    if gettattr(cls, 'MAIL_USE_TLS', None):
NameError: global name 'gettattr' is not defined
[2017-09-29 15:30:31 +0000] [18454] [INFO] Worker exiting (pid: 18454)
[2017-09-29 15:30:31 +0000] [18448] [INFO] Shutting down: Master
[2017-09-29 15:30:31 +0000] [18448] [INFO] Reason: Worker failed to boot.
[2017-09-29 15:30:32 +0000] [18463] [DEBUG] Current configuration:
  proxy_protocol: False
  worker_connections: 1000
  statsd_host: None
  max_requests_jitter: 0
  post_fork: <function post_fork at 0x1f8f410>
  errorlog: -
  enable_stdio_inheritance: False
  worker_class: gevent
  ssl_version: 2
  suppress_ragged_eofs: True
  syslog: False
  syslog_facility: user
  when_ready: <function when_ready at 0x1f8f140>
  pre_fork: <function pre_fork at 0x1f8f2a8>
  cert_reqs: 0
  preload_app: False
  keepalive: 2
  accesslog: None
  group: 0
  graceful_timeout: 30
  do_handshake_on_connect: False
  spew: False
  workers: 2
  proc_name: gunicorn.pid
  sendfile: None
  pidfile: /var/log/gunicorn/debug.log
  umask: 0
  on_reload: <function on_reload at 0x1f5cf50>
  pre_exec: <function pre_exec at 0x1f8f9b0>
  worker_tmp_dir: None
  limit_request_fields: 100
  pythonpath: None
  on_exit: <function on_exit at 0x1f91230>
  config: /var/www/projects/myblog/deploy_config.py
  logconfig: None
  check_config: False
  statsd_prefix: 
  secure_scheme_headers: {'X-FORWARDED-PROTOCOL': 'ssl', 'X-FORWARDED-PROTO': 'https', 'X-FORWARDED-SSL': 'on'}
  reload_engine: auto
  proxy_allow_ips: ['127.0.0.1']
  pre_request: <function pre_request at 0x1f8fb18>
  post_request: <function post_request at 0x1f8fc08>
  forwarded_allow_ips: ['127.0.0.1']
  worker_int: <function worker_int at 0x1f8f6e0>
  raw_paste_global_conf: []
  threads: 1
  max_requests: 0
  chdir: /var/www/projects/myblog
  daemon: False
  user: 0
  limit_request_line: 4094
  access_log_format: %(h)s %(l)s %(u)s %(t)s "%(r)s" %(s)s %(b)s "%(f)s" "%(a)s"
  certfile: None
  on_starting: <function on_starting at 0x1f5cde8>
  post_worker_init: <function post_worker_init at 0x1f8f578>
  child_exit: <function child_exit at 0x1f8fd70>
  worker_exit: <function worker_exit at 0x1f8fed8>
  paste: None
  default_proc_name: manage:app
  syslog_addr: udp://localhost:514
  syslog_prefix: None
  ciphers: TLSv1
  worker_abort: <function worker_abort at 0x1f8f848>
  loglevel: debug
  bind: ['127.0.0.1:8080']
  raw_env: []
  initgroups: False
  capture_output: False
  reload: False
  limit_request_field_size: 8190
  nworkers_changed: <function nworkers_changed at 0x1f910c8>
  timeout: 30
  keyfile: None
  ca_certs: None
  tmp_upload_dir: None
  backlog: 2048
  logger_class: gunicorn.glogging.Logger
[2017-09-29 15:30:32 +0000] [18463] [INFO] Starting gunicorn 19.7.1
[2017-09-29 15:30:32 +0000] [18463] [DEBUG] Arbiter booted
[2017-09-29 15:30:32 +0000] [18463] [INFO] Listening at: http://127.0.0.1:8080 (18463)
[2017-09-29 15:30:32 +0000] [18463] [INFO] Using worker: gevent
[2017-09-29 15:30:32 +0000] [18468] [INFO] Booting worker with pid: 18468
[2017-09-29 15:30:32 +0000] [18469] [INFO] Booting worker with pid: 18469
[2017-09-29 15:30:32 +0000] [18463] [DEBUG] 2 workers
[2017-09-29 15:30:36 +0000] [18468] [ERROR] Exception in worker process
Traceback (most recent call last):
  File "/var/www/projects/myblog/venv/lib/python2.7/site-packages/gunicorn/arbiter.py", line 578, in spawn_worker
    worker.init_process()
  File "/var/www/projects/myblog/venv/lib/python2.7/site-packages/gunicorn/workers/ggevent.py", line 190, in init_process
    super(GeventWorker, self).init_process()
  File "/var/www/projects/myblog/venv/lib/python2.7/site-packages/gunicorn/workers/base.py", line 126, in init_process
    self.load_wsgi()
  File "/var/www/projects/myblog/venv/lib/python2.7/site-packages/gunicorn/workers/base.py", line 135, in load_wsgi
    self.wsgi = self.app.wsgi()
  File "/var/www/projects/myblog/venv/lib/python2.7/site-packages/gunicorn/app/base.py", line 67, in wsgi
    self.callable = self.load()
  File "/var/www/projects/myblog/venv/lib/python2.7/site-packages/gunicorn/app/wsgiapp.py", line 65, in load
    return self.load_wsgiapp()
  File "/var/www/projects/myblog/venv/lib/python2.7/site-packages/gunicorn/app/wsgiapp.py", line 52, in load_wsgiapp
    return util.import_app(self.app_uri)
  File "/var/www/projects/myblog/venv/lib/python2.7/site-packages/gunicorn/util.py", line 352, in import_app
    __import__(module)
  File "/var/www/projects/myblog/venv/lib/python2.7/site-packages/gevent/builtins.py", line 93, in __import__
    result = _import(*args, **kwargs)
  File "/var/www/projects/myblog/manage.py", line 15, in <module>
    app = create_app(os.getenv('BLOG_CONFIG') or 'default')
  File "/var/www/projects/myblog/app/__init__.py", line 26, in create_app
    config[config_name].init_app(app)
  File "/var/www/projects/myblog/config.py", line 60, in init_app
    if gettattr(cls, 'MAIL_USE_TLS', None):
NameError: global name 'gettattr' is not defined
[2017-09-29 15:30:36 +0000] [18468] [INFO] Worker exiting (pid: 18468)
[2017-09-29 15:30:37 +0000] [18469] [ERROR] Exception in worker process
Traceback (most recent call last):
  File "/var/www/projects/myblog/venv/lib/python2.7/site-packages/gunicorn/arbiter.py", line 578, in spawn_worker
    worker.init_process()
  File "/var/www/projects/myblog/venv/lib/python2.7/site-packages/gunicorn/workers/ggevent.py", line 190, in init_process
    super(GeventWorker, self).init_process()
  File "/var/www/projects/myblog/venv/lib/python2.7/site-packages/gunicorn/workers/base.py", line 126, in init_process
    self.load_wsgi()
  File "/var/www/projects/myblog/venv/lib/python2.7/site-packages/gunicorn/workers/base.py", line 135, in load_wsgi
    self.wsgi = self.app.wsgi()
  File "/var/www/projects/myblog/venv/lib/python2.7/site-packages/gunicorn/app/base.py", line 67, in wsgi
    self.callable = self.load()
  File "/var/www/projects/myblog/venv/lib/python2.7/site-packages/gunicorn/app/wsgiapp.py", line 65, in load
    return self.load_wsgiapp()
  File "/var/www/projects/myblog/venv/lib/python2.7/site-packages/gunicorn/app/wsgiapp.py", line 52, in load_wsgiapp
    return util.import_app(self.app_uri)
  File "/var/www/projects/myblog/venv/lib/python2.7/site-packages/gunicorn/util.py", line 352, in import_app
    __import__(module)
  File "/var/www/projects/myblog/venv/lib/python2.7/site-packages/gevent/builtins.py", line 93, in __import__
    result = _import(*args, **kwargs)
  File "/var/www/projects/myblog/manage.py", line 15, in <module>
    app = create_app(os.getenv('BLOG_CONFIG') or 'default')
  File "/var/www/projects/myblog/app/__init__.py", line 26, in create_app
    config[config_name].init_app(app)
  File "/var/www/projects/myblog/config.py", line 60, in init_app
    if gettattr(cls, 'MAIL_USE_TLS', None):
NameError: global name 'gettattr' is not defined
[2017-09-29 15:30:37 +0000] [18469] [INFO] Worker exiting (pid: 18469)
[2017-09-29 15:30:37 +0000] [18463] [INFO] Shutting down: Master
[2017-09-29 15:30:37 +0000] [18463] [INFO] Reason: Worker failed to boot.
[2017-09-29 15:30:38 +0000] [18478] [DEBUG] Current configuration:
  proxy_protocol: False
  worker_connections: 1000
  statsd_host: None
  max_requests_jitter: 0
  post_fork: <function post_fork at 0x114f410>
  errorlog: -
  enable_stdio_inheritance: False
  worker_class: gevent
  ssl_version: 2
  suppress_ragged_eofs: True
  syslog: False
  syslog_facility: user
  when_ready: <function when_ready at 0x114f140>
  pre_fork: <function pre_fork at 0x114f2a8>
  cert_reqs: 0
  preload_app: False
  keepalive: 2
  accesslog: None
  group: 0
  graceful_timeout: 30
  do_handshake_on_connect: False
  spew: False
  workers: 2
  proc_name: gunicorn.pid
  sendfile: None
  pidfile: /var/log/gunicorn/debug.log
  umask: 0
  on_reload: <function on_reload at 0x111cf50>
  pre_exec: <function pre_exec at 0x114f9b0>
  worker_tmp_dir: None
  limit_request_fields: 100
  pythonpath: None
  on_exit: <function on_exit at 0x1151230>
  config: /var/www/projects/myblog/deploy_config.py
  logconfig: None
  check_config: False
  statsd_prefix: 
  secure_scheme_headers: {'X-FORWARDED-PROTOCOL': 'ssl', 'X-FORWARDED-PROTO': 'https', 'X-FORWARDED-SSL': 'on'}
  reload_engine: auto
  proxy_allow_ips: ['127.0.0.1']
  pre_request: <function pre_request at 0x114fb18>
  post_request: <function post_request at 0x114fc08>
  forwarded_allow_ips: ['127.0.0.1']
  worker_int: <function worker_int at 0x114f6e0>
  raw_paste_global_conf: []
  threads: 1
  max_requests: 0
  chdir: /var/www/projects/myblog
  daemon: False
  user: 0
  limit_request_line: 4094
  access_log_format: %(h)s %(l)s %(u)s %(t)s "%(r)s" %(s)s %(b)s "%(f)s" "%(a)s"
  certfile: None
  on_starting: <function on_starting at 0x111cde8>
  post_worker_init: <function post_worker_init at 0x114f578>
  child_exit: <function child_exit at 0x114fd70>
  worker_exit: <function worker_exit at 0x114fed8>
  paste: None
  default_proc_name: manage:app
  syslog_addr: udp://localhost:514
  syslog_prefix: None
  ciphers: TLSv1
  worker_abort: <function worker_abort at 0x114f848>
  loglevel: debug
  bind: ['127.0.0.1:8080']
  raw_env: []
  initgroups: False
  capture_output: False
  reload: False
  limit_request_field_size: 8190
  nworkers_changed: <function nworkers_changed at 0x11510c8>
  timeout: 30
  keyfile: None
  ca_certs: None
  tmp_upload_dir: None
  backlog: 2048
  logger_class: gunicorn.glogging.Logger
[2017-09-29 15:30:38 +0000] [18478] [INFO] Starting gunicorn 19.7.1
[2017-09-29 15:30:38 +0000] [18478] [DEBUG] Arbiter booted
[2017-09-29 15:30:38 +0000] [18478] [INFO] Listening at: http://127.0.0.1:8080 (18478)
[2017-09-29 15:30:38 +0000] [18478] [INFO] Using worker: gevent
[2017-09-29 15:30:38 +0000] [18483] [INFO] Booting worker with pid: 18483
[2017-09-29 15:30:38 +0000] [18484] [INFO] Booting worker with pid: 18484
[2017-09-29 15:30:38 +0000] [18478] [DEBUG] 2 workers
[2017-09-29 15:30:43 +0000] [18483] [ERROR] Exception in worker process
Traceback (most recent call last):
  File "/var/www/projects/myblog/venv/lib/python2.7/site-packages/gunicorn/arbiter.py", line 578, in spawn_worker
    worker.init_process()
  File "/var/www/projects/myblog/venv/lib/python2.7/site-packages/gunicorn/workers/ggevent.py", line 190, in init_process
    super(GeventWorker, self).init_process()
  File "/var/www/projects/myblog/venv/lib/python2.7/site-packages/gunicorn/workers/base.py", line 126, in init_process
    self.load_wsgi()
  File "/var/www/projects/myblog/venv/lib/python2.7/site-packages/gunicorn/workers/base.py", line 135, in load_wsgi
    self.wsgi = self.app.wsgi()
  File "/var/www/projects/myblog/venv/lib/python2.7/site-packages/gunicorn/app/base.py", line 67, in wsgi
    self.callable = self.load()
  File "/var/www/projects/myblog/venv/lib/python2.7/site-packages/gunicorn/app/wsgiapp.py", line 65, in load
    return self.load_wsgiapp()
  File "/var/www/projects/myblog/venv/lib/python2.7/site-packages/gunicorn/app/wsgiapp.py", line 52, in load_wsgiapp
    return util.import_app(self.app_uri)
  File "/var/www/projects/myblog/venv/lib/python2.7/site-packages/gunicorn/util.py", line 352, in import_app
    __import__(module)
  File "/var/www/projects/myblog/venv/lib/python2.7/site-packages/gevent/builtins.py", line 93, in __import__
    result = _import(*args, **kwargs)
  File "/var/www/projects/myblog/manage.py", line 15, in <module>
    app = create_app(os.getenv('BLOG_CONFIG') or 'default')
  File "/var/www/projects/myblog/app/__init__.py", line 26, in create_app
    config[config_name].init_app(app)
  File "/var/www/projects/myblog/config.py", line 60, in init_app
    if gettattr(cls, 'MAIL_USE_TLS', None):
NameError: global name 'gettattr' is not defined
[2017-09-29 15:30:43 +0000] [18483] [INFO] Worker exiting (pid: 18483)
[2017-09-29 15:30:43 +0000] [18484] [ERROR] Exception in worker process
Traceback (most recent call last):
  File "/var/www/projects/myblog/venv/lib/python2.7/site-packages/gunicorn/arbiter.py", line 578, in spawn_worker
    worker.init_process()
  File "/var/www/projects/myblog/venv/lib/python2.7/site-packages/gunicorn/workers/ggevent.py", line 190, in init_process
    super(GeventWorker, self).init_process()
  File "/var/www/projects/myblog/venv/lib/python2.7/site-packages/gunicorn/workers/base.py", line 126, in init_process
    self.load_wsgi()
  File "/var/www/projects/myblog/venv/lib/python2.7/site-packages/gunicorn/workers/base.py", line 135, in load_wsgi
    self.wsgi = self.app.wsgi()
  File "/var/www/projects/myblog/venv/lib/python2.7/site-packages/gunicorn/app/base.py", line 67, in wsgi
    self.callable = self.load()
  File "/var/www/projects/myblog/venv/lib/python2.7/site-packages/gunicorn/app/wsgiapp.py", line 65, in load
    return self.load_wsgiapp()
  File "/var/www/projects/myblog/venv/lib/python2.7/site-packages/gunicorn/app/wsgiapp.py", line 52, in load_wsgiapp
    return util.import_app(self.app_uri)
  File "/var/www/projects/myblog/venv/lib/python2.7/site-packages/gunicorn/util.py", line 352, in import_app
    __import__(module)
  File "/var/www/projects/myblog/venv/lib/python2.7/site-packages/gevent/builtins.py", line 93, in __import__
    result = _import(*args, **kwargs)
  File "/var/www/projects/myblog/manage.py", line 15, in <module>
    app = create_app(os.getenv('BLOG_CONFIG') or 'default')
  File "/var/www/projects/myblog/app/__init__.py", line 26, in create_app
    config[config_name].init_app(app)
  File "/var/www/projects/myblog/config.py", line 60, in init_app
    if gettattr(cls, 'MAIL_USE_TLS', None):
NameError: global name 'gettattr' is not defined
[2017-09-29 15:30:43 +0000] [18484] [INFO] Worker exiting (pid: 18484)
[2017-09-29 15:30:43 +0000] [18478] [INFO] Shutting down: Master
[2017-09-29 15:30:43 +0000] [18478] [INFO] Reason: Worker failed to boot.
[2017-09-29 15:30:45 +0000] [18493] [DEBUG] Current configuration:
  proxy_protocol: False
  worker_connections: 1000
  statsd_host: None
  max_requests_jitter: 0
  post_fork: <function post_fork at 0x1444410>
  errorlog: -
  enable_stdio_inheritance: False
  worker_class: gevent
  ssl_version: 2
  suppress_ragged_eofs: True
  syslog: False
  syslog_facility: user
  when_ready: <function when_ready at 0x1444140>
  pre_fork: <function pre_fork at 0x14442a8>
  cert_reqs: 0
  preload_app: False
  keepalive: 2
  accesslog: None
  group: 0
  graceful_timeout: 30
  do_handshake_on_connect: False
  spew: False
  workers: 2
  proc_name: gunicorn.pid
  sendfile: None
  pidfile: /var/log/gunicorn/debug.log
  umask: 0
  on_reload: <function on_reload at 0x1410f50>
  pre_exec: <function pre_exec at 0x14449b0>
  worker_tmp_dir: None
  limit_request_fields: 100
  pythonpath: None
  on_exit: <function on_exit at 0x1446230>
  config: /var/www/projects/myblog/deploy_config.py
  logconfig: None
  check_config: False
  statsd_prefix: 
  secure_scheme_headers: {'X-FORWARDED-PROTOCOL': 'ssl', 'X-FORWARDED-PROTO': 'https', 'X-FORWARDED-SSL': 'on'}
  reload_engine: auto
  proxy_allow_ips: ['127.0.0.1']
  pre_request: <function pre_request at 0x1444b18>
  post_request: <function post_request at 0x1444c08>
  forwarded_allow_ips: ['127.0.0.1']
  worker_int: <function worker_int at 0x14446e0>
  raw_paste_global_conf: []
  threads: 1
  max_requests: 0
  chdir: /var/www/projects/myblog
  daemon: False
  user: 0
  limit_request_line: 4094
  access_log_format: %(h)s %(l)s %(u)s %(t)s "%(r)s" %(s)s %(b)s "%(f)s" "%(a)s"
  certfile: None
  on_starting: <function on_starting at 0x1410de8>
  post_worker_init: <function post_worker_init at 0x1444578>
  child_exit: <function child_exit at 0x1444d70>
  worker_exit: <function worker_exit at 0x1444ed8>
  paste: None
  default_proc_name: manage:app
  syslog_addr: udp://localhost:514
  syslog_prefix: None
  ciphers: TLSv1
  worker_abort: <function worker_abort at 0x1444848>
  loglevel: debug
  bind: ['127.0.0.1:8080']
  raw_env: []
  initgroups: False
  capture_output: False
  reload: False
  limit_request_field_size: 8190
  nworkers_changed: <function nworkers_changed at 0x14460c8>
  timeout: 30
  keyfile: None
  ca_certs: None
  tmp_upload_dir: None
  backlog: 2048
  logger_class: gunicorn.glogging.Logger
[2017-09-29 15:30:45 +0000] [18493] [INFO] Starting gunicorn 19.7.1
[2017-09-29 15:30:45 +0000] [18493] [DEBUG] Arbiter booted
[2017-09-29 15:30:45 +0000] [18493] [INFO] Listening at: http://127.0.0.1:8080 (18493)
[2017-09-29 15:30:45 +0000] [18493] [INFO] Using worker: gevent
[2017-09-29 15:30:45 +0000] [18498] [INFO] Booting worker with pid: 18498
[2017-09-29 15:30:45 +0000] [18493] [DEBUG] 2 workers
[2017-09-29 15:30:45 +0000] [18499] [INFO] Booting worker with pid: 18499
[2017-09-29 15:30:49 +0000] [18498] [ERROR] Exception in worker process
Traceback (most recent call last):
  File "/var/www/projects/myblog/venv/lib/python2.7/site-packages/gunicorn/arbiter.py", line 578, in spawn_worker
    worker.init_process()
  File "/var/www/projects/myblog/venv/lib/python2.7/site-packages/gunicorn/workers/ggevent.py", line 190, in init_process
    super(GeventWorker, self).init_process()
  File "/var/www/projects/myblog/venv/lib/python2.7/site-packages/gunicorn/workers/base.py", line 126, in init_process
    self.load_wsgi()
  File "/var/www/projects/myblog/venv/lib/python2.7/site-packages/gunicorn/workers/base.py", line 135, in load_wsgi
    self.wsgi = self.app.wsgi()
  File "/var/www/projects/myblog/venv/lib/python2.7/site-packages/gunicorn/app/base.py", line 67, in wsgi
    self.callable = self.load()
  File "/var/www/projects/myblog/venv/lib/python2.7/site-packages/gunicorn/app/wsgiapp.py", line 65, in load
    return self.load_wsgiapp()
  File "/var/www/projects/myblog/venv/lib/python2.7/site-packages/gunicorn/app/wsgiapp.py", line 52, in load_wsgiapp
    return util.import_app(self.app_uri)
  File "/var/www/projects/myblog/venv/lib/python2.7/site-packages/gunicorn/util.py", line 352, in import_app
    __import__(module)
  File "/var/www/projects/myblog/venv/lib/python2.7/site-packages/gevent/builtins.py", line 93, in __import__
    result = _import(*args, **kwargs)
  File "/var/www/projects/myblog/manage.py", line 15, in <module>
    app = create_app(os.getenv('BLOG_CONFIG') or 'default')
  File "/var/www/projects/myblog/app/__init__.py", line 26, in create_app
    config[config_name].init_app(app)
  File "/var/www/projects/myblog/config.py", line 60, in init_app
    if gettattr(cls, 'MAIL_USE_TLS', None):
NameError: global name 'gettattr' is not defined
[2017-09-29 15:30:49 +0000] [18498] [INFO] Worker exiting (pid: 18498)
[2017-09-29 15:30:49 +0000] [18499] [ERROR] Exception in worker process
Traceback (most recent call last):
  File "/var/www/projects/myblog/venv/lib/python2.7/site-packages/gunicorn/arbiter.py", line 578, in spawn_worker
    worker.init_process()
  File "/var/www/projects/myblog/venv/lib/python2.7/site-packages/gunicorn/workers/ggevent.py", line 190, in init_process
    super(GeventWorker, self).init_process()
  File "/var/www/projects/myblog/venv/lib/python2.7/site-packages/gunicorn/workers/base.py", line 126, in init_process
    self.load_wsgi()
  File "/var/www/projects/myblog/venv/lib/python2.7/site-packages/gunicorn/workers/base.py", line 135, in load_wsgi
    self.wsgi = self.app.wsgi()
  File "/var/www/projects/myblog/venv/lib/python2.7/site-packages/gunicorn/app/base.py", line 67, in wsgi
    self.callable = self.load()
  File "/var/www/projects/myblog/venv/lib/python2.7/site-packages/gunicorn/app/wsgiapp.py", line 65, in load
    return self.load_wsgiapp()
  File "/var/www/projects/myblog/venv/lib/python2.7/site-packages/gunicorn/app/wsgiapp.py", line 52, in load_wsgiapp
    return util.import_app(self.app_uri)
  File "/var/www/projects/myblog/venv/lib/python2.7/site-packages/gunicorn/util.py", line 352, in import_app
    __import__(module)
  File "/var/www/projects/myblog/venv/lib/python2.7/site-packages/gevent/builtins.py", line 93, in __import__
    result = _import(*args, **kwargs)
  File "/var/www/projects/myblog/manage.py", line 15, in <module>
    app = create_app(os.getenv('BLOG_CONFIG') or 'default')
  File "/var/www/projects/myblog/app/__init__.py", line 26, in create_app
    config[config_name].init_app(app)
  File "/var/www/projects/myblog/config.py", line 60, in init_app
    if gettattr(cls, 'MAIL_USE_TLS', None):
NameError: global name 'gettattr' is not defined
[2017-09-29 15:30:49 +0000] [18499] [INFO] Worker exiting (pid: 18499)
[2017-09-29 15:30:49 +0000] [18493] [INFO] Shutting down: Master
[2017-09-29 15:30:49 +0000] [18493] [INFO] Reason: Worker failed to boot.
[2017-09-29 15:30:51 +0000] [18508] [DEBUG] Current configuration:
  proxy_protocol: False
  worker_connections: 1000
  statsd_host: None
  max_requests_jitter: 0
  post_fork: <function post_fork at 0x1705410>
  errorlog: -
  enable_stdio_inheritance: False
  worker_class: gevent
  ssl_version: 2
  suppress_ragged_eofs: True
  syslog: False
  syslog_facility: user
  when_ready: <function when_ready at 0x1705140>
  pre_fork: <function pre_fork at 0x17052a8>
  cert_reqs: 0
  preload_app: False
  keepalive: 2
  accesslog: None
  group: 0
  graceful_timeout: 30
  do_handshake_on_connect: False
  spew: False
  workers: 2
  proc_name: gunicorn.pid
  sendfile: None
  pidfile: /var/log/gunicorn/debug.log
  umask: 0
  on_reload: <function on_reload at 0x16d2f50>
  pre_exec: <function pre_exec at 0x17059b0>
  worker_tmp_dir: None
  limit_request_fields: 100
  pythonpath: None
  on_exit: <function on_exit at 0x1707230>
  config: /var/www/projects/myblog/deploy_config.py
  logconfig: None
  check_config: False
  statsd_prefix: 
  secure_scheme_headers: {'X-FORWARDED-PROTOCOL': 'ssl', 'X-FORWARDED-PROTO': 'https', 'X-FORWARDED-SSL': 'on'}
  reload_engine: auto
  proxy_allow_ips: ['127.0.0.1']
  pre_request: <function pre_request at 0x1705b18>
  post_request: <function post_request at 0x1705c08>
  forwarded_allow_ips: ['127.0.0.1']
  worker_int: <function worker_int at 0x17056e0>
  raw_paste_global_conf: []
  threads: 1
  max_requests: 0
  chdir: /var/www/projects/myblog
  daemon: False
  user: 0
  limit_request_line: 4094
  access_log_format: %(h)s %(l)s %(u)s %(t)s "%(r)s" %(s)s %(b)s "%(f)s" "%(a)s"
  certfile: None
  on_starting: <function on_starting at 0x16d2de8>
  post_worker_init: <function post_worker_init at 0x1705578>
  child_exit: <function child_exit at 0x1705d70>
  worker_exit: <function worker_exit at 0x1705ed8>
  paste: None
  default_proc_name: manage:app
  syslog_addr: udp://localhost:514
  syslog_prefix: None
  ciphers: TLSv1
  worker_abort: <function worker_abort at 0x1705848>
  loglevel: debug
  bind: ['127.0.0.1:8080']
  raw_env: []
  initgroups: False
  capture_output: False
  reload: False
  limit_request_field_size: 8190
  nworkers_changed: <function nworkers_changed at 0x17070c8>
  timeout: 30
  keyfile: None
  ca_certs: None
  tmp_upload_dir: None
  backlog: 2048
  logger_class: gunicorn.glogging.Logger
[2017-09-29 15:30:51 +0000] [18508] [INFO] Starting gunicorn 19.7.1
[2017-09-29 15:30:51 +0000] [18508] [DEBUG] Arbiter booted
[2017-09-29 15:30:51 +0000] [18508] [INFO] Listening at: http://127.0.0.1:8080 (18508)
[2017-09-29 15:30:51 +0000] [18508] [INFO] Using worker: gevent
[2017-09-29 15:30:51 +0000] [18513] [INFO] Booting worker with pid: 18513
[2017-09-29 15:30:51 +0000] [18514] [INFO] Booting worker with pid: 18514
[2017-09-29 15:30:51 +0000] [18508] [DEBUG] 2 workers
[2017-09-29 15:30:55 +0000] [18513] [ERROR] Exception in worker process
Traceback (most recent call last):
  File "/var/www/projects/myblog/venv/lib/python2.7/site-packages/gunicorn/arbiter.py", line 578, in spawn_worker
    worker.init_process()
  File "/var/www/projects/myblog/venv/lib/python2.7/site-packages/gunicorn/workers/ggevent.py", line 190, in init_process
    super(GeventWorker, self).init_process()
  File "/var/www/projects/myblog/venv/lib/python2.7/site-packages/gunicorn/workers/base.py", line 126, in init_process
    self.load_wsgi()
  File "/var/www/projects/myblog/venv/lib/python2.7/site-packages/gunicorn/workers/base.py", line 135, in load_wsgi
    self.wsgi = self.app.wsgi()
  File "/var/www/projects/myblog/venv/lib/python2.7/site-packages/gunicorn/app/base.py", line 67, in wsgi
    self.callable = self.load()
  File "/var/www/projects/myblog/venv/lib/python2.7/site-packages/gunicorn/app/wsgiapp.py", line 65, in load
    return self.load_wsgiapp()
  File "/var/www/projects/myblog/venv/lib/python2.7/site-packages/gunicorn/app/wsgiapp.py", line 52, in load_wsgiapp
    return util.import_app(self.app_uri)
  File "/var/www/projects/myblog/venv/lib/python2.7/site-packages/gunicorn/util.py", line 352, in import_app
    __import__(module)
  File "/var/www/projects/myblog/venv/lib/python2.7/site-packages/gevent/builtins.py", line 93, in __import__
    result = _import(*args, **kwargs)
  File "/var/www/projects/myblog/manage.py", line 15, in <module>
    app = create_app(os.getenv('BLOG_CONFIG') or 'default')
  File "/var/www/projects/myblog/app/__init__.py", line 26, in create_app
    config[config_name].init_app(app)
  File "/var/www/projects/myblog/config.py", line 60, in init_app
    if gettattr(cls, 'MAIL_USE_TLS', None):
NameError: global name 'gettattr' is not defined
[2017-09-29 15:30:55 +0000] [18513] [INFO] Worker exiting (pid: 18513)
[2017-09-29 15:30:55 +0000] [18514] [ERROR] Exception in worker process
Traceback (most recent call last):
  File "/var/www/projects/myblog/venv/lib/python2.7/site-packages/gunicorn/arbiter.py", line 578, in spawn_worker
    worker.init_process()
  File "/var/www/projects/myblog/venv/lib/python2.7/site-packages/gunicorn/workers/ggevent.py", line 190, in init_process
    super(GeventWorker, self).init_process()
  File "/var/www/projects/myblog/venv/lib/python2.7/site-packages/gunicorn/workers/base.py", line 126, in init_process
    self.load_wsgi()
  File "/var/www/projects/myblog/venv/lib/python2.7/site-packages/gunicorn/workers/base.py", line 135, in load_wsgi
    self.wsgi = self.app.wsgi()
  File "/var/www/projects/myblog/venv/lib/python2.7/site-packages/gunicorn/app/base.py", line 67, in wsgi
    self.callable = self.load()
  File "/var/www/projects/myblog/venv/lib/python2.7/site-packages/gunicorn/app/wsgiapp.py", line 65, in load
    return self.load_wsgiapp()
  File "/var/www/projects/myblog/venv/lib/python2.7/site-packages/gunicorn/app/wsgiapp.py", line 52, in load_wsgiapp
    return util.import_app(self.app_uri)
  File "/var/www/projects/myblog/venv/lib/python2.7/site-packages/gunicorn/util.py", line 352, in import_app
    __import__(module)
  File "/var/www/projects/myblog/venv/lib/python2.7/site-packages/gevent/builtins.py", line 93, in __import__
    result = _import(*args, **kwargs)
  File "/var/www/projects/myblog/manage.py", line 15, in <module>
    app = create_app(os.getenv('BLOG_CONFIG') or 'default')
  File "/var/www/projects/myblog/app/__init__.py", line 26, in create_app
    config[config_name].init_app(app)
  File "/var/www/projects/myblog/config.py", line 60, in init_app
    if gettattr(cls, 'MAIL_USE_TLS', None):
NameError: global name 'gettattr' is not defined
[2017-09-29 15:30:55 +0000] [18514] [INFO] Worker exiting (pid: 18514)
[2017-09-29 15:30:56 +0000] [18508] [INFO] Shutting down: Master
[2017-09-29 15:30:56 +0000] [18508] [INFO] Reason: Worker failed to boot.
[2017-09-29 15:30:57 +0000] [18523] [DEBUG] Current configuration:
  proxy_protocol: False
  worker_connections: 1000
  statsd_host: None
  max_requests_jitter: 0
  post_fork: <function post_fork at 0x12a3410>
  errorlog: -
  enable_stdio_inheritance: False
  worker_class: gevent
  ssl_version: 2
  suppress_ragged_eofs: True
  syslog: False
  syslog_facility: user
  when_ready: <function when_ready at 0x12a3140>
  pre_fork: <function pre_fork at 0x12a32a8>
  cert_reqs: 0
  preload_app: False
  keepalive: 2
  accesslog: None
  group: 0
  graceful_timeout: 30
  do_handshake_on_connect: False
  spew: False
  workers: 2
  proc_name: gunicorn.pid
  sendfile: None
  pidfile: /var/log/gunicorn/debug.log
  umask: 0
  on_reload: <function on_reload at 0x126ff50>
  pre_exec: <function pre_exec at 0x12a39b0>
  worker_tmp_dir: None
  limit_request_fields: 100
  pythonpath: None
  on_exit: <function on_exit at 0x12a5230>
  config: /var/www/projects/myblog/deploy_config.py
  logconfig: None
  check_config: False
  statsd_prefix: 
  secure_scheme_headers: {'X-FORWARDED-PROTOCOL': 'ssl', 'X-FORWARDED-PROTO': 'https', 'X-FORWARDED-SSL': 'on'}
  reload_engine: auto
  proxy_allow_ips: ['127.0.0.1']
  pre_request: <function pre_request at 0x12a3b18>
  post_request: <function post_request at 0x12a3c08>
  forwarded_allow_ips: ['127.0.0.1']
  worker_int: <function worker_int at 0x12a36e0>
  raw_paste_global_conf: []
  threads: 1
  max_requests: 0
  chdir: /var/www/projects/myblog
  daemon: False
  user: 0
  limit_request_line: 4094
  access_log_format: %(h)s %(l)s %(u)s %(t)s "%(r)s" %(s)s %(b)s "%(f)s" "%(a)s"
  certfile: None
  on_starting: <function on_starting at 0x126fde8>
  post_worker_init: <function post_worker_init at 0x12a3578>
  child_exit: <function child_exit at 0x12a3d70>
  worker_exit: <function worker_exit at 0x12a3ed8>
  paste: None
  default_proc_name: manage:app
  syslog_addr: udp://localhost:514
  syslog_prefix: None
  ciphers: TLSv1
  worker_abort: <function worker_abort at 0x12a3848>
  loglevel: debug
  bind: ['127.0.0.1:8080']
  raw_env: []
  initgroups: False
  capture_output: False
  reload: False
  limit_request_field_size: 8190
  nworkers_changed: <function nworkers_changed at 0x12a50c8>
  timeout: 30
  keyfile: None
  ca_certs: None
  tmp_upload_dir: None
  backlog: 2048
  logger_class: gunicorn.glogging.Logger
[2017-09-29 15:30:57 +0000] [18523] [INFO] Starting gunicorn 19.7.1
[2017-09-29 15:30:57 +0000] [18523] [DEBUG] Arbiter booted
[2017-09-29 15:30:57 +0000] [18523] [INFO] Listening at: http://127.0.0.1:8080 (18523)
[2017-09-29 15:30:57 +0000] [18523] [INFO] Using worker: gevent
[2017-09-29 15:30:57 +0000] [18528] [INFO] Booting worker with pid: 18528
[2017-09-29 15:30:57 +0000] [18529] [INFO] Booting worker with pid: 18529
[2017-09-29 15:30:57 +0000] [18523] [DEBUG] 2 workers
[2017-09-29 15:31:01 +0000] [18528] [ERROR] Exception in worker process
Traceback (most recent call last):
  File "/var/www/projects/myblog/venv/lib/python2.7/site-packages/gunicorn/arbiter.py", line 578, in spawn_worker
    worker.init_process()
  File "/var/www/projects/myblog/venv/lib/python2.7/site-packages/gunicorn/workers/ggevent.py", line 190, in init_process
    super(GeventWorker, self).init_process()
  File "/var/www/projects/myblog/venv/lib/python2.7/site-packages/gunicorn/workers/base.py", line 126, in init_process
    self.load_wsgi()
  File "/var/www/projects/myblog/venv/lib/python2.7/site-packages/gunicorn/workers/base.py", line 135, in load_wsgi
    self.wsgi = self.app.wsgi()
  File "/var/www/projects/myblog/venv/lib/python2.7/site-packages/gunicorn/app/base.py", line 67, in wsgi
    self.callable = self.load()
  File "/var/www/projects/myblog/venv/lib/python2.7/site-packages/gunicorn/app/wsgiapp.py", line 65, in load
    return self.load_wsgiapp()
  File "/var/www/projects/myblog/venv/lib/python2.7/site-packages/gunicorn/app/wsgiapp.py", line 52, in load_wsgiapp
    return util.import_app(self.app_uri)
  File "/var/www/projects/myblog/venv/lib/python2.7/site-packages/gunicorn/util.py", line 352, in import_app
    __import__(module)
  File "/var/www/projects/myblog/venv/lib/python2.7/site-packages/gevent/builtins.py", line 93, in __import__
    result = _import(*args, **kwargs)
  File "/var/www/projects/myblog/manage.py", line 15, in <module>
    app = create_app(os.getenv('BLOG_CONFIG') or 'default')
  File "/var/www/projects/myblog/app/__init__.py", line 26, in create_app
    config[config_name].init_app(app)
  File "/var/www/projects/myblog/config.py", line 60, in init_app
    if gettattr(cls, 'MAIL_USE_TLS', None):
NameError: global name 'gettattr' is not defined
[2017-09-29 15:31:01 +0000] [18528] [INFO] Worker exiting (pid: 18528)
[2017-09-29 15:31:01 +0000] [18529] [ERROR] Exception in worker process
Traceback (most recent call last):
  File "/var/www/projects/myblog/venv/lib/python2.7/site-packages/gunicorn/arbiter.py", line 578, in spawn_worker
    worker.init_process()
  File "/var/www/projects/myblog/venv/lib/python2.7/site-packages/gunicorn/workers/ggevent.py", line 190, in init_process
    super(GeventWorker, self).init_process()
  File "/var/www/projects/myblog/venv/lib/python2.7/site-packages/gunicorn/workers/base.py", line 126, in init_process
    self.load_wsgi()
  File "/var/www/projects/myblog/venv/lib/python2.7/site-packages/gunicorn/workers/base.py", line 135, in load_wsgi
    self.wsgi = self.app.wsgi()
  File "/var/www/projects/myblog/venv/lib/python2.7/site-packages/gunicorn/app/base.py", line 67, in wsgi
    self.callable = self.load()
  File "/var/www/projects/myblog/venv/lib/python2.7/site-packages/gunicorn/app/wsgiapp.py", line 65, in load
    return self.load_wsgiapp()
  File "/var/www/projects/myblog/venv/lib/python2.7/site-packages/gunicorn/app/wsgiapp.py", line 52, in load_wsgiapp
    return util.import_app(self.app_uri)
  File "/var/www/projects/myblog/venv/lib/python2.7/site-packages/gunicorn/util.py", line 352, in import_app
    __import__(module)
  File "/var/www/projects/myblog/venv/lib/python2.7/site-packages/gevent/builtins.py", line 93, in __import__
    result = _import(*args, **kwargs)
  File "/var/www/projects/myblog/manage.py", line 15, in <module>
    app = create_app(os.getenv('BLOG_CONFIG') or 'default')
  File "/var/www/projects/myblog/app/__init__.py", line 26, in create_app
    config[config_name].init_app(app)
  File "/var/www/projects/myblog/config.py", line 60, in init_app
    if gettattr(cls, 'MAIL_USE_TLS', None):
NameError: global name 'gettattr' is not defined
[2017-09-29 15:31:01 +0000] [18529] [INFO] Worker exiting (pid: 18529)
[2017-09-29 15:31:01 +0000] [18523] [INFO] Shutting down: Master
[2017-09-29 15:31:01 +0000] [18523] [INFO] Reason: Worker failed to boot.
[2017-09-29 15:31:03 +0000] [18538] [DEBUG] Current configuration:
  proxy_protocol: False
  worker_connections: 1000
  statsd_host: None
  max_requests_jitter: 0
  post_fork: <function post_fork at 0x1ec3410>
  errorlog: -
  enable_stdio_inheritance: False
  worker_class: gevent
  ssl_version: 2
  suppress_ragged_eofs: True
  syslog: False
  syslog_facility: user
  when_ready: <function when_ready at 0x1ec3140>
  pre_fork: <function pre_fork at 0x1ec32a8>
  cert_reqs: 0
  preload_app: False
  keepalive: 2
  accesslog: None
  group: 0
  graceful_timeout: 30
  do_handshake_on_connect: False
  spew: False
  workers: 2
  proc_name: gunicorn.pid
  sendfile: None
  pidfile: /var/log/gunicorn/debug.log
  umask: 0
  on_reload: <function on_reload at 0x1e90f50>
  pre_exec: <function pre_exec at 0x1ec39b0>
  worker_tmp_dir: None
  limit_request_fields: 100
  pythonpath: None
  on_exit: <function on_exit at 0x1ec5230>
  config: /var/www/projects/myblog/deploy_config.py
  logconfig: None
  check_config: False
  statsd_prefix: 
  secure_scheme_headers: {'X-FORWARDED-PROTOCOL': 'ssl', 'X-FORWARDED-PROTO': 'https', 'X-FORWARDED-SSL': 'on'}
  reload_engine: auto
  proxy_allow_ips: ['127.0.0.1']
  pre_request: <function pre_request at 0x1ec3b18>
  post_request: <function post_request at 0x1ec3c08>
  forwarded_allow_ips: ['127.0.0.1']
  worker_int: <function worker_int at 0x1ec36e0>
  raw_paste_global_conf: []
  threads: 1
  max_requests: 0
  chdir: /var/www/projects/myblog
  daemon: False
  user: 0
  limit_request_line: 4094
  access_log_format: %(h)s %(l)s %(u)s %(t)s "%(r)s" %(s)s %(b)s "%(f)s" "%(a)s"
  certfile: None
  on_starting: <function on_starting at 0x1e90de8>
  post_worker_init: <function post_worker_init at 0x1ec3578>
  child_exit: <function child_exit at 0x1ec3d70>
  worker_exit: <function worker_exit at 0x1ec3ed8>
  paste: None
  default_proc_name: manage:app
  syslog_addr: udp://localhost:514
  syslog_prefix: None
  ciphers: TLSv1
  worker_abort: <function worker_abort at 0x1ec3848>
  loglevel: debug
  bind: ['127.0.0.1:8080']
  raw_env: []
  initgroups: False
  capture_output: False
  reload: False
  limit_request_field_size: 8190
  nworkers_changed: <function nworkers_changed at 0x1ec50c8>
  timeout: 30
  keyfile: None
  ca_certs: None
  tmp_upload_dir: None
  backlog: 2048
  logger_class: gunicorn.glogging.Logger
[2017-09-29 15:31:03 +0000] [18538] [INFO] Starting gunicorn 19.7.1
[2017-09-29 15:31:03 +0000] [18538] [DEBUG] Arbiter booted
[2017-09-29 15:31:03 +0000] [18538] [INFO] Listening at: http://127.0.0.1:8080 (18538)
[2017-09-29 15:31:03 +0000] [18538] [INFO] Using worker: gevent
[2017-09-29 15:31:03 +0000] [18543] [INFO] Booting worker with pid: 18543
[2017-09-29 15:31:03 +0000] [18544] [INFO] Booting worker with pid: 18544
[2017-09-29 15:31:03 +0000] [18538] [DEBUG] 2 workers
[2017-09-29 15:31:07 +0000] [18543] [ERROR] Exception in worker process
Traceback (most recent call last):
  File "/var/www/projects/myblog/venv/lib/python2.7/site-packages/gunicorn/arbiter.py", line 578, in spawn_worker
    worker.init_process()
  File "/var/www/projects/myblog/venv/lib/python2.7/site-packages/gunicorn/workers/ggevent.py", line 190, in init_process
    super(GeventWorker, self).init_process()
  File "/var/www/projects/myblog/venv/lib/python2.7/site-packages/gunicorn/workers/base.py", line 126, in init_process
    self.load_wsgi()
  File "/var/www/projects/myblog/venv/lib/python2.7/site-packages/gunicorn/workers/base.py", line 135, in load_wsgi
    self.wsgi = self.app.wsgi()
  File "/var/www/projects/myblog/venv/lib/python2.7/site-packages/gunicorn/app/base.py", line 67, in wsgi
    self.callable = self.load()
  File "/var/www/projects/myblog/venv/lib/python2.7/site-packages/gunicorn/app/wsgiapp.py", line 65, in load
    return self.load_wsgiapp()
  File "/var/www/projects/myblog/venv/lib/python2.7/site-packages/gunicorn/app/wsgiapp.py", line 52, in load_wsgiapp
    return util.import_app(self.app_uri)
  File "/var/www/projects/myblog/venv/lib/python2.7/site-packages/gunicorn/util.py", line 352, in import_app
    __import__(module)
  File "/var/www/projects/myblog/venv/lib/python2.7/site-packages/gevent/builtins.py", line 93, in __import__
    result = _import(*args, **kwargs)
  File "/var/www/projects/myblog/manage.py", line 15, in <module>
    app = create_app(os.getenv('BLOG_CONFIG') or 'default')
  File "/var/www/projects/myblog/app/__init__.py", line 26, in create_app
    config[config_name].init_app(app)
  File "/var/www/projects/myblog/config.py", line 60, in init_app
    if gettattr(cls, 'MAIL_USE_TLS', None):
NameError: global name 'gettattr' is not defined
[2017-09-29 15:31:07 +0000] [18543] [INFO] Worker exiting (pid: 18543)
[2017-09-29 15:31:07 +0000] [18544] [ERROR] Exception in worker process
Traceback (most recent call last):
  File "/var/www/projects/myblog/venv/lib/python2.7/site-packages/gunicorn/arbiter.py", line 578, in spawn_worker
    worker.init_process()
  File "/var/www/projects/myblog/venv/lib/python2.7/site-packages/gunicorn/workers/ggevent.py", line 190, in init_process
    super(GeventWorker, self).init_process()
  File "/var/www/projects/myblog/venv/lib/python2.7/site-packages/gunicorn/workers/base.py", line 126, in init_process
    self.load_wsgi()
  File "/var/www/projects/myblog/venv/lib/python2.7/site-packages/gunicorn/workers/base.py", line 135, in load_wsgi
    self.wsgi = self.app.wsgi()
  File "/var/www/projects/myblog/venv/lib/python2.7/site-packages/gunicorn/app/base.py", line 67, in wsgi
    self.callable = self.load()
  File "/var/www/projects/myblog/venv/lib/python2.7/site-packages/gunicorn/app/wsgiapp.py", line 65, in load
    return self.load_wsgiapp()
  File "/var/www/projects/myblog/venv/lib/python2.7/site-packages/gunicorn/app/wsgiapp.py", line 52, in load_wsgiapp
    return util.import_app(self.app_uri)
  File "/var/www/projects/myblog/venv/lib/python2.7/site-packages/gunicorn/util.py", line 352, in import_app
    __import__(module)
  File "/var/www/projects/myblog/venv/lib/python2.7/site-packages/gevent/builtins.py", line 93, in __import__
    result = _import(*args, **kwargs)
  File "/var/www/projects/myblog/manage.py", line 15, in <module>
    app = create_app(os.getenv('BLOG_CONFIG') or 'default')
  File "/var/www/projects/myblog/app/__init__.py", line 26, in create_app
    config[config_name].init_app(app)
  File "/var/www/projects/myblog/config.py", line 60, in init_app
    if gettattr(cls, 'MAIL_USE_TLS', None):
NameError: global name 'gettattr' is not defined
[2017-09-29 15:31:07 +0000] [18544] [INFO] Worker exiting (pid: 18544)
[2017-09-29 15:31:07 +0000] [18538] [INFO] Shutting down: Master
[2017-09-29 15:31:07 +0000] [18538] [INFO] Reason: Worker failed to boot.
[2017-09-29 15:31:09 +0000] [18553] [DEBUG] Current configuration:
  proxy_protocol: False
  worker_connections: 1000
  statsd_host: None
  max_requests_jitter: 0
  post_fork: <function post_fork at 0x1edd410>
  errorlog: -
  enable_stdio_inheritance: False
  worker_class: gevent
  ssl_version: 2
  suppress_ragged_eofs: True
  syslog: False
  syslog_facility: user
  when_ready: <function when_ready at 0x1edd140>
  pre_fork: <function pre_fork at 0x1edd2a8>
  cert_reqs: 0
  preload_app: False
  keepalive: 2
  accesslog: None
  group: 0
  graceful_timeout: 30
  do_handshake_on_connect: False
  spew: False
  workers: 2
  proc_name: gunicorn.pid
  sendfile: None
  pidfile: /var/log/gunicorn/debug.log
  umask: 0
  on_reload: <function on_reload at 0x1ea9f50>
  pre_exec: <function pre_exec at 0x1edd9b0>
  worker_tmp_dir: None
  limit_request_fields: 100
  pythonpath: None
  on_exit: <function on_exit at 0x1edf230>
  config: /var/www/projects/myblog/deploy_config.py
  logconfig: None
  check_config: False
  statsd_prefix: 
  secure_scheme_headers: {'X-FORWARDED-PROTOCOL': 'ssl', 'X-FORWARDED-PROTO': 'https', 'X-FORWARDED-SSL': 'on'}
  reload_engine: auto
  proxy_allow_ips: ['127.0.0.1']
  pre_request: <function pre_request at 0x1eddb18>
  post_request: <function post_request at 0x1eddc08>
  forwarded_allow_ips: ['127.0.0.1']
  worker_int: <function worker_int at 0x1edd6e0>
  raw_paste_global_conf: []
  threads: 1
  max_requests: 0
  chdir: /var/www/projects/myblog
  daemon: False
  user: 0
  limit_request_line: 4094
  access_log_format: %(h)s %(l)s %(u)s %(t)s "%(r)s" %(s)s %(b)s "%(f)s" "%(a)s"
  certfile: None
  on_starting: <function on_starting at 0x1ea9de8>
  post_worker_init: <function post_worker_init at 0x1edd578>
  child_exit: <function child_exit at 0x1eddd70>
  worker_exit: <function worker_exit at 0x1edded8>
  paste: None
  default_proc_name: manage:app
  syslog_addr: udp://localhost:514
  syslog_prefix: None
  ciphers: TLSv1
  worker_abort: <function worker_abort at 0x1edd848>
  loglevel: debug
  bind: ['127.0.0.1:8080']
  raw_env: []
  initgroups: False
  capture_output: False
  reload: False
  limit_request_field_size: 8190
  nworkers_changed: <function nworkers_changed at 0x1edf0c8>
  timeout: 30
  keyfile: None
  ca_certs: None
  tmp_upload_dir: None
  backlog: 2048
  logger_class: gunicorn.glogging.Logger
[2017-09-29 15:31:09 +0000] [18553] [INFO] Starting gunicorn 19.7.1
[2017-09-29 15:31:09 +0000] [18553] [DEBUG] Arbiter booted
[2017-09-29 15:31:09 +0000] [18553] [INFO] Listening at: http://127.0.0.1:8080 (18553)
[2017-09-29 15:31:09 +0000] [18553] [INFO] Using worker: gevent
[2017-09-29 15:31:09 +0000] [18558] [INFO] Booting worker with pid: 18558
[2017-09-29 15:31:10 +0000] [18559] [INFO] Booting worker with pid: 18559
[2017-09-29 15:31:10 +0000] [18553] [DEBUG] 2 workers
[2017-09-29 15:31:13 +0000] [18558] [ERROR] Exception in worker process
Traceback (most recent call last):
  File "/var/www/projects/myblog/venv/lib/python2.7/site-packages/gunicorn/arbiter.py", line 578, in spawn_worker
    worker.init_process()
  File "/var/www/projects/myblog/venv/lib/python2.7/site-packages/gunicorn/workers/ggevent.py", line 190, in init_process
    super(GeventWorker, self).init_process()
  File "/var/www/projects/myblog/venv/lib/python2.7/site-packages/gunicorn/workers/base.py", line 126, in init_process
    self.load_wsgi()
  File "/var/www/projects/myblog/venv/lib/python2.7/site-packages/gunicorn/workers/base.py", line 135, in load_wsgi
    self.wsgi = self.app.wsgi()
  File "/var/www/projects/myblog/venv/lib/python2.7/site-packages/gunicorn/app/base.py", line 67, in wsgi
    self.callable = self.load()
  File "/var/www/projects/myblog/venv/lib/python2.7/site-packages/gunicorn/app/wsgiapp.py", line 65, in load
    return self.load_wsgiapp()
  File "/var/www/projects/myblog/venv/lib/python2.7/site-packages/gunicorn/app/wsgiapp.py", line 52, in load_wsgiapp
    return util.import_app(self.app_uri)
  File "/var/www/projects/myblog/venv/lib/python2.7/site-packages/gunicorn/util.py", line 352, in import_app
    __import__(module)
  File "/var/www/projects/myblog/venv/lib/python2.7/site-packages/gevent/builtins.py", line 93, in __import__
    result = _import(*args, **kwargs)
  File "/var/www/projects/myblog/manage.py", line 15, in <module>
    app = create_app(os.getenv('BLOG_CONFIG') or 'default')
  File "/var/www/projects/myblog/app/__init__.py", line 26, in create_app
    config[config_name].init_app(app)
  File "/var/www/projects/myblog/config.py", line 60, in init_app
    if gettattr(cls, 'MAIL_USE_TLS', None):
NameError: global name 'gettattr' is not defined
[2017-09-29 15:31:13 +0000] [18558] [INFO] Worker exiting (pid: 18558)
[2017-09-29 15:31:13 +0000] [18559] [ERROR] Exception in worker process
Traceback (most recent call last):
  File "/var/www/projects/myblog/venv/lib/python2.7/site-packages/gunicorn/arbiter.py", line 578, in spawn_worker
    worker.init_process()
  File "/var/www/projects/myblog/venv/lib/python2.7/site-packages/gunicorn/workers/ggevent.py", line 190, in init_process
    super(GeventWorker, self).init_process()
  File "/var/www/projects/myblog/venv/lib/python2.7/site-packages/gunicorn/workers/base.py", line 126, in init_process
    self.load_wsgi()
  File "/var/www/projects/myblog/venv/lib/python2.7/site-packages/gunicorn/workers/base.py", line 135, in load_wsgi
    self.wsgi = self.app.wsgi()
  File "/var/www/projects/myblog/venv/lib/python2.7/site-packages/gunicorn/app/base.py", line 67, in wsgi
    self.callable = self.load()
  File "/var/www/projects/myblog/venv/lib/python2.7/site-packages/gunicorn/app/wsgiapp.py", line 65, in load
    return self.load_wsgiapp()
  File "/var/www/projects/myblog/venv/lib/python2.7/site-packages/gunicorn/app/wsgiapp.py", line 52, in load_wsgiapp
    return util.import_app(self.app_uri)
  File "/var/www/projects/myblog/venv/lib/python2.7/site-packages/gunicorn/util.py", line 352, in import_app
    __import__(module)
  File "/var/www/projects/myblog/venv/lib/python2.7/site-packages/gevent/builtins.py", line 93, in __import__
    result = _import(*args, **kwargs)
  File "/var/www/projects/myblog/manage.py", line 15, in <module>
    app = create_app(os.getenv('BLOG_CONFIG') or 'default')
  File "/var/www/projects/myblog/app/__init__.py", line 26, in create_app
    config[config_name].init_app(app)
  File "/var/www/projects/myblog/config.py", line 60, in init_app
    if gettattr(cls, 'MAIL_USE_TLS', None):
NameError: global name 'gettattr' is not defined
[2017-09-29 15:31:13 +0000] [18559] [INFO] Worker exiting (pid: 18559)
[2017-09-29 15:31:14 +0000] [18553] [INFO] Shutting down: Master
[2017-09-29 15:31:14 +0000] [18553] [INFO] Reason: Worker failed to boot.
[2017-09-29 15:31:17 +0000] [18568] [DEBUG] Current configuration:
  proxy_protocol: False
  worker_connections: 1000
  statsd_host: None
  max_requests_jitter: 0
  post_fork: <function post_fork at 0x2b3b410>
  errorlog: -
  enable_stdio_inheritance: False
  worker_class: gevent
  ssl_version: 2
  suppress_ragged_eofs: True
  syslog: False
  syslog_facility: user
  when_ready: <function when_ready at 0x2b3b140>
  pre_fork: <function pre_fork at 0x2b3b2a8>
  cert_reqs: 0
  preload_app: False
  keepalive: 2
  accesslog: None
  group: 0
  graceful_timeout: 30
  do_handshake_on_connect: False
  spew: False
  workers: 2
  proc_name: gunicorn.pid
  sendfile: None
  pidfile: /var/log/gunicorn/debug.log
  umask: 0
  on_reload: <function on_reload at 0x2b07f50>
  pre_exec: <function pre_exec at 0x2b3b9b0>
  worker_tmp_dir: None
  limit_request_fields: 100
  pythonpath: None
  on_exit: <function on_exit at 0x2b3d230>
  config: /var/www/projects/myblog/deploy_config.py
  logconfig: None
  check_config: False
  statsd_prefix: 
  secure_scheme_headers: {'X-FORWARDED-PROTOCOL': 'ssl', 'X-FORWARDED-PROTO': 'https', 'X-FORWARDED-SSL': 'on'}
  reload_engine: auto
  proxy_allow_ips: ['127.0.0.1']
  pre_request: <function pre_request at 0x2b3bb18>
  post_request: <function post_request at 0x2b3bc08>
  forwarded_allow_ips: ['127.0.0.1']
  worker_int: <function worker_int at 0x2b3b6e0>
  raw_paste_global_conf: []
  threads: 1
  max_requests: 0
  chdir: /var/www/projects/myblog
  daemon: False
  user: 0
  limit_request_line: 4094
  access_log_format: %(h)s %(l)s %(u)s %(t)s "%(r)s" %(s)s %(b)s "%(f)s" "%(a)s"
  certfile: None
  on_starting: <function on_starting at 0x2b07de8>
  post_worker_init: <function post_worker_init at 0x2b3b578>
  child_exit: <function child_exit at 0x2b3bd70>
  worker_exit: <function worker_exit at 0x2b3bed8>
  paste: None
  default_proc_name: manage:app
  syslog_addr: udp://localhost:514
  syslog_prefix: None
  ciphers: TLSv1
  worker_abort: <function worker_abort at 0x2b3b848>
  loglevel: debug
  bind: ['127.0.0.1:8080']
  raw_env: []
  initgroups: False
  capture_output: False
  reload: False
  limit_request_field_size: 8190
  nworkers_changed: <function nworkers_changed at 0x2b3d0c8>
  timeout: 30
  keyfile: None
  ca_certs: None
  tmp_upload_dir: None
  backlog: 2048
  logger_class: gunicorn.glogging.Logger
[2017-09-29 15:31:17 +0000] [18568] [INFO] Starting gunicorn 19.7.1
[2017-09-29 15:31:17 +0000] [18568] [DEBUG] Arbiter booted
[2017-09-29 15:31:17 +0000] [18568] [INFO] Listening at: http://127.0.0.1:8080 (18568)
[2017-09-29 15:31:17 +0000] [18568] [INFO] Using worker: gevent
[2017-09-29 15:31:17 +0000] [18573] [INFO] Booting worker with pid: 18573
[2017-09-29 15:31:17 +0000] [18574] [INFO] Booting worker with pid: 18574
[2017-09-29 15:31:17 +0000] [18568] [DEBUG] 2 workers
[2017-09-29 15:31:21 +0000] [18573] [ERROR] Exception in worker process
Traceback (most recent call last):
  File "/var/www/projects/myblog/venv/lib/python2.7/site-packages/gunicorn/arbiter.py", line 578, in spawn_worker
    worker.init_process()
  File "/var/www/projects/myblog/venv/lib/python2.7/site-packages/gunicorn/workers/ggevent.py", line 190, in init_process
    super(GeventWorker, self).init_process()
  File "/var/www/projects/myblog/venv/lib/python2.7/site-packages/gunicorn/workers/base.py", line 126, in init_process
    self.load_wsgi()
  File "/var/www/projects/myblog/venv/lib/python2.7/site-packages/gunicorn/workers/base.py", line 135, in load_wsgi
    self.wsgi = self.app.wsgi()
  File "/var/www/projects/myblog/venv/lib/python2.7/site-packages/gunicorn/app/base.py", line 67, in wsgi
    self.callable = self.load()
  File "/var/www/projects/myblog/venv/lib/python2.7/site-packages/gunicorn/app/wsgiapp.py", line 65, in load
    return self.load_wsgiapp()
  File "/var/www/projects/myblog/venv/lib/python2.7/site-packages/gunicorn/app/wsgiapp.py", line 52, in load_wsgiapp
    return util.import_app(self.app_uri)
  File "/var/www/projects/myblog/venv/lib/python2.7/site-packages/gunicorn/util.py", line 352, in import_app
    __import__(module)
  File "/var/www/projects/myblog/venv/lib/python2.7/site-packages/gevent/builtins.py", line 93, in __import__
    result = _import(*args, **kwargs)
  File "/var/www/projects/myblog/manage.py", line 15, in <module>
    app = create_app(os.getenv('BLOG_CONFIG') or 'default')
  File "/var/www/projects/myblog/app/__init__.py", line 26, in create_app
    config[config_name].init_app(app)
  File "/var/www/projects/myblog/config.py", line 60, in init_app
    if gettattr(cls, 'MAIL_USE_TLS', None):
NameError: global name 'gettattr' is not defined
[2017-09-29 15:31:21 +0000] [18573] [INFO] Worker exiting (pid: 18573)
[2017-09-29 15:31:21 +0000] [18574] [ERROR] Exception in worker process
Traceback (most recent call last):
  File "/var/www/projects/myblog/venv/lib/python2.7/site-packages/gunicorn/arbiter.py", line 578, in spawn_worker
    worker.init_process()
  File "/var/www/projects/myblog/venv/lib/python2.7/site-packages/gunicorn/workers/ggevent.py", line 190, in init_process
    super(GeventWorker, self).init_process()
  File "/var/www/projects/myblog/venv/lib/python2.7/site-packages/gunicorn/workers/base.py", line 126, in init_process
    self.load_wsgi()
  File "/var/www/projects/myblog/venv/lib/python2.7/site-packages/gunicorn/workers/base.py", line 135, in load_wsgi
    self.wsgi = self.app.wsgi()
  File "/var/www/projects/myblog/venv/lib/python2.7/site-packages/gunicorn/app/base.py", line 67, in wsgi
    self.callable = self.load()
  File "/var/www/projects/myblog/venv/lib/python2.7/site-packages/gunicorn/app/wsgiapp.py", line 65, in load
    return self.load_wsgiapp()
  File "/var/www/projects/myblog/venv/lib/python2.7/site-packages/gunicorn/app/wsgiapp.py", line 52, in load_wsgiapp
    return util.import_app(self.app_uri)
  File "/var/www/projects/myblog/venv/lib/python2.7/site-packages/gunicorn/util.py", line 352, in import_app
    __import__(module)
  File "/var/www/projects/myblog/venv/lib/python2.7/site-packages/gevent/builtins.py", line 93, in __import__
    result = _import(*args, **kwargs)
  File "/var/www/projects/myblog/manage.py", line 15, in <module>
    app = create_app(os.getenv('BLOG_CONFIG') or 'default')
  File "/var/www/projects/myblog/app/__init__.py", line 26, in create_app
    config[config_name].init_app(app)
  File "/var/www/projects/myblog/config.py", line 60, in init_app
    if gettattr(cls, 'MAIL_USE_TLS', None):
NameError: global name 'gettattr' is not defined
[2017-09-29 15:31:21 +0000] [18574] [INFO] Worker exiting (pid: 18574)
[2017-09-29 15:31:21 +0000] [18568] [INFO] Shutting down: Master
[2017-09-29 15:31:21 +0000] [18568] [INFO] Reason: Worker failed to boot.
[2018-01-19 09:43:12 +0000] [28709] [DEBUG] Current configuration:
  proxy_protocol: False
  worker_connections: 1000
  statsd_host: None
  max_requests_jitter: 0
  post_fork: <function post_fork at 0x2a4d410>
  errorlog: -
  enable_stdio_inheritance: False
  worker_class: gevent
  ssl_version: 2
  suppress_ragged_eofs: True
  syslog: False
  syslog_facility: user
  when_ready: <function when_ready at 0x2a4d140>
  pre_fork: <function pre_fork at 0x2a4d2a8>
  cert_reqs: 0
  preload_app: False
  keepalive: 2
  accesslog: None
  group: 0
  graceful_timeout: 30
  do_handshake_on_connect: False
  spew: False
  workers: 2
  proc_name: gunicorn.pid
  sendfile: None
  pidfile: /var/log/gunicorn/debug.log
  umask: 0
  on_reload: <function on_reload at 0x2a19f50>
  pre_exec: <function pre_exec at 0x2a4d9b0>
  worker_tmp_dir: None
  limit_request_fields: 100
  pythonpath: None
  on_exit: <function on_exit at 0x2a4f230>
  config: /var/www/projects/myblog/deploy_config.py
  logconfig: None
  check_config: False
  statsd_prefix: 
  secure_scheme_headers: {'X-FORWARDED-PROTOCOL': 'ssl', 'X-FORWARDED-PROTO': 'https', 'X-FORWARDED-SSL': 'on'}
  reload_engine: auto
  proxy_allow_ips: ['127.0.0.1']
  pre_request: <function pre_request at 0x2a4db18>
  post_request: <function post_request at 0x2a4dc08>
  forwarded_allow_ips: ['127.0.0.1']
  worker_int: <function worker_int at 0x2a4d6e0>
  raw_paste_global_conf: []
  threads: 1
  max_requests: 0
  chdir: /var/www/projects/myblog
  daemon: False
  user: 0
  limit_request_line: 4094
  access_log_format: %(h)s %(l)s %(u)s %(t)s "%(r)s" %(s)s %(b)s "%(f)s" "%(a)s"
  certfile: None
  on_starting: <function on_starting at 0x2a19de8>
  post_worker_init: <function post_worker_init at 0x2a4d578>
  child_exit: <function child_exit at 0x2a4dd70>
  worker_exit: <function worker_exit at 0x2a4ded8>
  paste: None
  default_proc_name: manage:app
  syslog_addr: udp://localhost:514
  syslog_prefix: None
  ciphers: TLSv1
  worker_abort: <function worker_abort at 0x2a4d848>
  loglevel: debug
  bind: ['127.0.0.1:8080']
  raw_env: []
  initgroups: False
  capture_output: False
  reload: False
  limit_request_field_size: 8190
  nworkers_changed: <function nworkers_changed at 0x2a4f0c8>
  timeout: 30
  keyfile: None
  ca_certs: None
  tmp_upload_dir: None
  backlog: 2048
  logger_class: gunicorn.glogging.Logger
[2018-01-19 09:43:12 +0000] [28709] [INFO] Starting gunicorn 19.7.1

Error: Already running on PID 18613 (or pid file '/var/log/gunicorn/debug.log' is stale)

[2018-01-19 09:43:14 +0000] [28825] [DEBUG] Current configuration:
  proxy_protocol: False
  worker_connections: 1000
  statsd_host: None
  max_requests_jitter: 0
  post_fork: <function post_fork at 0x2a74410>
  errorlog: -
  enable_stdio_inheritance: False
  worker_class: gevent
  ssl_version: 2
  suppress_ragged_eofs: True
  syslog: False
  syslog_facility: user
  when_ready: <function when_ready at 0x2a74140>
  pre_fork: <function pre_fork at 0x2a742a8>
  cert_reqs: 0
  preload_app: False
  keepalive: 2
  accesslog: None
  group: 0
  graceful_timeout: 30
  do_handshake_on_connect: False
  spew: False
  workers: 2
  proc_name: gunicorn.pid
  sendfile: None
  pidfile: /var/log/gunicorn/debug.log
  umask: 0
  on_reload: <function on_reload at 0x2a41f50>
  pre_exec: <function pre_exec at 0x2a749b0>
  worker_tmp_dir: None
  limit_request_fields: 100
  pythonpath: None
  on_exit: <function on_exit at 0x2a76230>
  config: /var/www/projects/myblog/deploy_config.py
  logconfig: None
  check_config: False
  statsd_prefix: 
  secure_scheme_headers: {'X-FORWARDED-PROTOCOL': 'ssl', 'X-FORWARDED-PROTO': 'https', 'X-FORWARDED-SSL': 'on'}
  reload_engine: auto
  proxy_allow_ips: ['127.0.0.1']
  pre_request: <function pre_request at 0x2a74b18>
  post_request: <function post_request at 0x2a74c08>
  forwarded_allow_ips: ['127.0.0.1']
  worker_int: <function worker_int at 0x2a746e0>
  raw_paste_global_conf: []
  threads: 1
  max_requests: 0
  chdir: /var/www/projects/myblog
  daemon: False
  user: 0
  limit_request_line: 4094
  access_log_format: %(h)s %(l)s %(u)s %(t)s "%(r)s" %(s)s %(b)s "%(f)s" "%(a)s"
  certfile: None
  on_starting: <function on_starting at 0x2a41de8>
  post_worker_init: <function post_worker_init at 0x2a74578>
  child_exit: <function child_exit at 0x2a74d70>
  worker_exit: <function worker_exit at 0x2a74ed8>
  paste: None
  default_proc_name: manage:app
  syslog_addr: udp://localhost:514
  syslog_prefix: None
  ciphers: TLSv1
  worker_abort: <function worker_abort at 0x2a74848>
  loglevel: debug
  bind: ['127.0.0.1:8080']
  raw_env: []
  initgroups: False
  capture_output: False
  reload: False
  limit_request_field_size: 8190
  nworkers_changed: <function nworkers_changed at 0x2a760c8>
  timeout: 30
  keyfile: None
  ca_certs: None
  tmp_upload_dir: None
  backlog: 2048
  logger_class: gunicorn.glogging.Logger
[2018-01-19 09:43:14 +0000] [28825] [INFO] Starting gunicorn 19.7.1

Error: Already running on PID 18613 (or pid file '/var/log/gunicorn/debug.log' is stale)

[2018-01-19 09:43:16 +0000] [28830] [DEBUG] Current configuration:
  proxy_protocol: False
  worker_connections: 1000
  statsd_host: None
  max_requests_jitter: 0
  post_fork: <function post_fork at 0x1ff8410>
  errorlog: -
  enable_stdio_inheritance: False
  worker_class: gevent
  ssl_version: 2
  suppress_ragged_eofs: True
  syslog: False
  syslog_facility: user
  when_ready: <function when_ready at 0x1ff8140>
  pre_fork: <function pre_fork at 0x1ff82a8>
  cert_reqs: 0
  preload_app: False
  keepalive: 2
  accesslog: None
  group: 0
  graceful_timeout: 30
  do_handshake_on_connect: False
  spew: False
  workers: 2
  proc_name: gunicorn.pid
  sendfile: None
  pidfile: /var/log/gunicorn/debug.log
  umask: 0
  on_reload: <function on_reload at 0x1fc5f50>
  pre_exec: <function pre_exec at 0x1ff89b0>
  worker_tmp_dir: None
  limit_request_fields: 100
  pythonpath: None
  on_exit: <function on_exit at 0x1ffa230>
  config: /var/www/projects/myblog/deploy_config.py
  logconfig: None
  check_config: False
  statsd_prefix: 
  secure_scheme_headers: {'X-FORWARDED-PROTOCOL': 'ssl', 'X-FORWARDED-PROTO': 'https', 'X-FORWARDED-SSL': 'on'}
  reload_engine: auto
  proxy_allow_ips: ['127.0.0.1']
  pre_request: <function pre_request at 0x1ff8b18>
  post_request: <function post_request at 0x1ff8c08>
  forwarded_allow_ips: ['127.0.0.1']
  worker_int: <function worker_int at 0x1ff86e0>
  raw_paste_global_conf: []
  threads: 1
  max_requests: 0
  chdir: /var/www/projects/myblog
  daemon: False
  user: 0
  limit_request_line: 4094
  access_log_format: %(h)s %(l)s %(u)s %(t)s "%(r)s" %(s)s %(b)s "%(f)s" "%(a)s"
  certfile: None
  on_starting: <function on_starting at 0x1fc5de8>
  post_worker_init: <function post_worker_init at 0x1ff8578>
  child_exit: <function child_exit at 0x1ff8d70>
  worker_exit: <function worker_exit at 0x1ff8ed8>
  paste: None
  default_proc_name: manage:app
  syslog_addr: udp://localhost:514
  syslog_prefix: None
  ciphers: TLSv1
  worker_abort: <function worker_abort at 0x1ff8848>
  loglevel: debug
  bind: ['127.0.0.1:8080']
  raw_env: []
  initgroups: False
  capture_output: False
  reload: False
  limit_request_field_size: 8190
  nworkers_changed: <function nworkers_changed at 0x1ffa0c8>
  timeout: 30
  keyfile: None
  ca_certs: None
  tmp_upload_dir: None
  backlog: 2048
  logger_class: gunicorn.glogging.Logger
[2018-01-19 09:43:16 +0000] [28830] [INFO] Starting gunicorn 19.7.1

Error: Already running on PID 18613 (or pid file '/var/log/gunicorn/debug.log' is stale)

[2018-01-19 09:43:20 +0000] [28835] [DEBUG] Current configuration:
  proxy_protocol: False
  worker_connections: 1000
  statsd_host: None
  max_requests_jitter: 0
  post_fork: <function post_fork at 0x2335410>
  errorlog: -
  enable_stdio_inheritance: False
  worker_class: gevent
  ssl_version: 2
  suppress_ragged_eofs: True
  syslog: False
  syslog_facility: user
  when_ready: <function when_ready at 0x2335140>
  pre_fork: <function pre_fork at 0x23352a8>
  cert_reqs: 0
  preload_app: False
  keepalive: 2
  accesslog: None
  group: 0
  graceful_timeout: 30
  do_handshake_on_connect: False
  spew: False
  workers: 2
  proc_name: gunicorn.pid
  sendfile: None
  pidfile: /var/log/gunicorn/debug.log
  umask: 0
  on_reload: <function on_reload at 0x2302f50>
  pre_exec: <function pre_exec at 0x23359b0>
  worker_tmp_dir: None
  limit_request_fields: 100
  pythonpath: None
  on_exit: <function on_exit at 0x2337230>
  config: /var/www/projects/myblog/deploy_config.py
  logconfig: None
  check_config: False
  statsd_prefix: 
  secure_scheme_headers: {'X-FORWARDED-PROTOCOL': 'ssl', 'X-FORWARDED-PROTO': 'https', 'X-FORWARDED-SSL': 'on'}
  reload_engine: auto
  proxy_allow_ips: ['127.0.0.1']
  pre_request: <function pre_request at 0x2335b18>
  post_request: <function post_request at 0x2335c08>
  forwarded_allow_ips: ['127.0.0.1']
  worker_int: <function worker_int at 0x23356e0>
  raw_paste_global_conf: []
  threads: 1
  max_requests: 0
  chdir: /var/www/projects/myblog
  daemon: False
  user: 0
  limit_request_line: 4094
  access_log_format: %(h)s %(l)s %(u)s %(t)s "%(r)s" %(s)s %(b)s "%(f)s" "%(a)s"
  certfile: None
  on_starting: <function on_starting at 0x2302de8>
  post_worker_init: <function post_worker_init at 0x2335578>
  child_exit: <function child_exit at 0x2335d70>
  worker_exit: <function worker_exit at 0x2335ed8>
  paste: None
  default_proc_name: manage:app
  syslog_addr: udp://localhost:514
  syslog_prefix: None
  ciphers: TLSv1
  worker_abort: <function worker_abort at 0x2335848>
  loglevel: debug
  bind: ['127.0.0.1:8080']
  raw_env: []
  initgroups: False
  capture_output: False
  reload: False
  limit_request_field_size: 8190
  nworkers_changed: <function nworkers_changed at 0x23370c8>
  timeout: 30
  keyfile: None
  ca_certs: None
  tmp_upload_dir: None
  backlog: 2048
  logger_class: gunicorn.glogging.Logger
[2018-01-19 09:43:20 +0000] [28835] [INFO] Starting gunicorn 19.7.1

Error: Already running on PID 18613 (or pid file '/var/log/gunicorn/debug.log' is stale)

